Workbook

Sheet 75
A1: name1 | B1: name2 | C1: id1 | D1: id2 | E1: similarity_score | F1: Ok/no
A2: ahmed alâ€rawi | B2: ahmed al-rawi | C2: A5050245548 | D2: A5093769593 | E2: 92 | F2: ok | H2: % ok | I2: {=COUNTIF(F2:F509,"ok")/SUM(IF(ISBLANK(F2:F509),0,1))} -> 0.37401575 | J2: =COUNTIF(F2:F509,"ok") -> 190
A3: gail s anderson | B3: a m anderson | C3: A5046194198 | D3: A5043746917 | E3: 81 | F3: no | H3: % no | I3: {=COUNTIF(F2:F509,"no")/SUM(IF(ISBLANK(F2:F509),0,1))} -> 0.62598425 | J3: =COUNTIF(F2:F509,"no") -> 318
A4: gail s anderson | B4: aspen anderson | C4: A5046194198 | D4: A5019882570 | E4: 76 | F4: no
A5: d g armstrong | B5: kyle m armstrong | C5: A5109229854 | D5: A5071425274 | E5: 76 | F5: no
A6: vinÃ­cius c azevedo | B6: vinicius c azevedo | C6: A5112368463 | D6: A5103260690 | E6: 94 | F6: ok
A7: scott c anderson | B7: sean c anderson | C7: A5081601519 | D7: A5081686405 | E7: 77 | F7: no
A8: niloufar aran | B8: niloufar abhari | C8: A5086077761 | D8: A5034158753 | E8: 79 | F8: no
A9: a m anderson | B9: sean c anderson | C9: A5043746917 | D9: A5081686405 | E9: 81 | F9: no
A10: a m anderson | B10: aspen anderson | C10: A5043746917 | D10: A5019882570 | E10: 77 | F10: no
A11: joshua d alampi | B11: josh alampi | C11: A5005530879 | D11: A5064096264 | E11: 85 | F11: ok
A12: sean c anderson | B12: aspen anderson | C12: A5081686405 | D12: A5019882570 | E12: 83 | F12: no
A13: niloufar abhari | B13: neilofar amiri | C13: A5034158753 | D13: A5088404611 | E13: 76 | F13: no
A14: amirhossein alimohammadi | B14: amirhossein alizadehkhaledi | C14: A5035619284 | D14: A5019710534 | E14: 75 | F14: ok
A15: nadra ansari | B15: neda anvari | C15: A5058829130 | D15: A5085378218 | E15: 78 | F15: no
... A509: n zhang | B509: peng zhang | C509: A5061007955 | D509: A5100364110 | E509: 82 | F509: no

Sheet 78
A1: name1 | B1: name2 | C1: id1 | D1: id2 | E1: similarity_score | F1: ok/no
A2: ahmed alâ€rawi | B2: ahmed al-rawi | C2: A5050245548 | D2: A5093769593 | E2: 92 | F2: =IF(_xlfn.XLOOKUP(C2,'75'!$C$2:$C$509,'75'!$D$2:$D$509)=D2,'75'!F2) -> ok | H2: %ok | I2: =COUNTIF(F2:F339,"ok")/338 -> 0.40532544 | J2: =COUNTIF(F2:F339, "ok") -> 137
A3: gail s anderson | B3: a m anderson | C3: A5046194198 | D3: A5043746917 | E3: 81 | F3: =IF(_xlfn.XLOOKUP(C3,'75'!$C$2:$C$509,'75'!$D$2:$D$509)=D3,'75'!F3) -> no | H3: %no | I3: =COUNTIF(F2:F339, "no")/338 -> 0.59467456 | J3: =COUNTIF(F2:F339,"no") -> 201
A4: vinÃ­cius c azevedo | B4: vinicius c azevedo | C4: A5112368463 | D4: A5103260690 | E4: 94 | F4: =IF(_xlfn.XLOOKUP(C4,'75'!$C$2:$C$509,'75'!$D$2:$D$509)=D4,'75'!F4) -> no
A5: niloufar aran | B5: niloufar abhari | C5: A5086077761 | D5: A5034158753 | E5: 79 | F5: =IF(_xlfn.XLOOKUP(C5,'75'!$C$2:$C$509,'75'!$D$2:$D$509)=D5,'75'!F5) -> no
A6: a m anderson | B6: sean c anderson | C6: A5043746917 | D6: A5081686405 | E6: 81 | F6: =IF(_xlfn.XLOOKUP(C6,'75'!$C$2:$C$509,'75'!$D$2:$D$509)=D6,'75'!F6) -> ok
A7: joshua d alampi | B7: josh alampi | C7: A5005530879 | D7: A5064096264 | E7: 85 | F7: =IF(_xlfn.XLOOKUP(C7,'75'!$C$2:$C$509,'75'!$D$2:$D$509)=D7,'75'!F7) -> no
A8: sean c anderson | B8: aspen anderson | C8: A5081686405 | D8: A5019882570 | E8: 83 | F8: =IF(_xlfn.XLOOKUP(C8,'75'!$C$2:$C$509,'75'!$D$2:$D$509)=D8,'75'!F8) -> no
A9: nadra ansari | B9: neda anvari | C9: A5058829130 | D9: A5085378218 | E9: 78 | F9: =IF(_xlfn.XLOOKUP(C9,'75'!$C$2:$C$509,'75'!$D$2:$D$509)=D9,'75'!F9) -> no
A10: ivan v bajiÄ‡ | B10: lvan v bajic | C10: A5012187461 | D10: A5093208285 | E10: 83 | F10: =IF(_xlfn.XLOOKUP(C10,'75'!$C$2:$C$509,'75'!$D$2:$D$509)=D10,'75'!F10) -> no
A11: mark a brockman | B11: ma brockman | C11: A5021397351 | D11: A5062945775 | E11: 85 | F11: =IF(_xlfn.XLOOKUP(C11,'75'!$C$2:$C$509,'75'!$D$2:$D$509)=D11,'75'!F11) -> ok
A12: nicholas blomley | B12: nicholas brunelle | C12: A5028312431 | D12: A5008301049 | E12: 79 | F12: =IF(_xlfn.XLOOKUP(C12,'75'!$C$2:$C$509,'75'!$D$2:$D$509)=D12,'75'!F12) -> no
A13: behraad bahreyni | B13: behdad bahrani | C13: A5014284015 | D13: A5115910521 | E13: 80 | F13: =IF(_xlfn.XLOOKUP(C13,'75'!$C$2:$C$509,'75'!$D$2:$D$509)=D13,'75'!F13) -> no
A14: andrew p blaber | B14: andrew phillip blaber | C14: A5111618673 | D14: A5113110122 | E14: 83 | F14: =IF(_xlfn.XLOOKUP(C14,'75'!$C$2:$C$509,'75'!$D$2:$D$509)=D14,'75'!F14) -> ok
A15: matthew brown | B15: matthew berkowitz | C15: A5041724055 | D15: A5060702246 | E15: 80 | F15: =IF(_xlfn.XLOOKUP(C15,'75'!$C$2:$C$509,'75'!$D$2:$D$509)=D15,'75'!F15) -> no
A16: christopher beh | B16: christopher buse | C16: A5012256170 | D16: A5118970217 | E16: 90 | F16: no
A17: tom c brown | B17: tom brown | C17: A5112796676 | D17: A5078745916 | E17: 90 | F17: =IF(_xlfn.XLOOKUP(C17,'75'!$C$2:$C$509,'75'!$D$2:$D$509)=D17,'75'!F17) -> ok
A18: andreÇ a bulatov | B18: andreÄ­ a bulatov | C18: A5103266587 | D18: A5108247017 | E18: 94 | F18: =IF(_xlfn.XLOOKUP(C18,'75'!$C$2:$C$509,'75'!$D$2:$D$509)=D18,'75'!F18) -> no
A19: douglas c braun | B19: doug r braun | C19: A5113442963 | D19: A5103066580 | E19: 81 | F19: =IF(_xlfn.XLOOKUP(C19,'75'!$C$2:$C$509,'75'!$D$2:$D$509)=D19,'75'!F19) -> ok
A20: megan barker | B20: megan k barker | C20: A5056468452 | D20: A5054202306 | E20: 92 | F20: =IF(_xlfn.XLOOKUP(C20,'75'!$C$2:$C$509,'75'!$D$2:$D$509)=D20,'75'!F20) -> no
A21: tim u h baumeister | B21: tim baumeister | C21: A5019595229 | D21: A5058323325 | E21: 88 | F21: =IF(_xlfn.XLOOKUP(C21,'75'!$C$2:$C$509,'75'!$D$2:$D$509)=D21,'75'!F21) -> no
A22: andreea bratu | B22: andreea barbu | C22: A5064542404 | D22: A5098667658 | E22: 85 | F22: =IF(_xlfn.XLOOKUP(C22,'75'!$C$2:$C$509,'75'!$D$2:$D$509)=D22,'75'!F22) -> no
A23: jil a busmann | B23: jil busmann | C23: A5072224327 | D23: A5074527350 | E23: 92 | F23: =IF(_xlfn.XLOOKUP(C23,'75'!$C$2:$C$509,'75'!$D$2:$D$509)=D23,'75'!F23) -> ok
A24: florian baer | B24: florian r bÃ¤r | C24: A5066677866 | D24: A5092691914 | E24: 80 | F24: =IF(_xlfn.XLOOKUP(C24,'75'!$C$2:$C$509,'75'!$D$2:$D$509)=D24,'75'!F24) -> no
A25: monica bhattacharjee | B25: paloma bhattacharjee | C25: A5044573188 | D25: A5010444190 | E25: 80 | F25: =IF(_xlfn.XLOOKUP(C25,'75'!$C$2:$C$509,'75'!$D$2:$D$509)=D25,'75'!F25) -> no
A26: scott e bernstein | B26: scott bernstein | C26: A5057881599 | D26: A5002125273 | E26: 94 | F26: =IF(_xlfn.XLOOKUP(C26,'75'!$C$2:$C$509,'75'!$D$2:$D$509)=D26,'75'!F26) -> no
A27: alishba bibal | B27: alishba bilal | C27: A5115512232 | D27: A5112957369 | E27: 92 | F27: =IF(_xlfn.XLOOKUP(C27,'75'!$C$2:$C$509,'75'!$D$2:$D$509)=D27,'75'!F27) -> ok
A28: ignacio calderon de la barca | B28: igacio calderon de la barca | C28: A5017248675 | D28: A5050733708 | E28: 98 | F28: =IF(_xlfn.XLOOKUP(C28,'75'!$C$2:$C$509,'75'!$D$2:$D$509)=D28,'75'!F28) -> ok
... A34: caroline colijn | B34: caroline coljin | C34: A5091754800 | D34: A5019122524 | E34: 93 | F34: =IF(_xlfn.XLOOKUP(C34,'75'!$C$2:$C$509,'75'!$D$2:$D$509)=D34,'75'!F34) -> no
A35: caroline colijn | B35: caroline colijin | C35: A5091754800 | D35: A5092252314 | E35: 97 | F35: ok
A36: sarah l canham | B36: rachel canham | C36: A5056237664 | D36: A5034142600 | E36: 81 | F36: =IF(_xlfn.XLOOKUP(C36,'75'!$C$2:$C$509,'75'!$D$2:$D$509)=D36,'75'!F36) -> ok
A37: jing chen | B37: gang chen | C37: A5100394876 | D37: A5100389308 | E37: 78 | F37: =IF(_xlfn.XLOOKUP(C37,'75'!$C$2:$C$509,'75'!$D$2:$D$509)=D37,'75'!F37) -> no
A38: jing chen | B38: j chen | C38: A5100394876 | D38: A5107886267 | E38: 80 | F38: ok
A39: jing chen | B39: long chen | C39: A5100394876 | D39: A5100336421 | E39: 78 | F39: ok
A40: jing chen | B40: imin chen | C40: A5100394876 | D40: A5024124555 | E40: 78 | F40: no
A41: yuxi chen | B41: xi chen | C41: A5100764265 | D41: A5100690182 | E41: 88 | F41: no
A42: brian e conway | B42: brian conway | C42: A5109163734 | D42: A5101537673 | E42: 92 | F42: =IF(_xlfn.XLOOKUP(C42,'75'!$C$2:$C$509,'75'!$D$2:$D$509)=D42,'75'!F42) -> no
A43: david c clarke | B43: dave clarke | C43: A5062270975 | D43: A5075735110 | E43: 80 | F43: =IF(_xlfn.XLOOKUP(C43,'75'!$C$2:$C$509,'75'!$D$2:$D$509)=D43,'75'!F43) -> ok
A44: david c clarke | B44: dave c clarke | C44: A5062270975 | D44: A5112840346 | E44: 89 | F44: ok
A45: deborah a connolly | B45: deb connolly | C45: A5014109821 | D45: A5066779521 | E45: 80 | F45: =IF(_xlfn.XLOOKUP(C45,'75'!$C$2:$C$509,'75'!$D$2:$D$509)=D45,'75'!F45) -> no
...

Sheet 80
A1: name1 | B1: name2 | C1: id1 | D1: id2 | E1: similarity_score | F1: ok/no
A2: ahmed alâ€rawi | B2: ahmed al-rawi | C2: A5050245548 | D2: A5093769593 | E2: 92 | F2: =IF(_xlfn.XLOOKUP(C2,'75'!$C$2:$C$509,'75'!$D$2:$D$509)=D2,'75'!F2) -> ok | H2: %ok | I2: =COUNTIF(F2:F292,"ok")/291 -> 0.38487973 | J2: =COUNTIF(F2:F292,"ok") -> 112
A3: gail s anderson | B3: a m anderson | C3: A5046194198 | D3: A5043746917 | E3: 81 | F3: =IF(_xlfn.XLOOKUP(C3,'75'!$C$2:$C$509,'75'!$D$2:$D$509)=D3,'75'!F3) -> no | H3: %no | I3: =COUNTIF(F2:F292,"no")/291 -> 0.61512027 | J3: =COUNTIF(F2:F292,"no") -> 179
A4: vinÃ­cius c azevedo | B4: vinicius c azevedo | C4: A5112368463 | D4: A5103260690 | E4: 94 | F4: =IF(_xlfn.XLOOKUP(C4,'75'!$C$2:$C$509,'75'!$D$2:$D$509)=D4,'75'!F4) -> no
A5: a m anderson | B5: sean c anderson | C5: A5043746917 | D5: A5081686405 | E5: 81 | F5: =IF(_xlfn.XLOOKUP(C5,'75'!$C$2:$C$509,'75'!$D$2:$D$509)=D5,'75'!F5) -> no
A6: joshua d alampi | B6: josh alampi | C6: A5005530879 | D6: A5064096264 | E6: 85 | F6: =IF(_xlfn.XLOOKUP(C6,'75'!$C$2:$C$509,'75'!$D$2:$D$509)=D6,'75'!F6) -> ok
A7: sean c anderson | B7: aspen anderson | C7: A5081686405 | D7: A5019882570 | E7: 83 | F7: =IF(_xlfn.XLOOKUP(C7,'75'!$C$2:$C$509,'75'!$D$2:$D$509)=D7,'75'!F7) -> no
A8: ivan v bajiÄ‡ | B8: lvan v bajic | C8: A5012187461 | D8: A5093208285 | E8: 83 | F8: =IF(_xlfn.XLOOKUP(C8,'75'!$C$2:$C$509,'75'!$D$2:$D$509)=D8,'75'!F8) -> no
A9: mark a brockman | B9: ma brockman | C9: A5021397351 | D9: A5062945775 | E9: 85 | F9: =IF(_xlfn.XLOOKUP(C9,'75'!$C$2:$C$509,'75'!$D$2:$D$509)=D9,'75'!F9) -> no
A10: behraad bahreyni | B10: behdad bahrani | C10: A5014284015 | D10: A5115910521 | E10: 80 | F10: =IF(_xlfn.XLOOKUP(C10,'75'!$C$2:$C$509,'75'!$D$2:$D$509)=D10,'75'!F10) -> no
A11: andrew p blaber | B11: andrew phillip blaber | C11: A5111618673 | D11: A5113110122 | E11: 83 | F11: =IF(_xlfn.XLOOKUP(C11,'75'!$C$2:$C$509,'75'!$D$2:$D$509)=D11,'75'!F11) -> ok
A12: matthew brown | B12: matthew berkowitz | C12: A5041724055 | D12: A5060702246 | E12: 80 | F12: =IF(_xlfn.XLOOKUP(C12,'75'!$C$2:$C$509,'75'!$D$2:$D$509)=D12,'75'!F12) -> no
A13: christopher beh | B13: christopher buse | C13: A5012256170 | D13: A5118970217 | E13: 90 | F13: no
A14: tom c brown | B14: tom brown | C14: A5112796676 | D14: A5078745916 | E14: 90 | F14: =IF(_xlfn.XLOOKUP(C14,'75'!$C$2:$C$509,'75'!$D$2:$D$509)=D14,'75'!F14) -> ok
A15: andreÇ a bulatov | B15: andreÄ­ a bulatov | C15: A5103266587 | D15: A5108247017 | E15: 94 | F15: =IF(_xlfn.XLOOKUP(C15,'75'!$C$2:$C$509,'75'!$D$2:$D$509)=D15,'75'!F15) -> no
A16: douglas c braun | B16: doug r braun | C16: A5113442963 | D16: A5103066580 | E16: 81 | F16: =IF(_xlfn.XLOOKUP(C16,'75'!$C$2:$C$509,'75'!$D$2:$D$509)=D16,'75'!F16) -> no
A17: megan barker | B17: megan k barker | C17: A5056468452 | D17: A5054202306 | E17: 92 | F17: =IF(_xlfn.XLOOKUP(C17,'75'!$C$2:$C$509,'75'!$D$2:$D$509)=D17,'75'!F17) -> ok
A18: tim u h baumeister | B18: tim baumeister | C18: A5019595229 | D18: A5058323325 | E18: 88 | F18: =IF(_xlfn.XLOOKUP(C18,'75'!$C$2:$C$509,'75'!$D$2:$D$509)=D18,'75'!F18) -> no
A19: andreea bratu | B19: andreea barbu | C19: A5064542404 | D19: A5098667658 | E19: 85 | F19: =IF(_xlfn.XLOOKUP(C19,'75'!$C$2:$C$509,'75'!$D$2:$D$509)=D19,'75'!F19) -> ok
A20: jil a busmann | B20: jil busmann | C20: A5072224327 | D20: A5074527350 | E20: 92 | F20: =IF(_xlfn.XLOOKUP(C20,'75'!$C$2:$C$509,'75'!$D$2:$D$509)=D20,'75'!F20) -> no
A21: florian baer | B21: florian r bÃ¤r | C21: A5066677866 | D21: A5092691914 | E21: 80 | F21: =IF(_xlfn.XLOOKUP(C21,'75'!$C$2:$C$509,'75'!$D$2:$D$509)=D21,'75'!F21) -> no
A22: monica bhattacharjee | B22: paloma bhattacharjee | C22: A5044573188 | D22: A5010444190 | E22: 80 | F22: =IF(_xlfn.XLOOKUP(C22,'75'!$C$2:$C$509,'75'!$D$2:$D$509)=D22,'75'!F22) -> no
A23: scott e bernstein | B23: scott bernstein | C23: A5057881599 | D23: A5002125273 | E23: 94 | F23: =IF(_xlfn.XLOOKUP(C23,'75'!$C$2:$C$509,'75'!$D$2:$D$509)=D23,'75'!F23) -> ok
A24: alishba bibal | B24: alishba bilal | C24: A5115512232 | D24: A5112957369 | E24: 92 | F24: =IF(_xlfn.XLOOKUP(C24,'75'!$C$2:$C$509,'75'!$D$2:$D$509)=D24,'75'!F24) -> no
A25: ignacio calderon de la barca | B25: igacio calderon de la barca | C25: A5017248675 | D25: A5050733708 | E25: 98 | F25: =IF(_xlfn.XLOOKUP(C25,'75'!$C$2:$C$509,'75'!$D$2:$D$509)=D25,'75'!F25) -> no
... A30: caroline colijn | B30: caroline coljin | C30: A5091754800 | D30: A5019122524 | E30: 93 | F30: =IF(_xlfn.XLOOKUP(C30,'75'!$C$2:$C$509,'75'!$D$2:$D$509)=D30,'75'!F30) -> ok
A31: caroline colijn | B31: caroline colijin | C31: A5091754800 | D31: A5092252314 | E31: 97 | F31: ok
A32: sarah l canham | B32: rachel canham | C32: A5056237664 | D32: A5034142600 | E32: 81 | F32: =IF(_xlfn.XLOOKUP(C32,'75'!$C$2:$C$509,'75'!$D$2:$D$509)=D32,'75'!F32) -> no
A33: jing chen | B33: j chen | C33: A5100394876 | D33: A5107886267 | E33: 80 | F33: ok
A34: yuxi chen | B34: xi chen | C34: A5100764265 | D34: A5100690182 | E34: 88 | F34: no
A35: brian e conway | B35: brian conway | C35: A5109163734 | D35: A5101537673 | E35: 92 | F35: =IF(_xlfn.XLOOKUP(C35,'75'!$C$2:$C$509,'75'!$D$2:$D$509)=D35,'75'!F35) -> ok
A36: david c clarke | B36: dave clarke | C36: A5062270975 | D36: A5075735110 | E36: 80 | F36: =IF(_xlfn.XLOOKUP(C36,'75'!$C$2:$C$509,'75'!$D$2:$D$509)=D36,'75'!F36) -> ok
A37: david c clarke | B37: dave c clarke | C37: A5062270975 | D37: A5112840346 | E37: 89 | F37: ok
A38: deborah a connolly | B38: deb connolly | C38: A5014109821 | D38: A5066779521 | E38: 80 | F38: =IF(_xlfn.XLOOKUP(C38,'75'!$C$2:$C$509,'75'!$D$2:$D$509)=D38,'75'!F38) -> no
A39: teresa cheung | B39: tessa cheng | C39: A5077739432 | D39: A5051697024 | E39: 83 | F39: =IF(_xlfn.XLOOKUP(C39,'75'!$C$2:$C$509,'75'!$D$2:$D$509)=D39,'75'!F39) -> ok
A40: teresa cheung | B40: teresa p cheung | C40: A5077739432 | D40: A5079537793 | E40: 93 | F40: ok
A41: anita t cotÃ© | B41: anita cotÃ© | C41: A5072214202 | D41: A5066224186 | E41: 91 | F41: =IF(_xlfn.XLOOKUP(C41,'75'!$C$2:$C$509,'75'!$D$2:$D$509)=D41,'75'!F41) -> no
A42: rebecca j cobb | B42: rebecca d cox | C42: A5000846228 | D42: A5024026724 | E42: 81 | F42: =IF(_xlfn.XLOOKUP(C42,'75'!$C$2:$C$509,'75'!$D$2:$D$509)=D42,'75'!F42) -> no
A43: stephen choi | B43: stephen collis | C43: A5046677225 | D43: A5015481958 | E43: 85 | F43: =IF(_xlfn.XLOOKUP(C43,'75'!$C$2:$C$509,'75'!$D$2:$D$509)=D43,'75'!F43) -> ok
A44: daniel chang | B44: dave chang | C44: A5044668950 | D44: A5011390842 | E44: 82 | F44: =IF(_xlfn.XLOOKUP(C44,'75'!$C$2:$C$509,'75'!$D$2:$D$509)=D44,'75'!F44) -> ok
...

Sheet 82
A1: name1 | B1: name2 | C1: id1 | D1: id2 | E1: similarity_score | F1: ok/no
A2: ahmed alâ€rawi | B2: ahmed al-rawi | C2: A5050245548 | D2: A5093769593 | E2: 92 | F2: =IF(_xlfn.XLOOKUP(C2,'75'!$C$2:$C$509,'75'!$D$2:$D$509)=D2,'75'!F2) -> ok | H2: %ok | I2: =COUNTIF(F2:F221, "ok")/220 -> 0.40454545 | J2: =COUNTIF(F2:F221,"ok") -> 89
A3: vinÃ­cius c azevedo | B3: vinicius c azevedo | C3: A5112368463 | D3: A5103260690 | E3: 94 | F3: =IF(_xlfn.XLOOKUP(C3,'75'!$C$2:$C$509,'75'!$D$2:$D$509)=D3,'75'!F3) -> no | H3: %no | I3: =COUNTIF(F2:F221, "no")/220 -> 0.59545455 | J3: =COUNTIF(F2:F221, "no") -> 131
A4: joshua d alampi | B4: josh alampi | C4: A5005530879 | D4: A5064096264 | E4: 85 | F4: =IF(_xlfn.XLOOKUP(C4,'75'!$C$2:$C$509,'75'!$D$2:$D$509)=D4,'75'!F4) -> no
A5: sean c anderson | B5: aspen anderson | C5: A5081686405 | D5: A5019882570 | E5: 83 | F5: =IF(_xlfn.XLOOKUP(C5,'75'!$C$2:$C$509,'75'!$D$2:$D$509)=D5,'75'!F5) -> no
A6: ivan v bajiÄ‡ | B6: lvan v bajic | C6: A5012187461 | D6: A5093208285 | E6: 83 | F6: =IF(_xlfn.XLOOKUP(C6,'75'!$C$2:$C$509,'75'!$D$2:$D$509)=D6,'75'!F6) -> ok
A7: mark a brockman | B7: ma brockman | C7: A5021397351 | D7: A5062945775 | E7: 85 | F7: =IF(_xlfn.XLOOKUP(C7,'75'!$C$2:$C$509,'75'!$D$2:$D$509)=D7,'75'!F7) -> no
A8: andrew p blaber | B8: andrew phillip blaber | C8: A5111618673 | D8: A5113110122 | E8: 83 | F8: =IF(_xlfn.XLOOKUP(C8,'75'!$C$2:$C$509,'75'!$D$2:$D$509)=D8,'75'!F8) -> no
A9: christopher beh | B9: christopher buse | C9: A5012256170 | D9: A5118970217 | E9: 90 | F9: no
A10: tom c brown | B10: tom brown | C10: A5112796676 | D10: A5078745916 | E10: 90 | F10: =IF(_xlfn.XLOOKUP(C10,'75'!$C$2:$C$509,'75'!$D$2:$D$509)=D10,'75'!F10) -> no
A11: andreÇ a bulatov | B11: andreÄ­ a bulatov | C11: A5103266587 | D11: A5108247017 | E11: 94 | F11: =IF(_xlfn.XLOOKUP(C11,'75'!$C$2:$C$509,'75'!$D$2:$D$509)=D11,'75'!F11) -> ok
A12: megan barker | B12: megan k barker | C12: A5056468452 | D12: A5054202306 | E12: 92 | F12: =IF(_xlfn.XLOOKUP(C12,'75'!$C$2:$C$509,'75'!$D$2:$D$509)=D12,'75'!F12) -> no
A13: tim u h baumeister | B13: tim baumeister | C13: A5019595229 | D13: A5058323325 | E13: 88 | F13: =IF(_xlfn.XLOOKUP(C13,'75'!$C$2:$C$509,'75'!$D$2:$D$509)=D13,'75'!F13) -> no
A14: andreea bratu | B14: andreea barbu | C14: A5064542404 | D14: A5098667658 | E14: 85 | F14: =IF(_xlfn.XLOOKUP(C14,'75'!$C$2:$C$509,'75'!$D$2:$D$509)=D14,'75'!F14) -> ok
A15: jil a busmann | B15: jil busmann | C15: A5072224327 | D15: A5074527350 | E15: 92 | F15: =IF(_xlfn.XLOOKUP(C15,'75'!$C$2:$C$509,'75'!$D$2:$D$509)=D15,'75'!F15) -> no
A16: scott e bernstein | B16: scott bernstein | C16: A5057881599 | D16: A5002125273 | E16: 94 | F16: =IF(_xlfn.XLOOKUP(C16,'75'!$C$2:$C$509,'75'!$D$2:$D$509)=D16,'75'!F16) -> no
A17: alishba bibal | B17: alishba bilal | C17: A5115512232 | D17: A5112957369 | E17: 92 | F17: =IF(_xlfn.XLOOKUP(C17,'75'!$C$2:$C$509,'75'!$D$2:$D$509)=D17,'75'!F17) -> ok
A18: ignacio calderon de la barca | B18: igacio calderon de la barca | C18: A5017248675 | D18: A5050733708 | E18: 98 | F18: =IF(_xlfn.XLOOKUP(C18,'75'!$C$2:$C$509,'75'!$D$2:$D$509)=D18,'75'!F18) -> no
A19: z brumme | B19: zl brumme | C19: A5075252668 | D19: A5084001641 | E19: 94 | F19: =IF(_xlfn.XLOOKUP(C19,'75'!$C$2:$C$509,'75'!$D$2:$D$509)=D19,'75'!F19) -> ok
A20: mirzafaisal beg | B20: mirza faisal beg | C20: A5104015115 | D20: A5000972836 | E20: 97 | F20: =IF(_xlfn.XLOOKUP(C20,'75'!$C$2:$C$509,'75'!$D$2:$D$509)=D20,'75'!F20) -> no
A21: john j clague | B21: j j clague | C21: A5090873433 | D21: A5000296592 | E21: 87 | F21: =IF(_xlfn.XLOOKUP(C21,'75'!$C$2:$C$509,'75'!$D$2:$D$509)=D21,'75'!F21) -> no
... A23: caroline colijn | B23: caroline coljin | C23: A5091754800 | D23: A5019122524 | E23: 93 | F23: =IF(_xlfn.XLOOKUP(C23,'75'!$C$2:$C$509,'75'!$D$2:$D$509)=D23,'75'!F23) -> ok
A24: caroline colijn | B24: caroline colijin | C24: A5091754800 | D24: A5092252314 | E24: 97 | F24: ok
A25: yuxi chen | B25: xi chen | C25: A5100764265 | D25: A5100690182 | E25: 88 | F25: no
A26: brian e conway | B26: brian conway | C26: A5109163734 | D26: A5101537673 | E26: 92 | F26: =IF(_xlfn.XLOOKUP(C26,'75'!$C$2:$C$509,'75'!$D$2:$D$509)=D26,'75'!F26) -> no
A27: david c clarke | B27: dave c clarke | C27: A5062270975 | D27: A5112840346 | E27: 89 | F27: ok
A28: teresa cheung | B28: tessa cheng | C28: A5077739432 | D28: A5051697024 | E28: 83 | F28: =IF(_xlfn.XLOOKUP(C28,'75'!$C$2:$C$509,'75'!$D$2:$D$509)=D28,'75'!F28) -> ok
A29: teresa cheung | B29: teresa p cheung | C29: A5077739432 | D29: A5079537793 | E29: 93 | F29: ok
A30: anita t cotÃ© | B30: anita cotÃ© | C30: A5072214202 | D30: A5066224186 | E30: 91 | F30: =IF(_xlfn.XLOOKUP(C30,'75'!$C$2:$C$509,'75'!$D$2:$D$509)=D30,'75'!F30) -> ok
A31: stephen choi | B31: stephen collis | C31: A5046677225 | D31: A5015481958 | E31: 85 | F31: =IF(_xlfn.XLOOKUP(C31,'75'!$C$2:$C$509,'75'!$D$2:$D$509)=D31,'75'!F31) -> ok
A32: daniel chang | B32: dave chang | C32: A5044668950 | D32: A5011390842 | E32: 82 | F32: =IF(_xlfn.XLOOKUP(C32,'75'!$C$2:$C$509,'75'!$D$2:$D$509)=D32,'75'!F32) -> no
A33: daniel chang | B33: daniel chiang | C33: A5044668950 | D33: A5006979877 | E33: 96 | F33: no
A34: si chen | B34: xi chen | C34: A5100366176 | D34: A5100690182 | E34: 86 | F34: no
A35: kristin chong | B35: christine chuong | C35: A5104109440 | D35: A5083724661 | E35: 83 | F35: =IF(_xlfn.XLOOKUP(C35,'75'!$C$2:$C$509,'75'!$D$2:$D$509)=D35,'75'!F35) -> ok
A36: qimin chen | B36: imin chen | C36: A5069419461 | D36: A5024124555 | E36: 95 | F36: =IF(_xlfn.XLOOKUP(C36,'75'!$C$2:$C$509,'75'!$D$2:$D$509)=D36,'75'!F36) -> ok
A37: maude comtoisâ€cabana | B37: maude comtois cabana | C37: A5071955961 | D37: A5007654876 | E37: 95 | F37: =IF(_xlfn.XLOOKUP(C37,'75'!$C$2:$C$509,'75'!$D$2:$D$509)=D37,'75'!F37) -> no
A38: a carr | B38: a carter | C38: A5081082111 | D38: A5004107679 | E38: 86 | F38: =IF(_xlfn.XLOOKUP(C38,'75'!$C$2:$C$509,'75'!$D$2:$D$509)=D38,'75'!F38) -> no
A39: stephanie j cooper | B39: stephanie cooper | C39: A5103638663 | D39: A5111618796 | E39: 94 | F39: =IF(_xlfn.XLOOKUP(C39,'75'!$C$2:$C$509,'75'!$D$2:$D$509)=D39,'75'!F39) -> ok
A40: dave clarke | B40: dave c clarke | C40: A5075735110 | D40: A5112840346 | E40: 92 | F40: =IF(_xlfn.XLOOKUP(C40,'75'!$C$2:$C$509,'75'!$D$2:$D$509)=D40,'75'!F40) -> ok
A41: caroline coljin | B41: caroline colijin | C41: A5019122524 | D41: A5092252314 | E41: 97 | F41: =IF(_xlfn.XLOOKUP(C41,'75'!$C$2:$C$509,'75'!$D$2:$D$509)=D41,'75'!F41) -> no
...

Sheet 85
A1: name1 | B1: name2 | C1: id1 | D1: id2 | E1: similarity_score | F1: ok/no
A2: ahmed alâ€rawi | B2: ahmed al-rawi | C2: A5050245548 | D2: A5093769593 | E2: 92 | F2: =IF(_xlfn.XLOOKUP(C2,'75'!$C$2:$C$509,'75'!$D$2:$D$509)=D2,'75'!F2) -> ok | H2: %ok | I2: =COUNTIF(F2:F159, "ok")/158 -> 0.44936709 | J2: =COUNTIF(F2:F159, "ok") -> 71
A3: vinÃ­cius c azevedo | B3: vinicius c azevedo | C3: A5112368463 | D3: A5103260690 | E3: 94 | F3: =IF(_xlfn.XLOOKUP(C3,'75'!$C$2:$C$509,'75'!$D$2:$D$509)=D3,'75'!F3) -> no | H3: %no | I3: =COUNTIF(F2:F159, "no")/158 -> 0.55063291 | J3: =COUNTIF(F2:F159,"no") -> 87
A4: joshua d alampi | B4: josh alampi | C4: A5005530879 | D4: A5064096264 | E4: 85 | F4: =IF(_xlfn.XLOOKUP(C4,'75'!$C$2:$C$509,'75'!$D$2:$D$509)=D4,'75'!F4) -> no
A5: mark a brockman | B5: ma brockman | C5: A5021397351 | D5: A5062945775 | E5: 85 | F5: =IF(_xlfn.XLOOKUP(C5,'75'!$C$2:$C$509,'75'!$D$2:$D$509)=D5,'75'!F5) -> no
A6: christopher beh | B6: christopher buse | C6: A5012256170 | D6: A5118970217 | E6: 90 | F6: no
A7: tom c brown | B7: tom brown | C7: A5112796676 | D7: A5078745916 | E7: 90 | F7: =IF(_xlfn.XLOOKUP(C7,'75'!$C$2:$C$509,'75'!$D$2:$D$509)=D7,'75'!F7) -> no
A8: andreÇ a bulatov | B8: andreÄ­ a bulatov | C8: A5103266587 | D8: A5108247017 | E8: 94 | F8: =IF(_xlfn.XLOOKUP(C8,'75'!$C$2:$C$509,'75'!$D$2:$D$509)=D8,'75'!F8) -> no
A9: megan barker | B9: megan k barker | C9: A5056468452 | D9: A5054202306 | E9: 92 | F9: =IF(_xlfn.XLOOKUP(C9,'75'!$C$2:$C$509,'75'!$D$2:$D$509)=D9,'75'!F9) -> no
A10: tim u h baumeister | B10: tim baumeister | C10: A5019595229 | D10: A5058323325 | E10: 88 | F10: =IF(_xlfn.XLOOKUP(C10,'75'!$C$2:$C$509,'75'!$D$2:$D$509)=D10,'75'!F10) -> no
A11: andreea bratu | B11: andreea barbu | C11: A5064542404 | D11: A5098667658 | E11: 85 | F11: =IF(_xlfn.XLOOKUP(C11,'75'!$C$2:$C$509,'75'!$D$2:$D$509)=D11,'75'!F11) -> ok
A12: jil a busmann | B12: jil busmann | C12: A5072224327 | D12: A5074527350 | E12: 92 | F12: =IF(_xlfn.XLOOKUP(C12,'75'!$C$2:$C$509,'75'!$D$2:$D$509)=D12,'75'!F12) -> no
A13: scott e bernstein | B13: scott bernstein | C13: A5057881599 | D13: A5002125273 | E13: 94 | F13: =IF(_xlfn.XLOOKUP(C13,'75'!$C$2:$C$509,'75'!$D$2:$D$509)=D13,'75'!F13) -> no
A14: alishba bibal | B14: alishba bilal | C14: A5115512232 | D14: A5112957369 | E14: 92 | F14: =IF(_xlfn.XLOOKUP(C14,'75'!$C$2:$C$509,'75'!$D$2:$D$509)=D14,'75'!F14) -> ok
A15: ignacio calderon de la barca | B15: igacio calderon de la barca | C15: A5017248675 | D15: A5050733708 | E15: 98 | F15: =IF(_xlfn.XLOOKUP(C15,'75'!$C$2:$C$509,'75'!$D$2:$D$509)=D15,'75'!F15) -> no
A16: z brumme | B16: zl brumme | C16: A5075252668 | D16: A5084001641 | E16: 94 | F16: =IF(_xlfn.XLOOKUP(C16,'75'!$C$2:$C$509,'75'!$D$2:$D$509)=D16,'75'!F16) -> no
A17: mirzafaisal beg | B17: mirza faisal beg | C17: A5104015115 | D17: A5000972836 | E17: 97 | F17: =IF(_xlfn.XLOOKUP(C17,'75'!$C$2:$C$509,'75'!$D$2:$D$509)=D17,'75'!F17) -> ok
A18: john j clague | B18: j j clague | C18: A5090873433 | D18: A5000296592 | E18: 87 | F18: =IF(_xlfn.XLOOKUP(C18,'75'!$C$2:$C$509,'75'!$D$2:$D$509)=D18,'75'!F18) -> no
... A20: caroline colijn | B20: caroline coljin | C20: A5091754800 | D20: A5019122524 | E20: 93 | F20: =IF(_xlfn.XLOOKUP(C20,'75'!$C$2:$C$509,'75'!$D$2:$D$509)=D20,'75'!F20) -> no
A21: caroline colijn | B21: caroline colijin | C21: A5091754800 | D21: A5092252314 | E21: 97 | F21: ok
A22: yuxi chen | B22: xi chen | C22: A5100764265 | D22: A5100690182 | E22: 88 | F22: no
A23: brian e conway | B23: brian conway | C23: A5109163734 | D23: A5101537673 | E23: 92 | F23: =IF(_xlfn.XLOOKUP(C23,'75'!$C$2:$C$509,'75'!$D$2:$D$509)=D23,'75'!F23) -> ok
A24: david c clarke | B24: dave c clarke | C24: A5062270975 | D24: A5112840346 | E24: 89 | F24: ok
A25: teresa cheung | B25: teresa p cheung | C25: A5077739432 | D25: A5079537793 | E25: 93 | F25: ok
A26: anita t cotÃ© | B26: anita cotÃ© | C26: A5072214202 | D26: A5066224186 | E26: 91 | F26: =IF(_xlfn.XLOOKUP(C26,'75'!$C$2:$C$509,'75'!$D$2:$D$509)=D26,'75'!F26) -> no
A27: stephen choi | B27: stephen collis | C27: A5046677225 | D27: A5015481958 | E27: 85 | F27: =IF(_xlfn.XLOOKUP(C27,'75'!$C$2:$C$509,'75'!$D$2:$D$509)=D27,'75'!F27) -> ok
A28: daniel chang | B28: daniel chiang | C28: A5044668950 | D28: A5006979877 | E28: 96 | F28: no
A29: si chen | B29: xi chen | C29: A5100366176 | D29: A5100690182 | E29: 86 | F29: no
A30: qimin chen | B30: imin chen | C30: A5069419461 | D30: A5024124555 | E30: 95 | F30: =IF(_xlfn.XLOOKUP(C30,'75'!$C$2:$C$509,'75'!$D$2:$D$509)=D30,'75'!F30) -> ok
A31: maude comtoisâ€cabana | B31: maude comtois cabana | C31: A5071955961 | D31: A5007654876 | E31: 95 | F31: =IF(_xlfn.XLOOKUP(C31,'75'!$C$2:$C$509,'75'!$D$2:$D$509)=D31,'75'!F31) -> ok
A32: a carr | B32: a carter | C32: A5081082111 | D32: A5004107679 | E32: 86 | F32: =IF(_xlfn.XLOOKUP(C32,'75'!$C$2:$C$509,'75'!$D$2:$D$509)=D32,'75'!F32) -> no
A33: stephanie j cooper | B33: stephanie cooper | C33: A5103638663 | D33: A5111618796 | E33: 94 | F33: =IF(_xlfn.XLOOKUP(C33,'75'!$C$2:$C$509,'75'!$D$2:$D$509)=D33,'75'!F33) -> no
A34: dave clarke | B34: dave c clarke | C34: A5075735110 | D34: A5112840346 | E34: 92 | F34: =IF(_xlfn.XLOOKUP(C34,'75'!$C$2:$C$509,'75'!$D$2:$D$509)=D34,'75'!F34) -> no
A35: caroline coljin | B35: caroline colijin | C35: A5019122524 | D35: A5092252314 | E35: 97 | F35: =IF(_xlfn.XLOOKUP(C35,'75'!$C$2:$C$509,'75'!$D$2:$D$509)=D35,'75'!F35) -> ok
A36: hugo cardoso | B36: hugo fv cardoso | C36: A5102492080 | D36: A5078265907 | E36: 89 | F36: =IF(_xlfn.XLOOKUP(C36,'75'!$C$2:$C$509,'75'!$D$2:$D$509)=D36,'75'!F36) -> ok
A37: sam m doesburg | B37: sam doesburg | C37: A5081393957 | D37: A5022796523 | E37: 92 | F37: =IF(_xlfn.XLOOKUP(C37,'75'!$C$2:$C$509,'75'!$D$2:$D$509)=D37,'75'!F37) -> no
A38: garth w p davies | B38: garth davies | C38: A5061377171 | D38: A5104079126 | E38: 86 | F38: =IF(_xlfn.XLOOKUP(C38,'75'!$C$2:$C$509,'75'!$D$2:$D$509)=D38,'75'!F38) -> no
A39: andrÃ©anne doyon | B39: andrÃ© doyon | C39: A5020845547 | D39: A5066893131 | E39: 85 | F39: =IF(_xlfn.XLOOKUP(C39,'75'!$C$2:$C$509,'75'!$D$2:$D$509)=D39,'75'!F39) -> ok
A40: andrÃ©anne doyon | B40: andreanne doyon | C40: A5020845547 | D40: A5106389029 | E40: 93 | F40: ok
A41: thomas donaldson | B41: tom donaldson | C41: A5002800300 | D41: A5046128130 | E41: 90 | F41: =IF(_xlfn.XLOOKUP(C41,'75'!$C$2:$C$509,'75'!$D$2:$D$509)=D41,'75'!F41) -> no
...

Sheet 88
A1: name1 | B1: name2 | C1: id1 | D1: id2 | E1: similarity_score | F1: ok/no
A2: ahmed alâ€rawi | B2: ahmed al-rawi | C2: A5050245548 | D2: A5093769593 | E2: 92 | F2: =IF(_xlfn.XLOOKUP(C2,'75'!$C$2:$C$509,'75'!$D$2:$D$509)=D2,'75'!F2) -> ok | H2: %ok | I2: =COUNTIF(F2:F123, "ok")/122 -> 0.41803279 | J2: =COUNTIF(F2:F123,"ok") -> 51
A3: vinÃ­cius c azevedo | B3: vinicius c azevedo | C3: A5112368463 | D3: A5103260690 | E3: 94 | F3: =IF(_xlfn.XLOOKUP(C3,'75'!$C$2:$C$509,'75'!$D$2:$D$509)=D3,'75'!F3) -> no | H3: %no | I3: =COUNTIF(F2:F123, "no")/122 -> 0.58196721 | J3: =COUNTIF(F2:F123,"no") -> 71
A4: christopher beh | B4: christopher buse | C4: A5012256170 | D4: A5118970217 | E4: 90 | F4: no
A5: tom c brown | B5: tom brown | C5: A5112796676 | D5: A5078745916 | E5: 90 | F5: =IF(_xlfn.XLOOKUP(C5,'75'!$C$2:$C$509,'75'!$D$2:$D$509)=D5,'75'!F5) -> no
A6: andreÇ a bulatov | B6: andreÄ­ a bulatov | C6: A5103266587 | D6: A5108247017 | E6: 94 | F6: =IF(_xlfn.XLOOKUP(C6,'75'!$C$2:$C$509,'75'!$D$2:$D$509)=D6,'75'!F6) -> ok
A7: megan barker | B7: megan k barker | C7: A5056468452 | D7: A5054202306 | E7: 92 | F7: =IF(_xlfn.XLOOKUP(C7,'75'!$C$2:$C$509,'75'!$D$2:$D$509)=D7,'75'!F7) -> no
A8: tim u h baumeister | B8: tim baumeister | C8: A5019595229 | D8: A5058323325 | E8: 88 | F8: =IF(_xlfn.XLOOKUP(C8,'75'!$C$2:$C$509,'75'!$D$2:$D$509)=D8,'75'!F8) -> no
A9: jil a busmann | B9: jil busmann | C9: A5072224327 | D9: A5074527350 | E9: 92 | F9: =IF(_xlfn.XLOOKUP(C9,'75'!$C$2:$C$509,'75'!$D$2:$D$509)=D9,'75'!F9) -> no
A10: scott e bernstein | B10: scott bernstein | C10: A5057881599 | D10: A5002125273 | E10: 94 | F10: =IF(_xlfn.XLOOKUP(C10,'75'!$C$2:$C$509,'75'!$D$2:$D$509)=D10,'75'!F10) -> no
A11: alishba bibal | B11: alishba bilal | C11: A5115512232 | D11: A5112957369 | E11: 92 | F11: =IF(_xlfn.XLOOKUP(C11,'75'!$C$2:$C$509,'75'!$D$2:$D$509)=D11,'75'!F11) -> ok
A12: ignacio calderon de la barca | B12: igacio calderon de la barca | C12: A5017248675 | D12: A5050733708 | E12: 98 | F12: =IF(_xlfn.XLOOKUP(C12,'75'!$C$2:$C$509,'75'!$D$2:$D$509)=D12,'75'!F12) -> no
A13: z brumme | B13: zl brumme | C13: A5075252668 | D13: A5084001641 | E13: 94 | F13: =IF(_xlfn.XLOOKUP(C13,'75'!$C$2:$C$509,'75'!$D$2:$D$509)=D13,'75'!F13) -> no
A14: mirzafaisal beg | B14: mirza faisal beg | C14: A5104015115 | D14: A5000972836 | E14: 97 | F14: =IF(_xlfn.XLOOKUP(C14,'75'!$C$2:$C$509,'75'!$D$2:$D$509)=D14,'75'!F14) -> ok
A15: jennifer a chan | B15: jennifer c y chan | C15: A5067228740 | D15: A5029500670 | E15: 88 | F15: =IF(_xlfn.XLOOKUP(C15,'75'!$C$2:$C$509,'75'!$D$2:$D$509)=D15,'75'!F15) -> no
A16: caroline colijn | B16: caroline coljin | C16: A5091754800 | D16: A5019122524 | E16: 93 | F16: =IF(_xlfn.XLOOKUP(C16,'75'!$C$2:$C$509,'75'!$D$2:$D$509)=D16,'75'!F16) -> no
A17: caroline colijn | B17: caroline colijin | C17: A5091754800 | D17: A5092252314 | E17: 97 | F17: ok
A18: yuxi chen | B18: xi chen | C18: A5100764265 | D18: A5100690182 | E18: 88 | F18: no
A19: brian e conway | B19: brian conway | C19: A5109163734 | D19: A5101537673 | E19: 92 | F19: =IF(_xlfn.XLOOKUP(C19,'75'!$C$2:$C$509,'75'!$D$2:$D$509)=D19,'75'!F19) -> ok
A20: david c clarke | B20: dave c clarke | C20: A5062270975 | D20: A5112840346 | E20: 89 | F20: ok
A21: teresa cheung | B21: teresa p cheung | C21: A5077739432 | D21: A5079537793 | E21: 93 | F21: ok
A22: anita t cotÃ© | B22: anita cotÃ© | C22: A5072214202 | D22: A5066224186 | E22: 91 | F22: =IF(_xlfn.XLOOKUP(C22,'75'!$C$2:$C$509,'75'!$D$2:$D$509)=D22,'75'!F22) -> no
A23: daniel chang | B23: daniel chiang | C23: A5044668950 | D23: A5006979877 | E23: 96 | F23: no
A24: qimin chen | B24: imin chen | C24: A5069419461 | D24: A5024124555 | E24: 95 | F24: =IF(_xlfn.XLOOKUP(C24,'75'!$C$2:$C$509,'75'!$D$2:$D$509)=D24,'75'!F24) -> no
A25: maude comtoisâ€cabana | B25: maude comtois cabana | C25: A5071955961 | D25: A5007654876 | E25: 95 | F25: =IF(_xlfn.XLOOKUP(C25,'75'!$C$2:$C$509,'75'!$D$2:$D$509)=D25,'75'!F25) -> no
A26: stephanie j cooper | B26: stephanie cooper | C26: A5103638663 | D26: A5111618796 | E26: 94 | F26: =IF(_xlfn.XLOOKUP(C26,'75'!$C$2:$C$509,'75'!$D$2:$D$509)=D26,'75'!F26) -> no
A27: dave clarke | B27: dave c clarke | C27: A5075735110 | D27: A5112840346 | E27: 92 | F27: =IF(_xlfn.XLOOKUP(C27,'75'!$C$2:$C$509,'75'!$D$2:$D$509)=D27,'75'!F27) -> ok
A28: caroline coljin | B28: caroline colijin | C28: A5019122524 | D28: A5092252314 | E28: 97 | F28: =IF(_xlfn.XLOOKUP(C28,'75'!$C$2:$C$509,'75'!$D$2:$D$509)=D28,'75'!F28) -> ok
A29: hugo cardoso | B29: hugo fv cardoso | C29: A5102492080 | D29: A5078265907 | E29: 89 | F29: =IF(_xlfn.XLOOKUP(C29,'75'!$C$2:$C$509,'75'!$D$2:$D$509)=D29,'75'!F29) -> no
A30: sam m doesburg | B30: sam doesburg | C30: A5081393957 | D30: A5022796523 | E30: 92 | F30: =IF(_xlfn.XLOOKUP(C30,'75'!$C$2:$C$509,'75'!$D$2:$D$509)=D30,'75'!F30) -> ok
A31: andrÃ©anne doyon | B31: andreanne doyon | C31: A5020845547 | D31: A5106389029 | E31: 93 | F31: ok
A32: thomas donaldson | B32: tom donaldson | C32: A5002800300 | D32: A5046128130 | E32: 90 | F32: =IF(_xlfn.XLOOKUP(C32,'75'!$C$2:$C$509,'75'!$D$2:$D$509)=D32,'75'!F32) -> no
A33: clara vada etter | B33: clara v etter | C33: A5077611536 | D33: A5068946645 | E33: 90 | F33: =IF(_xlfn.XLOOKUP(C33,'75'!$C$2:$C$509,'75'!$D$2:$D$509)=D33,'75'!F33) -> no
A34: richard g frank | B34: richard frank | C34: A5018486913 | D34: A5030367930 | E34: 93 | F34: =IF(_xlfn.XLOOKUP(C34,'75'!$C$2:$C$509,'75'!$D$2:$D$509)=D34,'75'!F34) -> no
A35: faranak farzan | B35: farnak farzan | C35: A5015821361 | D35: A5016330282 | E35: 96 | F35: =IF(_xlfn.XLOOKUP(C35,'75'!$C$2:$C$509,'75'!$D$2:$D$509)=D35,'75'!F35) -> ok
A36: andrei v frolov | B36: andrei v frolovand | C36: A5036300411 | D36: A5047401072 | E36: 91 | F36: =IF(_xlfn.XLOOKUP(C36,'75'!$C$2:$C$509,'75'!$D$2:$D$509)=D36,'75'!F36) -> ok
A37: henry a finn | B37: henry finn | C37: A5029860397 | D37: A5080374417 | E37: 91 | F37: =IF(_xlfn.XLOOKUP(C37,'75'!$C$2:$C$509,'75'!$D$2:$D$509)=D37,'75'!F37) -> no
A38: ron ferguson | B38: arron ferguson | C38: A5113563751 | D38: A5037222281 | E38: 92 | F38: =IF(_xlfn.XLOOKUP(C38,'75'!$C$2:$C$509,'75'!$D$2:$D$509)=D38,'75'!F38) -> no
A39: sina fatolahzadeh | B39: s fatolahzadeh | C39: A5028619456 | D39: A5106384340 | E39: 90 | F39: =IF(_xlfn.XLOOKUP(C39,'75'!$C$2:$C$509,'75'!$D$2:$D$509)=D39,'75'!F39) -> ok
A40: birutÃ© m f galdikas | B40: birute mary f galdikas | C40: A5110301419 | D40: A5110389729 | E40: 88 | F40: =IF(_xlfn.XLOOKUP(C40,'75'!$C$2:$C$509,'75'!$D$2:$D$509)=D40,'75'!F40) -> ok
...

Sheet 90
A1: name1 | B1: name2 | C1: id1 | D1: id2 | E1: similarity_score | F1: ok/no
A2: ahmed alâ€rawi | B2: ahmed al-rawi | C2: A5050245548 | D2: A5093769593 | E2: 92 | F2: =IF(_xlfn.XLOOKUP(C2,'75'!$C$2:$C$509,'75'!$D$2:$D$509)=D2,'75'!F2) -> ok | H2: %ok | I2: =COUNTIF(F2:F103, "ok")/102 -> 0.40196078 | J2: =COUNTIF(F2:F103,"ok") -> 41
A3: vinÃ­cius c azevedo | B3: vinicius c azevedo | C3: A5112368463 | D3: A5103260690 | E3: 94 | F3: =IF(_xlfn.XLOOKUP(C3,'75'!$C$2:$C$509,'75'!$D$2:$D$509)=D3,'75'!F3) -> no | H3: %no | I3: =COUNTIF(F2:F103,"no")/102 -> 0.59803922 | J3: =COUNTIF(F2:F103, "no") -> 61
A4: christopher beh | B4: christopher buse | C4: A5012256170 | D4: A5118970217 | E4: 90 | F4: no
A5: tom c brown | B5: tom brown | C5: A5112796676 | D5: A5078745916 | E5: 90 | F5: =IF(_xlfn.XLOOKUP(C5,'75'!$C$2:$C$509,'75'!$D$2:$D$509)=D5,'75'!F5) -> no
A6: andreÇ a bulatov | B6: andreÄ­ a bulatov | C6: A5103266587 | D6: A5108247017 | E6: 94 | F6: =IF(_xlfn.XLOOKUP(C6,'75'!$C$2:$C$509,'75'!$D$2:$D$509)=D6,'75'!F6) -> ok
A7: megan barker | B7: megan k barker | C7: A5056468452 | D7: A5054202306 | E7: 92 | F7: =IF(_xlfn.XLOOKUP(C7,'75'!$C$2:$C$509,'75'!$D$2:$D$509)=D7,'75'!F7) -> no
A8: jil a busmann | B8: jil busmann | C8: A5072224327 | D8: A5074527350 | E8: 92 | F8: =IF(_xlfn.XLOOKUP(C8,'75'!$C$2:$C$509,'75'!$D$2:$D$509)=D8,'75'!F8) -> no
A9: ` | B9: scott bernstein | C9: A5057881599 | D9: A5002125273 | E9: 94 | F9: =IF(_xlfn.XLOOKUP(C9,'75'!$C$2:$C$509,'75'!$D$2:$D$509)=D9,'75'!F9) -> no
A10: alishba bibal | B10: alishba bilal | C10: A5115512232 | D10: A5112957369 | E10: 92 | F10: =IF(_xlfn.XLOOKUP(C10,'75'!$C$2:$C$509,'75'!$D$2:$D$509)=D10,'75'!F10) -> no
A11: ignacio calderon de la barca | B11: igacio calderon de la barca | C11: A5017248675 | D11: A5050733708 | E11: 98 | F11: =IF(_xlfn.XLOOKUP(C11,'75'!$C$2:$C$509,'75'!$D$2:$D$509)=D11,'75'!F11) -> ok
A12: z brumme | B12: zl brumme | C12: A5075252668 | D12: A5084001641 | E12: 94 | F12: =IF(_xlfn.XLOOKUP(C12,'75'!$C$2:$C$509,'75'!$D$2:$D$509)=D12,'75'!F12) -> no
A13: mirzafaisal beg | B13: mirza faisal beg | C13: A5104015115 | D13: A5000972836 | E13: 97 | F13: =IF(_xlfn.XLOOKUP(C13,'75'!$C$2:$C$509,'75'!$D$2:$D$509)=D13,'75'!F13) -> no
A14: caroline colijn | B14: caroline coljin | C14: A5091754800 | D14: A5019122524 | E14: 93 | F14: =IF(_xlfn.XLOOKUP(C14,'75'!$C$2:$C$509,'75'!$D$2:$D$509)=D14,'75'!F14) -> ok
A15: caroline colijn | B15: caroline colijin | C15: A5091754800 | D15: A5092252314 | E15: 97 | F15: ok
A16: brian e conway | B16: brian conway | C16: A5109163734 | D16: A5101537673 | E16: 92 | F16: =IF(_xlfn.XLOOKUP(C16,'75'!$C$2:$C$509,'75'!$D$2:$D$509)=D16,'75'!F16) -> no
A17: teresa cheung | B17: teresa p cheung | C17: A5077739432 | D17: A5079537793 | E17: 93 | F17: ok
A18: anita t cotÃ© | B18: anita cotÃ© | C18: A5072214202 | D18: A5066224186 | E18: 91 | F18: =IF(_xlfn.XLOOKUP(C18,'75'!$C$2:$C$509,'75'!$D$2:$D$509)=D18,'75'!F18) -> no
A19: daniel chang | B19: daniel chiang | C19: A5044668950 | D19: A5006979877 | E19: 96 | F19: no
A20: qimin chen | B20: imin chen | C20: A5069419461 | D20: A5024124555 | E20: 95 | F20: =IF(_xlfn.XLOOKUP(C20,'75'!$C$2:$C$509,'75'!$D$2:$D$509)=D20,'75'!F20) -> no
A21: maude comtoisâ€cabana | B21: maude comtois cabana | C21: A5071955961 | D21: A5007654876 | E21: 95 | F21: =IF(_xlfn.XLOOKUP(C21,'75'!$C$2:$C$509,'75'!$D$2:$D$509)=D21,'75'!F21) -> no
A22: stephanie j cooper | B22: stephanie cooper | C22: A5103638663 | D22: A5111618796 | E22: 94 | F22: =IF(_xlfn.XLOOKUP(C22,'75'!$C$2:$C$509,'75'!$D$2:$D$509)=D22,'75'!F22) -> no
A23: dave clarke | B23: dave c clarke | C23: A5075735110 | D23: A5112840346 | E23: 92 | F23: =IF(_xlfn.XLOOKUP(C23,'75'!$C$2:$C$509,'75'!$D$2:$D$509)=D23,'75'!F23) -> ok
A24: caroline coljin | B24: caroline colijin | C24: A5019122524 | D24: A5092252314 | E24: 97 | F24: =IF(_xlfn.XLOOKUP(C24,'75'!$C$2:$C$509,'75'!$D$2:$D$509)=D24,'75'!F24) -> no
A25: sam m doesburg | B25: sam doesburg | C25: A5081393957 | D25: A5022796523 | E25: 92 | F25: =IF(_xlfn.XLOOKUP(C25,'75'!$C$2:$C$509,'75'!$D$2:$D$509)=D25,'75'!F25) -> no
A26: andrÃ©anne doyon | B26: andreanne doyon | C26: A5020845547 | D26: A5106389029 | E26: 93 | F26: ok
A27: thomas donaldson | B27: tom donaldson | C27: A5002800300 | D27: A5046128130 | E27: 90 | F27: =IF(_xlfn.XLOOKUP(C27,'75'!$C$2:$C$509,'75'!$D$2:$D$509)=D27,'75'!F27) -> ok
A28: clara vada etter | B28: clara v etter | C28: A5077611536 | D28: A5068946645 | E28: 90 | F28: =IF(_xlfn.XLOOKUP(C28,'75'!$C$2:$C$509,'75'!$D$2:$D$509)=D28,'75'!F28) -> ok
A29: richard g frank | B29: richard frank | C29: A5018486913 | D29: A5030367930 | E29: 93 | F29: =IF(_xlfn.XLOOKUP(C29,'75'!$C$2:$C$509,'75'!$D$2:$D$509)=D29,'75'!F29) -> no
A30: faranak farzan | B30: farnak farzan | C30: A5015821361 | D30: A5016330282 | E30: 96 | F30: =IF(_xlfn.XLOOKUP(C30,'75'!$C$2:$C$509,'75'!$D$2:$D$509)=D30,'75'!F30) -> ok
A31: andrei v frolov | B31: andrei v frolovand | C31: A5036300411 | D31: A5047401072 | E31: 91 | F31: =IF(_xlfn.XLOOKUP(C31,'75'!$C$2:$C$509,'75'!$D$2:$D$509)=D31,'75'!F31) -> ok
A32: henry a finn | B32: henry finn | C32: A5029860397 | D32: A5080374417 | E32: 91 | F32: =IF(_xlfn.XLOOKUP(C32,'75'!$C$2:$C$509,'75'!$D$2:$D$509)=D32,'75'!F32) -> no
A33: ron ferguson | B33: arron ferguson | C33: A5113563751 | D33: A5037222281 | E33: 92 | F33: =IF(_xlfn.XLOOKUP(C33,'75'!$C$2:$C$509,'75'!$D$2:$D$509)=D33,'75'!F33) -> no
A34: sina fatolahzadeh | B34: s fatolahzadeh | C34: A5028619456 | D34: A5106384340 | E34: 90 | F34: =IF(_xlfn.XLOOKUP(C34,'75'!$C$2:$C$509,'75'!$D$2:$D$509)=D34,'75'!F34) -> no
A35: alissa greer | B35: alissa m greer | C35: A5037509232 | D35: A5102942084 | E35: 92 | F35: =IF(_xlfn.XLOOKUP(C35,'75'!$C$2:$C$509,'75'!$D$2:$D$509)=D35,'75'!F35) -> ok
A36: daniel r y gan | B36: daniel ry gan | C36: A5075926575 | D36: A5091261371 | E36: 96 | F36: =IF(_xlfn.XLOOKUP(C36,'75'!$C$2:$C$509,'75'!$D$2:$D$509)=D36,'75'!F36) -> ok
A37: shreemouna gurung | B37: sheemouna gurung | C37: A5088826260 | D37: A5114125674 | E37: 97 | F37: =IF(_xlfn.XLOOKUP(C37,'75'!$C$2:$C$509,'75'!$D$2:$D$509)=D37,'75'!F37) -> no
A38: bhargav gadhvi | B38: bhargav gadhavi | C38: A5024718097 | D38: A5067698309 | E38: 97 | F38: =IF(_xlfn.XLOOKUP(C38,'75'!$C$2:$C$509,'75'!$D$2:$D$509)=D38,'75'!F38) -> no
... A55: angela kaida | B55: angela kaidaon | C55: A5091089188 | D55: A5095333481 | E55: 92 | F55: =IF(_xlfn.XLOOKUP(C55,'75'!$C$2:$C$509,'75'!$D$2:$D$509)=D55,'75'!F55) -> ok
A56: cheng li | B56: cheng lit | C56: A5100354297 | D56: A5094001550 | E56: 94 | F56: ok
...

Sheet comparisons
B1: 75 | C1: 78 | D1: 80 | E1: 82 | F1: 85 | G1: 88 | H1: 90
A2: Proportion Correct | B2: {='75'!I2:I3} -> 0.37401575 | C2: {='78'!I2:I3} -> 0.40532544 | D2: {='80'!I2:I3} -> 0.38487973 | E2: {='82'!I2:I3} -> 0.40454545 | F2: {='85'!I2:I3} -> 0.44936709 | G2: {='88'!I2:I3} -> 0.41803279 | H2: {='90'!I2:I3} -> 0.40196078
A3: Proportion Wrong | B3: 0.62598425 | C3: 0.59467456 | D3: 0.61512027 | E3: 0.59545455 | F3: 0.55063291 | G3: 0.58196721 | H3: 0.59803922
B5: 75 | C5: 78 | D5: 80 | E5: 82 | F5: 85 | G5: 88 | H5: 90
A6: Count Correct | B6: {='75'!J2:J3} -> 190 | C6: {='78'!J2:J3} -> 137 | D6: {='80'!J2:J3} -> 112 | E6: {='82'!J2:J3} -> 89 | F6: {='85'!J2:J3} -> 71 | G6: {='88'!J2:J3} -> 51 | H6: {='90'!J2:J3} -> 41
A7: Count Wrong | B7: 318 | C7: 201 | D7: 179 | E7: 131 | F7: 87 | G7: 71 | H7: 61
