Workbook

Sheet query1
A1: id | B1: doi | C1: title | D1: publication_year | E1: publication_date | F1: language | G1: type | H1: open_access | I1: authorships | J1: countries_distinct_count | K1: institutions_distinct_count | L1: fwci | M1: has_fulltext | N1: cited_by_count | O1: biblio | P1: primary_topic | Q1: topics | R1: keywords | S1: concepts | T1: sustainable_development_goals | U1: referenced_works_count
A2: https://openalex.org/W2998917588 | B2: https://doi.org/10.3390/rs12020266 | C2: Flood Detection and Susceptibility Mapping Using Sentinel-1 Remote Sensing Data and a Machine Learning Approach: Hybrid Intelligence of Bagging Ensemble Based on K-Nearest Neighbor Classifier | D2: 2020 | E2: 43843 | F2: en | G2: article | H2: {'is_oa': True, 'oa_status': 'gold', 'oa_url': 'https://www.mdpi.com/2072-4292/12/2/266/pdf?version=1579681280', 'any_repository_has_fulltext': True} | I2: [{'author_position': 'first', 'author': {'id': 'https://openalex.org/A5091211368', 'display_name': 'Himan Shahabi', 'orcid': 'https://orcid.org/0000-0001-5091-6947'}, 'institutions': [{'id': 'https://openalex.org/I3124704065', 'display_name': 'University of Kurdistan', 'ror': 'https://ror.org/04k89yk85', 'country_code': 'IR', 'type': 'education', 'lineage': ['https://openalex.org/I3124704065']}], 'countries': ['IR'], 'is_corresponding': True, 'raw_author_name': 'Himan Shahabi', 'raw_affiliation_strings': ['Board Member of Department of Zrebar Lake Environmental Research, Kurdistan Studies Institute, University of Kurdistan, Sanandaj 66177-15175, Iran', 'Department of Geomorphology, Faculty of Natural Resources, University of Kurdistan, Sanandaj 66177-15175, Iran'], 'affiliations': [{'raw_affiliation_string': 'Board Member of Department of Zrebar Lake Environmental Research, Kurdistan Studies Institute, University of Kurdistan, Sanandaj 66177-15175, Iran', 'institution_ids': ['https://openalex.org/I3124704065']}, {'raw_affiliation_string': 'Department of Geomorphology, Faculty of Natural Resources, University of Kurdistan, Sanandaj 66177-15175, Iran', 'institution_ids': ['https://openalex.org/I3124704065']}]}, {'author_position': 'middle', 'author': {'id': 'https://openalex.org/A5063537118', 'display_name': 'Ataollah Shirzadi', 'orcid': 'https://orcid.org/0000-0001-9668-8687'}, 'institutions': [{'id': 'https://openalex.org/I3124704065', 'display_name': 'University of Kurdistan', 'ror': 'https://ror.org/04k89yk85', 'country_code': 'IR', 'type': 'education', 'lineage': ['https://openalex.org/I3124704065']}], 'countries': ['IR'], 'is_corresponding': False, 'raw_author_name': 'Ataollah Shirzadi', 'raw_affiliation_strings': ['Department of Rangeland and Watershed Management, Faculty of Natural Resources, University of Kurdistan, Sanandaj 66177-15175, Iran'], 'affiliations': [{'raw_affiliation_string': 'Department of Rangeland and Watershed Management, Faculty of Natural Resources, University of Kurdistan, Sanandaj 66177-15175, Iran', 'institution_ids': ['https://openalex.org/I3124704065']}]}, {'author_position': 'middle', 'author': {'id': 'https://openalex.org/A5024191113', 'display_name': 'Kayvan Ghaderi', 'orcid': 'https://orcid.org/0000-0002-0741-7744'}, 'institutions': [{'id': 'https://openalex.org/I3124704065', 'display_name': 'University of Kurdistan', 'ror': 'https://ror.org/04k89yk85', 'country_code': 'IR', 'type': 'education', 'lineage': ['https://openalex.org/I3124704065']}], 'countries': ['IR'], 'is_corresponding': False, 'raw_author_name': 'Kayvan Ghaderi', 'raw_affiliation_strings': ['Department of Information Technology and Computer Engineering, Faculty of Engineering, University of Kurdistan, Sanandaj 66177-15175, Iran'], 'affiliations': [{'raw_affiliation_string': 'Department of Information Technology and Computer Engineering, Faculty of Engineering, University of Kurdistan, Sanandaj 66177-15175, Iran', 'institution_ids': ['https://openalex.org/I3124704065']}]}, {'author_position': 'middle', 'author': {'id': 'https://openalex.org/A5081211065', 'display_name': 'Ebrahim Omidvar', 'orcid': 'https://orcid.org/0000-0002-8784-3646'}, 'institutions': [{'id': 'https://openalex.org/I105818395', 'display_name': 'University of Kashan', 'ror': 'https://ror.org/015zmr509', 'country_code': 'IR', 'type': 'education', 'lineage': ['https://openalex.org/I105818395']}], 'countries': ['IR'], 'is_corresponding': False, 'raw_author_name': 'Ebrahim Omidvar', 'raw_affiliation_strings': ['Department of Rangeland and Watershed Management, Faculty of Natural Resources and Earth Sciences, University of Kashan, Kashan 87317-53153, Iran'], 'affiliations': [{'raw_affiliation_string': 'Department of Rangeland and Watershed Management, Faculty of Natural Resources and Earth Sciences, University of Kashan, Kashan 87317-53153, Iran', 'institution_ids': ['https://openalex.org/I105818395']}]}, {'author_position': 'middle', 'author': {'id': 'https://openalex.org/A5070829177', 'display_name': 'Nadhir Alâ€Ansari', 'orcid': 'https://orcid.org/0000-0002-6790-2653'}, 'institutions': [{'id': 'https://openalex.org/I190632392', 'display_name': 'LuleÃ¥ University of Technology', 'ror': 'https://ror.org/016st3p78', 'country_code': 'SE', 'type': 'education', 'lineage': ['https://openalex.org/I190632392']}], 'countries': ['SE'], 'is_corresponding': False, 'raw_author_name': 'Nadhir Al-Ansari', 'raw_affiliation_strings': ['Department of Civil, Environmental and Natural Resources Engineering, Lulea University of Technology, 971 87 Lulea, Sweden'], 'affiliations': [{'raw_affiliation_string': 'Department of Civil, Environmental and Natural Resources Engineering, Lulea University of Technology, 971 87 Lulea, Sweden', 'institution_ids': ['https://openalex.org/I190632392']}]}, {'author_position': 'middle', 'author': {'id': 'https://openalex.org/A5090873433', 'display_name': 'John J. Clague', 'orcid': 'https://orcid.org/0000-0002-2697-2233'}, 'institutions': [{'id': 'https://openalex.org/I18014758', 'display_name': 'Simon Fraser University', 'ror': 'https://ror.org/0213rcc28', 'country_code': 'CA', 'type': 'education', 'lineage': ['https://openalex.org/I18014758']}], 'countries': ['CA'], 'is_corresponding': False, 'raw_author_name': 'John J. Clague', 'raw_affiliation_strings': ['Department of Earth Sciences Simon Fraser University 8888 University Drive Burnaby, Burnaby, BC V5A 1S6, Canada'], 'affiliations': [{'raw_affiliation_string': 'Department of Earth Sciences Simon Fraser University 8888 University Drive Burnaby, Burnaby, BC V5A 1S6, Canada', 'institution_ids': ['https://openalex.org/I18014758']}]}, {'author_position': 'middle', 'author': {'id': 'https://openalex.org/A5081186550', 'display_name': 'Marten Geertsema', 'orcid': 'https://orcid.org/0000-0002-4650-8251'}, 'institutions': [{'id': 'https://openalex.org/I4210131853', 'display_name': 'Ministry of Forests', 'ror': 'https://ror.org/03cx3d993', 'country_code': 'CA', 'type': 'government', 'lineage': ['https://openalex.org/I4210131853']}], 'countries': ['CA'], 'is_corresponding': False, 'raw_author_name': 'Marten Geertsema', 'raw_affiliation_strings': ['British Columbia, Ministry of Forests, Lands, Natural Resource Operations and Rural Development, Prince George, BC V2L 1R5, Canada'], 'affiliations': [{'raw_affiliation_string': 'British Columbia, Ministry of Forests, Lands, Natural Resource Operations and Rural Development, Prince George, BC V2L 1R5, Canada', 'institution_ids': ['https://openalex.org/I4210131853']}]}, {'author_position': 'middle', 'author': {'id': 'https://openalex.org/A5083514118', 'display_name': 'Khabat Khosravi', 'orcid': 'https://orcid.org/0000-0001-5773-4003'}, 'institutions': [{'id': 'https://openalex.org/I79817857', 'display_name': 'University of Guelph', 'ror': 'https://ror.org/01r7awg59', 'country_code': 'CA', 'type': 'education', 'lineage': ['https://openalex.org/I79817857']}], 'countries': ['CA'], 'is_corresponding': False, 'raw_author_name': 'Khabat Khosravi', 'raw_affiliation_strings': ['School of Engineering, University of Guelph, Guelph, ON N1G 2W1, Canada'], 'affiliations': [{'raw_affiliation_string': 'School of Engineering, University of Guelph, Guelph, ON N1G 2W1, Canada', 'institution_ids': ['https://openalex.org/I79817857']}]}, {'author_position': 'middle', 'author': {'id': 'https://openalex.org/A5053124996', 'display_name': 'Ata Amini', 'orcid': 'https://orcid.org/0000-0001-9358-185X'}, 'institutions': [{'id': 'https://openalex.org/I4210141426', 'display_name': 'Agricultural Research & Education Organization', 'ror': 'https://ror.org/032hv6w38', 'country_code': 'IR', 'type': 'nonprofit', 'lineage': ['https://openalex.org/I4210141426']}, {'id': 'https://openalex.org/I4210088633', 'display_name': 'Soil Conservation and Watershed Management Research', 'ror': 'https://ror.org/0066jc902', 'country_code': 'IR', 'type': 'facility', 'lineage': ['https://openalex.org/I4210088633']}], 'countries': ['IR'], 'is_corresponding': False, 'raw_author_name': 'Ata Amini', 'raw_affiliation_strings': ['Kurdistan Agricultural and Natural Resources Research and Education Center, AREEO, Sanandaj 66177-15175, Iran'], 'affiliations': [{'raw_affiliation_string': 'Kurdistan Agricultural and Natural Resources Research and Education Center, AREEO, Sanandaj 66177-15175, Iran', 'institution_ids': ['https://openalex.org/I4210088633', 'https://openalex.org/I4210141426']}]}, {'author_position': 'middle', 'author': {'id': 'https://openalex.org/A5007654910', 'display_name': 'Sepideh Bahrami', 'orcid': 'https://orcid.org/0000-0003-2174-2145'}, 'institutions': [{'id': 'https://openalex.org/I134113660', 'display_name': 'University of Nevada, Reno', 'ror': 'https://ror.org/01keh0577', 'country_code': 'US', 'type': 'education', 'lineage': ['https://openalex.org/I134113660']}], 'countries': ['US'], 'is_corresponding': False, 'raw_author_name': 'Sepideh Bahrami', 'raw_affiliation_strings': ['Department of Hydrological Sciences, University of Nevada, 89557-02601-775-685-8040, Reno, NV 89557, USA'], 'affiliations': [{'raw_affiliation_string': 'Department of Hydrological Sciences, University of Nevada, 89557-02601-775-685-8040, Reno, NV 89557, USA', 'institution_ids': ['https://openalex.org/I134113660']}]}, {'author_position': 'middle', 'author': {'id': 'https://openalex.org/A5039567207', 'display_name': 'Omid Rahmati', 'orcid': 'https://orcid.org/0000-0001-5672-8525'}, 'institutions': [{'id': 'https://openalex.org/I4210141426', 'display_name': 'Agricultural Research & Education Organization', 'ror': 'https://ror.org/032hv6w38', 'country_code': 'IR', 'type': 'nonprofit', 'lineage': ['https://openalex.org/I4210141426']}, {'id': 'https://openalex.org/I4210088633', 'display_name': 'Soil Conservation and Watershed Management Research', 'ror': 'https://ror.org/0066jc902', 'country_code': 'IR', 'type': 'facility', 'lineage': ['https://openalex.org/I4210088633']}], 'countries': ['IR'], 'is_corresponding': False, 'raw_author_name': 'Omid Rahmati', 'raw_affiliation_strings': ['Kurdistan Agricultural and Natural Resources Research and Education Center, AREEO, Sanandaj 66177-15175, Iran'], 'affiliations': [{'raw_affiliation_string': 'Kurdistan Agricultural and Natural Resources Research and Education Center, AREEO, Sanandaj 66177-15175, Iran', 'institution_ids': ['https://openalex.org/I4210088633', 'https://openalex.org/I4210141426']}]}, {'author_position': 'middle', 'author': {'id': 'https://openalex.org/A5090793544', 'display_name': 'Kyoumars Habibi', 'orcid': 'https://orcid.org/0000-0002-7093-9625'}, 'institutions': [{'id': 'https://openalex.org/I3124704065', 'display_name': 'University of Kurdistan', 'ror': 'https://ror.org/04k89yk85', 'country_code': 'IR', 'type': 'education', 'lineage': ['https://openalex.org/I3124704065']}], 'countries': ['IR'], 'is_corresponding': False, 'raw_author_name': 'Kyoumars Habibi', 'raw_affiliation_strings': ['Department of urban and regional planning, Faculty of Art and Architecture, University of Kurdistan, Sanandaj 66177-15175, Iran'], 'affiliations': [{'raw_affiliation_string': 'Department of urban and regional planning, Faculty of Art and Architecture, University of Kurdistan, Sanandaj 66177-15175, Iran', 'institution_ids': ['https://openalex.org/I3124704065']}]}, {'author_position': 'middle', 'author': {'id': 'https://openalex.org/A5002151224', 'display_name': 'Ayub Mohammadi', 'orcid': 'https://orcid.org/0000-0001-8848-8917'}, 'institutions': [{'id': 'https://openalex.org/I4576418', 'display_name': 'University of Technology Malaysia', 'ror': 'https://ror.org/026w31v75', 'country_code': 'MY', 'type': 'education', 'lineage': ['https://openalex.org/I4576418']}], 'countries': ['MY'], 'is_corresponding': False, 'raw_author_name': 'Ayub Mohammadi', 'raw_affiliation_strings': ['Department of Geoinformation, Faculty of Built Environment and Surveying, Universiti Teknologi Malaysia (UTM), 81310 Johor Bahru, Malaysia'], 'affiliations': [{'raw_affiliation_string': 'Department of Geoinformation, Faculty of Built Environment and Surveying, Universiti Teknologi Malaysia (UTM), 81310 Johor Bahru, Malaysia', 'institution_ids': ['https://openalex.org/I4576418']}]}, {'author_position': 'middle', 'author': {'id': 'https://openalex.org/A5080411341', 'display_name': 'Hoang Nguyen', 'orcid': 'https://orcid.org/0000-0001-6122-8314'}, 'institutions': [{'id': 'https://openalex.org/I170238339', 'display_name': 'Duy Tan University', 'ror': 'https://ror.org/05ezss144', 'country_code': 'VN', 'type': 'education', 'lineage': ['https://openalex.org/I170238339']}], 'countries': ['VN'], 'is_corresponding': False, 'raw_author_name': 'Hoang Nguyen', 'raw_affiliation_strings': ['Institute of Research and Development, Duy Tan University, Da Nang 550000, Vietnam'], 'affiliations': [{'raw_affiliation_string': 'Institute of Research and Development, Duy Tan University, Da Nang 550000, Vietnam', 'institution_ids': ['https://openalex.org/I170238339']}]}, {'author_position': 'middle', 'author': {'id': 'https://openalex.org/A5050922013', 'display_name': 'Assefa M. Melesse', 'orcid': 'https://orcid.org/0000-0003-4724-9367'}, 'institutions': [{'id': 'https://openalex.org/I19700959', 'display_name': 'Florida International University', 'ror': 'https://ror.org/02gz6gg07', 'country_code': 'US', 'type': 'education', 'lineage': ['https://openalex.org/I19700959']}], 'countries': ['US'], 'is_corresponding': False, 'raw_author_name': 'Assefa M. Melesse', 'raw_affiliation_strings': ['Department of Earth and Environment, Florida International University, Miami, FL 33199, USA'], 'affiliations': [{'raw_affiliation_string': 'Department of Earth and Environment, Florida International University, Miami, FL 33199, USA', 'institution_ids': ['https://openalex.org/I19700959']}]}, {'author_position': 'middle', 'author': {'id': 'https://openalex.org/A5110285224', 'display_name': 'Baharin Bin Ahmad', 'orcid': None}, 'institutions': [{'id': 'https://openalex.org/I4576418', 'display_name': 'University of Technology Malaysia', 'ror': 'https://ror.org/026w31v75', 'country_code': 'MY', 'type': 'education', 'lineage': ['https://openalex.org/I4576418']}], 'countries': ['MY'], 'is_corresponding': False, 'raw_author_name': 'Baharin Bin Ahmad', 'raw_affiliation_strings': ['Department of Geoinformation, Faculty of Built Environment and Surveying, Universiti Teknologi Malaysia (UTM), 81310 Johor Bahru, Malaysia'], 'affiliations': [{'raw_affiliation_string': 'Department of Geoinformation, Faculty of Built Environment and Surveying, Universiti Teknologi Malaysia (UTM), 81310 Johor Bahru, Malaysia', 'institution_ids': ['https://openalex.org/I4576418']}]}, {'author_position': 'last', 'author': {'id': 'https://openalex.org/A5108111405', 'display_name': 'Anuar Ahmad', 'orcid': None}, 'institutions': [{'id': 'https://openalex.org/I4576418', 'display_name': 'University of Technology Malaysia', 'ror': 'https://ror.org/026w31v75', 'country_code': 'MY', 'type': 'education', 'lineage': ['https://openalex.org/I4576418']}], 'countries': ['MY'], 'is_corresponding': False, 'raw_author_name': 'Anuar Ahmad', 'raw_affiliation_strings': ['Department of Geoinformation, Faculty of Built Environment and Surveying, Universiti Teknologi Malaysia (UTM), 81310 Johor Bahru, Malaysia'], 'affiliations': [{'raw_affiliation_string': 'Department of Geoinformation, Faculty of Built Environment and Surveying, Universiti Teknologi Malaysia (UTM), 81310 Johor Bahru, Malaysia', 'institution_ids': ['https://openalex.org/I4576418']}]}] | J2: 6 | K2: 17 | L2: 21.4237 | M2: FALSE | N2: 355 | O2: {'volume': '12', 'issue': '2', 'first_page': '266', 'last_page': '266'} | P2: {'id': 'https://openalex.org/T10930', 'display_name': 'Flood Risk Assessment and Management', 'score': 1.0, 'subfield': {'id': 'https://openalex.org/subfields/2306', 'display_name': 'Global and Planetary Change'}, 'field': {'id': 'https://openalex.org/fields/23', 'display_name': 'Environmental Science'}, 'domain': {'id': 'https://openalex.org/domains/3', 'display_name': 'Physical Sciences'}} | Q2: [{'id': 'https://openalex.org/T10930', 'display_name': 'Flood Risk Assessment and Management', 'score': 1.0, 'subfield': {'id': 'https://openalex.org/subfields/2306', 'display_name': 'Global and Planetary Change'}, 'field': {'id': 'https://openalex.org/fields/23', 'display_name': 'Environmental Science'}, 'domain': {'id': 'https://openalex.org/domains/3', 'display_name': 'Physical Sciences'}}, {'id': 'https://openalex.org/T12543', 'display_name': 'Groundwater and Watershed Analysis', 'score': 0.9921000003814697, 'subfield': {'id': 'https://openalex.org/subfields/2305', 'display_name': 'Environmental Engineering'}, 'field': {'id': 'https://openalex.org/fields/23', 'display_name': 'Environmental Science'}, 'domain': {'id': 'https://openalex.org/domains/3', 'display_name': 'Physical Sciences'}}, {'id': 'https://openalex.org/T10330', 'display_name': 'Hydrology and Watershed Management Studies', 'score': 0.9915000200271606, 'subfield': {'id': 'https://openalex.org/subfields/2312', 'display_name': 'Water Science and Technology'}, 'field': {'id': 'https://openalex.org/fields/23', 'display_name': 'Environmental Science'}, 'domain': {'id': 'https://openalex.org/domains/3', 'display_name': 'Physical Sciences'}}] | R2: [{'id': 'https://openalex.org/keywords/overfitting', 'display_name': 'Overfitting', 'score': 0.752395749092102}, {'id': 'https://openalex.org/keywords/computer-science', 'display_name': 'Computer science', 'score': 0.6012298464775085}, {'id': 'https://openalex.org/keywords/flood-myth', 'display_name': 'Flood myth', 'score': 0.5734686851501465}, {'id': 'https://openalex.org/keywords/artificial-intelligence', 'display_name': 'Artificial intelligence', 'score': 0.5104095339775085}, {'id': 'https://openalex.org/keywords/k-nearest-neighbors-algorithm', 'display_name': 'k-nearest neighbors algorithm', 'score': 0.46870845556259155}, {'id': 'https://openalex.org/keywords/ensemble-learning', 'display_name': 'Ensemble learning', 'score': 0.4673502743244171}, {'id': 'https://openalex.org/keywords/data-mining', 'display_name': 'Data mining', 'score': 0.4642764925956726}, {'id': 'https://openalex.org/keywords/adaboost', 'display_name': 'AdaBoost', 'score': 0.4611509144306183}, {'id': 'https://openalex.org/keywords/machine-learning', 'display_name': 'Machine learning', 'score': 0.42886656522750854}, {'id': 'https://openalex.org/keywords/bootstrap-aggregating', 'display_name': 'Bootstrap aggregating', 'score': 0.42870351672172546}, {'id': 'https://openalex.org/keywords/random-forest', 'display_name': 'Random forest', 'score': 0.42514973878860474}, {'id': 'https://openalex.org/keywords/classifier', 'display_name': 'Classifier (UML)', 'score': 0.4000876545906067}, {'id': 'https://openalex.org/keywords/remote-sensing', 'display_name': 'Remote sensing', 'score': 0.3343126177787781}, {'id': 'https://openalex.org/keywords/pattern-recognition', 'display_name': 'Pattern recognition (psychology)', 'score': 0.32905542850494385}, {'id': 'https://openalex.org/keywords/artificial-neural-network', 'display_name': 'Artificial neural network', 'score': 0.15411809086799622}, {'id': 'https://openalex.org/keywords/geography', 'display_name': 'Geography', 'score': 0.11170724034309387}] | S2: [{'id': 'https://openalex.org/C22019652', 'wikidata': 'https://www.wikidata.org/wiki/Q331309', 'display_name': 'Overfitting', 'level': 3, 'score': 0.752395749092102}, {'id': 'https://openalex.org/C41008148', 'wikidata': 'https://www.wikidata.org/wiki/Q21198', 'display_name': 'Computer science', 'level': 0, 'score': 0.6012298464775085}, {'id': 'https://openalex.org/C74256435', 'wikidata': 'https://www.wikidata.org/wiki/Q134052', 'display_name': 'Flood myth', 'level': 2, 'score': 0.5734686851501465}, {'id': 'https://openalex.org/C154945302', 'wikidata': 'https://www.wikidata.org/wiki/Q11660', 'display_name': 'Artificial intelligence', 'level': 1, 'score': 0.5104095339775085}, {'id': 'https://openalex.org/C113238511', 'wikidata': 'https://www.wikidata.org/wiki/Q1071612', 'display_name': 'k-nearest neighbors algorithm', 'level': 2, 'score': 0.46870845556259155}, {'id': 'https://openalex.org/C45942800', 'wikidata': 'https://www.wikidata.org/wiki/Q245652', 'display_name': 'Ensemble learning', 'level': 2, 'score': 0.4673502743244171}, {'id': 'https://openalex.org/C124101348', 'wikidata': 'https://www.wikidata.org/wiki/Q172491', 'display_name': 'Data mining', 'level': 1, 'score': 0.4642764925956726}, {'id': 'https://openalex.org/C141404830', 'wikidata': 'https://www.wikidata.org/wiki/Q2823869', 'display_name': 'AdaBoost', 'level': 3, 'score': 0.4611509144306183}, {'id': 'https://openalex.org/C119857082', 'wikidata': 'https://www.wikidata.org/wiki/Q2539', 'display_name': 'Machine learning', 'level': 1, 'score': 0.42886656522750854}, {'id': 'https://openalex.org/C162040801', 'wikidata': 'https://www.wikidata.org/wiki/Q799897', 'display_name': 'Bootstrap aggregating', 'level': 2, 'score': 0.42870351672172546}, {'id': 'https://openalex.org/C169258074', 'wikidata': 'https://www.wikidata.org/wiki/Q245748', 'display_name': 'Random forest', 'level': 2, 'score': 0.42514973878860474}, {'id': 'https://openalex.org/C95623464', 'wikidata': 'https://www.wikidata.org/wiki/Q1096149', 'display_name': 'Classifier (UML)', 'level': 2, 'score': 0.4000876545906067}, {'id': 'https://openalex.org/C62649853', 'wikidata': 'https://www.wikidata.org/wiki/Q199687', 'display_name': 'Remote sensing', 'level': 1, 'score': 0.3343126177787781}, {'id': 'https://openalex.org/C153180895', 'wikidata': 'https://www.wikidata.org/wiki/Q7148389', 'display_name': 'Pattern recognition (psychology)', 'level': 2, 'score': 0.32905542850494385}, {'id': 'https://openalex.org/C50644808', 'wikidata': 'https://www.wikidata.org/wiki/Q192776', 'display_name': 'Artificial neural network', 'level': 2, 'score': 0.15411809086799622}, {'id': 'https://openalex.org/C205649164', 'wikidata': 'https://www.wikidata.org/wiki/Q1071', 'display_name': 'Geography', 'level': 0, 'score': 0.11170724034309387}, {'id': 'https://openalex.org/C166957645', 'wikidata': 'https://www.wikidata.org/wiki/Q23498', 'display_name': 'Archaeology', 'level': 1, 'score': 0.0}] | T2: [{'id': 'https://metadata.un.org/sdg/13', 'display_name': 'Climate action', 'score': 0.5699999928474426}] | U2: 129
A3: https://openalex.org/W3035624836 | B3: https://doi.org/10.1109/cvpr42600.2020.01111 | C3: SAPIEN: A SimulAted Part-Based Interactive ENvironment | D3: 2020 | E3: 43983 | F3: en | G3: preprint | H3: {'is_oa': False, 'oa_status': 'closed', 'oa_url': None, 'any_repository_has_fulltext': False} | I3: [{'author_position': 'first', 'author': {'id': 'https://openalex.org/A5008903324', 'display_name': 'Fanbo Xiang', 'orcid': 'https://orcid.org/0009-0005-5335-873X'}, 'institutions': [{'id': 'https://openalex.org/I2800935791', 'display_name': 'UC San Diego Health System', 'ror': 'https://ror.org/01kbfgm16', 'country_code': 'US', 'type': 'healthcare', 'lineage': ['https://openalex.org/I2800935791']}], 'countries': ['US'], 'is_corresponding': True, 'raw_author_name': 'Fanbo Xiang', 'raw_affiliation_strings': ['UC San Diego'], 'affiliations': [{'raw_affiliation_string': 'UC San Diego', 'institution_ids': ['https://openalex.org/I2800935791']}]}, {'author_position': 'middle', 'author': {'id': 'https://openalex.org/A5060146466', 'display_name': 'Yuzhe Qin', 'orcid': 'https://orcid.org/0000-0002-9321-9305'}, 'institutions': [{'id': 'https://openalex.org/I2800935791', 'display_name': 'UC San Diego Health System', 'ror': 'https://ror.org/01kbfgm16', 'country_code': 'US', 'type': 'healthcare', 'lineage': ['https://openalex.org/I2800935791']}], 'countries': ['US'], 'is_corresponding': False, 'raw_author_name': 'Yuzhe Qin', 'raw_affiliation_strings': ['UC San Diego'], 'affiliations': [{'raw_affiliation_string': 'UC San Diego', 'institution_ids': ['https://openalex.org/I2800935791']}]}, {'author_position': 'middle', 'author': {'id': 'https://openalex.org/A5051488351', 'display_name': 'Kaichun Mo', 'orcid': 'https://orcid.org/0000-0003-4365-5050'}, 'institutions': [{'id': 'https://openalex.org/I97018004', 'display_name': 'Stanford University', 'ror': 'https://ror.org/00f54p054', 'country_code': 'US', 'type': 'education', 'lineage': ['https://openalex.org/I97018004']}], 'countries': ['US'], 'is_corresponding': False, 'raw_author_name': 'Kaichun Mo', 'raw_affiliation_strings': ['Stanford University'], 'affiliations': [{'raw_affiliation_string': 'Stanford University', 'institution_ids': ['https://openalex.org/I97018004']}]}, {'author_position': 'middle', 'author': {'id': 'https://openalex.org/A5033298018', 'display_name': 'Yikuan Xia', 'orcid': None}, 'institutions': [{'id': 'https://openalex.org/I2800935791', 'display_name': 'UC San Diego Health System', 'ror': 'https://ror.org/01kbfgm16', 'country_code': 'US', 'type': 'healthcare', 'lineage': ['https://openalex.org/I2800935791']}], 'countries': ['US'], 'is_corresponding': False, 'raw_author_name': 'Yikuan Xia', 'raw_affiliation_strings': ['UC San Diego'], 'affiliations': [{'raw_affiliation_string': 'UC San Diego', 'institution_ids': ['https://openalex.org/I2800935791']}]}, {'author_position': 'middle', 'author': {'id': 'https://openalex.org/A5043239430', 'display_name': 'Hao Zhu', 'orcid': 'https://orcid.org/0000-0003-1596-4366'}, 'institutions': [{'id': 'https://openalex.org/I2800935791', 'display_name': 'UC San Diego Health System', 'ror': 'https://ror.org/01kbfgm16', 'country_code': 'US', 'type': 'healthcare', 'lineage': ['https://openalex.org/I2800935791']}], 'countries': ['US'], 'is_corresponding': False, 'raw_author_name': 'Hao Zhu', 'raw_affiliation_strings': ['UC San Diego'], 'affiliations': [{'raw_affiliation_string': 'UC San Diego', 'institution_ids': ['https://openalex.org/I2800935791']}]}, {'author_position': 'middle', 'author': {'id': 'https://openalex.org/A5075643825', 'display_name': 'Fangchen Liu', 'orcid': 'https://orcid.org/0000-0002-8987-6396'}, 'institutions': [{'id': 'https://openalex.org/I2800935791', 'display_name': 'UC San Diego Health System', 'ror': 'https://ror.org/01kbfgm16', 'country_code': 'US', 'type': 'healthcare', 'lineage': ['https://openalex.org/I2800935791']}], 'countries': ['US'], 'is_corresponding': False, 'raw_author_name': 'Fangchen Liu', 'raw_affiliation_strings': ['UC San Diego'], 'affiliations': [{'raw_affiliation_string': 'UC San Diego', 'institution_ids': ['https://openalex.org/I2800935791']}]}, {'author_position': 'middle', 'author': {'id': 'https://openalex.org/A5058453644', 'display_name': 'Minghua Liu', 'orcid': 'https://orcid.org/0000-0002-6603-1251'}, 'institutions': [{'id': 'https://openalex.org/I2800935791', 'display_name': 'UC San Diego Health System', 'ror': 'https://ror.org/01kbfgm16', 'country_code': 'US', 'type': 'healthcare', 'lineage': ['https://openalex.org/I2800935791']}], 'countries': ['US'], 'is_corresponding': False, 'raw_author_name': 'Minghua Liu', 'raw_affiliation_strings': ['UC San Diego'], 'affiliations': [{'raw_affiliation_string': 'UC San Diego', 'institution_ids': ['https://openalex.org/I2800935791']}]}, {'author_position': 'middle', 'author': {'id': 'https://openalex.org/A5044737861', 'display_name': 'Hanxiao Jiang', 'orcid': 'https://orcid.org/0000-0001-6245-361X'}, 'institutions': [{'id': 'https://openalex.org/I18014758', 'display_name': 'Simon Fraser University', 'ror': 'https://ror.org/0213rcc28', 'country_code': 'CA', 'type': 'education', 'lineage': ['https://openalex.org/I18014758']}], 'countries': ['CA'], 'is_corresponding': False, 'raw_author_name': 'Hanxiao Jiang', 'raw_affiliation_strings': ['Simon Fraser University'], 'affiliations': [{'raw_affiliation_string': 'Simon Fraser University', 'institution_ids': ['https://openalex.org/I18014758']}]}, {'author_position': 'middle', 'author': {'id': 'https://openalex.org/A5049269697', 'display_name': 'Yifu Yuan', 'orcid': None}, 'institutions': [{'id': 'https://openalex.org/I4210139270', 'display_name': 'UtopiaCompression (United States)', 'ror': 'https://ror.org/051d4q284', 'country_code': 'US', 'type': 'company', 'lineage': ['https://openalex.org/I4210139270']}], 'countries': ['US'], 'is_corresponding': False, 'raw_author_name': 'Yifu Yuan', 'raw_affiliation_strings': ['UC Los Angeles'], 'affiliations': [{'raw_affiliation_string': 'UC Los Angeles', 'institution_ids': ['https://openalex.org/I4210139270']}]}, {'author_position': 'middle', 'author': {'id': 'https://openalex.org/A5100351699', 'display_name': 'He Wang', 'orcid': 'https://orcid.org/0000-0003-1679-0337'}, 'institutions': [{'id': 'https://openalex.org/I97018004', 'display_name': 'Stanford University', 'ror': 'https://ror.org/00f54p054', 'country_code': 'US', 'type': 'education', 'lineage': ['https://openalex.org/I97018004']}], 'countries': ['US'], 'is_corresponding': False, 'raw_author_name': 'He Wang', 'raw_affiliation_strings': ['Stanford University'], 'affiliations': [{'raw_affiliation_string': 'Stanford University', 'institution_ids': ['https://openalex.org/I97018004']}]}, {'author_position': 'middle', 'author': {'id': 'https://openalex.org/A5100421473', 'display_name': 'Yi Li', 'orcid': 'https://orcid.org/0000-0002-2856-7290'}, 'institutions': [{'id': 'https://openalex.org/I1291425158', 'display_name': 'Google (United States)', 'ror': 'https://ror.org/00njsd438', 'country_code': 'US', 'type': 'company', 'lineage': ['https://openalex.org/I1291425158', 'https://openalex.org/I4210128969']}], 'countries': ['US'], 'is_corresponding': False, 'raw_author_name': 'Li Yi', 'raw_affiliation_strings': ['Google Research'], 'affiliations': [{'raw_affiliation_string': 'Google Research', 'institution_ids': ['https://openalex.org/I1291425158']}]}, {'author_position': 'middle', 'author': {'id': 'https://openalex.org/A5044978994', 'display_name': 'Anne Lynn S. Chang', 'orcid': 'https://orcid.org/0000-0002-2869-2147'}, 'institutions': [{'id': 'https://openalex.org/I18014758', 'display_name': 'Simon Fraser University', 'ror': 'https://ror.org/0213rcc28', 'country_code': 'CA', 'type': 'education', 'lineage': ['https://openalex.org/I18014758']}], 'countries': ['CA'], 'is_corresponding': False, 'raw_author_name': 'Angel X. Chang', 'raw_affiliation_strings': ['Simon Fraser University'], 'affiliations': [{'raw_affiliation_string': 'Simon Fraser University', 'institution_ids': ['https://openalex.org/I18014758']}]}, {'author_position': 'middle', 'author': {'id': 'https://openalex.org/A5065368881', 'display_name': 'Leonidas Guibas', 'orcid': 'https://orcid.org/0000-0002-8315-4886'}, 'institutions': [{'id': 'https://openalex.org/I97018004', 'display_name': 'Stanford University', 'ror': 'https://ror.org/00f54p054', 'country_code': 'US', 'type': 'education', 'lineage': ['https://openalex.org/I97018004']}], 'countries': ['US'], 'is_corresponding': False, 'raw_author_name': 'Leonidas J. Guibas', 'raw_affiliation_strings': ['Stanford University'], 'affiliations': [{'raw_affiliation_string': 'Stanford University', 'institution_ids': ['https://openalex.org/I97018004']}]}, {'author_position': 'last', 'author': {'id': 'https://openalex.org/A5091622325', 'display_name': 'Hao Su', 'orcid': 'https://orcid.org/0000-0002-9686-6540'}, 'institutions': [{'id': 'https://openalex.org/I2800935791', 'display_name': 'UC San Diego Health System', 'ror': 'https://ror.org/01kbfgm16', 'country_code': 'US', 'type': 'healthcare', 'lineage': ['https://openalex.org/I2800935791']}], 'countries': ['US'], 'is_corresponding': False, 'raw_author_name': 'Hao Su', 'raw_affiliation_strings': ['UC San Diego'], 'affiliations': [{'raw_affiliation_string': 'UC San Diego', 'institution_ids': ['https://openalex.org/I2800935791']}]}] | J3: 2 | K3: 14 | L3: 20.258692 | M3: FALSE | N3: 353 | O3: {'volume': None, 'issue': None, 'first_page': '11094', 'last_page': '11104'} | P3: {'id': 'https://openalex.org/T11714', 'display_name': 'Multimodal Machine Learning Applications', 'score': 0.9997000098228455, 'subfield': {'id': 'https://openalex.org/subfields/1707', 'display_name': 'Computer Vision and Pattern Recognition'}, 'field': {'id': 'https://openalex.org/fields/17', 'display_name': 'Computer Science'}, 'domain': {'id': 'https://openalex.org/domains/3', 'display_name': 'Physical Sciences'}} | Q3: [{'id': 'https://openalex.org/T11714', 'display_name': 'Multimodal Machine Learning Applications', 'score': 0.9997000098228455, 'subfield': {'id': 'https://openalex.org/subfields/1707', 'display_name': 'Computer Vision and Pattern Recognition'}, 'field': {'id': 'https://openalex.org/fields/17', 'display_name': 'Computer Science'}, 'domain': {'id': 'https://openalex.org/domains/3', 'display_name': 'Physical Sciences'}}, {'id': 'https://openalex.org/T10653', 'display_name': 'Robot Manipulation and Learning', 'score': 0.9994999766349792, 'subfield': {'id': 'https://openalex.org/subfields/2207', 'display_name': 'Control and Systems Engineering'}, 'field': {'id': 'https://openalex.org/fields/22', 'display_name': 'Engineering'}, 'domain': {'id': 'https://openalex.org/domains/3', 'display_name': 'Physical Sciences'}}, {'id': 'https://openalex.org/T10586', 'display_name': 'Robotic Path Planning Algorithms', 'score': 0.9990000128746033, 'subfield': {'id': 'https://openalex.org/subfields/1707', 'display_name': 'Computer Vision and Pattern Recognition'}, 'field': {'id': 'https://openalex.org/fields/17', 'display_name': 'Computer Science'}, 'domain': {'id': 'https://openalex.org/domains/3', 'display_name': 'Physical Sciences'}}] | R3: [{'id': 'https://openalex.org/keywords/robotics', 'display_name': 'Robotics', 'score': 0.7897522449493408}, {'id': 'https://openalex.org/keywords/artificial-intelligence', 'display_name': 'Artificial intelligence', 'score': 0.6961296200752258}, {'id': 'https://openalex.org/keywords/robot', 'display_name': 'Robot', 'score': 0.6861521601676941}, {'id': 'https://openalex.org/keywords/computer-science', 'display_name': 'Computer science', 'score': 0.658255934715271}, {'id': 'https://openalex.org/keywords/reinforcement-learning', 'display_name': 'Reinforcement learning', 'score': 0.6101622581481934}, {'id': 'https://openalex.org/keywords/humanâ€“computer-interaction', 'display_name': 'Humanâ€“computer interaction', 'score': 0.590071439743042}, {'id': 'https://openalex.org/keywords/task', 'display_name': 'Task (project management)', 'score': 0.5621821284294128}, {'id': 'https://openalex.org/keywords/motion', 'display_name': 'Motion (physics)', 'score': 0.5154355764389038}, {'id': 'https://openalex.org/keywords/set', 'display_name': 'Set (abstract data type)', 'score': 0.49389272928237915}, {'id': 'https://openalex.org/keywords/heuristic', 'display_name': 'Heuristic', 'score': 0.4710685610771179}, {'id': 'https://openalex.org/keywords/focus', 'display_name': 'Focus (optics)', 'score': 0.43487516045570374}, {'id': 'https://openalex.org/keywords/machine-learning', 'display_name': 'Machine learning', 'score': 0.3394186794757843}, {'id': 'https://openalex.org/keywords/engineering', 'display_name': 'Engineering', 'score': 0.19693204760551453}, {'id': 'https://openalex.org/keywords/systems-engineering', 'display_name': 'Systems engineering', 'score': 0.10156914591789246}] | S3: [{'id': 'https://openalex.org/C34413123', 'wikidata': 'https://www.wikidata.org/wiki/Q170978', 'display_name': 'Robotics', 'level': 3, 'score': 0.7897522449493408}, {'id': 'https://openalex.org/C154945302', 'wikidata': 'https://www.wikidata.org/wiki/Q11660', 'display_name': 'Artificial intelligence', 'level': 1, 'score': 0.6961296200752258}, {'id': 'https://openalex.org/C90509273', 'wikidata': 'https://www.wikidata.org/wiki/Q11012', 'display_name': 'Robot', 'level': 2, 'score': 0.6861521601676941}, {'id': 'https://openalex.org/C41008148', 'wikidata': 'https://www.wikidata.org/wiki/Q21198', 'display_name': 'Computer science', 'level': 0, 'score': 0.658255934715271}, {'id': 'https://openalex.org/C97541855', 'wikidata': 'https://www.wikidata.org/wiki/Q830687', 'display_name': 'Reinforcement learning', 'level': 2, 'score': 0.6101622581481934}, {'id': 'https://openalex.org/C107457646', 'wikidata': 'https://www.wikidata.org/wiki/Q207434', 'display_name': 'Humanâ€“computer interaction', 'level': 1, 'score': 0.590071439743042}, {'id': 'https://openalex.org/C2780451532', 'wikidata': 'https://www.wikidata.org/wiki/Q759676', 'display_name': 'Task (project management)', 'level': 2, 'score': 0.5621821284294128}, {'id': 'https://openalex.org/C104114177', 'wikidata': 'https://www.wikidata.org/wiki/Q79782', 'display_name': 'Motion (physics)', 'level': 2, 'score': 0.5154355764389038}, {'id': 'https://openalex.org/C177264268', 'wikidata': 'https://www.wikidata.org/wiki/Q1514741', 'display_name': 'Set (abstract data type)', 'level': 2, 'score': 0.49389272928237915}, {'id': 'https://openalex.org/C173801870', 'wikidata': 'https://www.wikidata.org/wiki/Q201413', 'display_name': 'Heuristic', 'level': 2, 'score': 0.4710685610771179}, {'id': 'https://openalex.org/C192209626', 'wikidata': 'https://www.wikidata.org/wiki/Q190909', 'display_name': 'Focus (optics)', 'level': 2, 'score': 0.43487516045570374}, {'id': 'https://openalex.org/C119857082', 'wikidata': 'https://www.wikidata.org/wiki/Q2539', 'display_name': 'Machine learning', 'level': 1, 'score': 0.3394186794757843}, {'id': 'https://openalex.org/C127413603', 'wikidata': 'https://www.wikidata.org/wiki/Q11023', 'display_name': 'Engineering', 'level': 0, 'score': 0.19693204760551453}, {'id': 'https://openalex.org/C201995342', 'wikidata': 'https://www.wikidata.org/wiki/Q682496', 'display_name': 'Systems engineering', 'level': 1, 'score': 0.10156914591789246}, {'id': 'https://openalex.org/C120665830', 'wikidata': 'https://www.wikidata.org/wiki/Q14620', 'display_name': 'Optics', 'level': 1, 'score': 0.0}, {'id': 'https://openalex.org/C199360897', 'wikidata': 'https://www.wikidata.org/wiki/Q9143', 'display_name': 'Programming language', 'level': 1, 'score': 0.0}, {'id': 'https://openalex.org/C121332964', 'wikidata': 'https://www.wikidata.org/wiki/Q413', 'display_name': 'Physics', 'level': 0, 'score': 0.0}] | T3: [] | U3: 82
A4: https://openalex.org/W3108888189 | B4: https://doi.org/10.1175/jcli-d-19-1013.1 | C4: Changes in Annual Extremes of Daily Temperature and Precipitation in CMIP6 Models | D4: 2020 | E4: 44166 | F4: en | G4: article | H4: {'is_oa': True, 'oa_status': 'hybrid', 'oa_url': 'https://journals.ametsoc.org/downloadpdf/journals/clim/34/9/JCLI-D-19-1013.1.pdf', 'any_repository_has_fulltext': True} | I4: [{'author_position': 'first', 'author': {'id': 'https://openalex.org/A5100323109', 'display_name': 'Chao Li', 'orcid': 'https://orcid.org/0000-0001-6863-9271'}, 'institutions': [{'id': 'https://openalex.org/I200845125', 'display_name': 'Nanjing University of Information Science and Technology', 'ror': 'https://ror.org/02y0rxk19', 'country_code': 'CN', 'type': 'education', 'lineage': ['https://openalex.org/I200845125']}, {'id': 'https://openalex.org/I66867065', 'display_name': 'East China Normal University', 'ror': 'https://ror.org/02n96ep67', 'country_code': 'CN', 'type': 'education', 'lineage': ['https://openalex.org/I66867065']}], 'countries': ['CN'], 'is_corresponding': True, 'raw_author_name': 'Chao Li', 'raw_affiliation_strings': ['a Key Laboratory of Geographic Information Science, Ministry of Education, East China Normal University, Shanghai, China', 'b School of Geographic Sciences, East China Normal University, Shanghai, China', 'd Nanjing University of Information Science and Technology, Nanjing, China', 'Nanjing University of Information Science and Technology, Nanjing, China', 'Key Laboratory of Geographic Information Science, Ministry of Education, East China Normal University, Shanghai, China', 'School of Geographic Sciences, East China Normal University, Shanghai, China'], 'affiliations': [{'raw_affiliation_string': 'a Key Laboratory of Geographic Information Science, Ministry of Education, East China Normal University, Shanghai, China', 'institution_ids': ['https://openalex.org/I66867065']}, {'raw_affiliation_string': 'b School of Geographic Sciences, East China Normal University, Shanghai, China', 'institution_ids': ['https://openalex.org/I66867065']}, {'raw_affiliation_string': 'd Nanjing University of Information Science and Technology, Nanjing, China', 'institution_ids': ['https://openalex.org/I200845125']}, {'raw_affiliation_string': 'Nanjing University of Information Science and Technology, Nanjing, China', 'institution_ids': ['https://openalex.org/I200845125']}, {'raw_affiliation_string': 'Key Laboratory of Geographic Information Science, Ministry of Education, East China Normal University, Shanghai, China', 'institution_ids': ['https://openalex.org/I66867065']}, {'raw_affiliation_string': 'School of Geographic Sciences, East China Normal University, Shanghai, China', 'institution_ids': ['https://openalex.org/I66867065']}]}, {'author_position': 'middle', 'author': {'id': 'https://openalex.org/A5062528804', 'display_name': 'Francis W. Zwiers', 'orcid': 'https://orcid.org/0000-0002-8375-5147'}, 'institutions': [{'id': 'https://openalex.org/I4210094865', 'display_name': 'Pacific Institute for Climate Solutions', 'ror': 'https://ror.org/00hv6g197', 'country_code': 'CA', 'type': 'facility', 'lineage': ['https://openalex.org/I141945490', 'https://openalex.org/I151934421', 'https://openalex.org/I18014758', 'https://openalex.org/I212119943', 'https://openalex.org/I4210094865']}, {'id': 'https://openalex.org/I200845125', 'display_name': 'Nanjing University of Information Science and Technology', 'ror': 'https://ror.org/02y0rxk19', 'country_code': 'CN', 'type': 'education', 'lineage': ['https://openalex.org/I200845125']}, {'id': 'https://openalex.org/I212119943', 'display_name': 'University of Victoria', 'ror': 'https://ror.org/04s5mat29', 'country_code': 'CA', 'type': 'education', 'lineage': ['https://openalex.org/I212119943']}], 'countries': ['CA', 'CN'], 'is_corresponding': False, 'raw_author_name': 'Francis Zwiers', 'raw_affiliation_strings': ['c Pacific Climate Impacts Consortium, University of Victoria, Victoria, British Columbia, Canada', 'd Nanjing University of Information Science and Technology, Nanjing, China', 'Nanjing University of Information Science and Technology, Nanjing, China', 'Pacific Climate Impacts Consortium, University of Victoria, Victoria, British Columbia, Canada'], 'affiliations': [{'raw_affiliation_string': 'c Pacific Climate Impacts Consortium, University of Victoria, Victoria, British Columbia, Canada', 'institution_ids': ['https://openalex.org/I4210094865', 'https://openalex.org/I212119943']}, {'raw_affiliation_string': 'd Nanjing University of Information Science and Technology, Nanjing, China', 'institution_ids': ['https://openalex.org/I200845125']}, {'raw_affiliation_string': 'Nanjing University of Information Science and Technology, Nanjing, China', 'institution_ids': ['https://openalex.org/I200845125']}, {'raw_affiliation_string': 'Pacific Climate Impacts Consortium, University of Victoria, Victoria, British Columbia, Canada', 'institution_ids': ['https://openalex.org/I4210094865', 'https://openalex.org/I212119943']}]}, {'author_position': 'middle', 'author': {'id': 'https://openalex.org/A5100387443', 'display_name': 'Xuebin Zhang', 'orcid': 'https://orcid.org/0000-0002-6551-6249'}, 'institutions': [{'id': 'https://openalex.org/I1342547582', 'display_name': 'Environment and Climate Change Canada', 'ror': 'https://ror.org/026ny0e17', 'country_code': 'CA', 'type': 'government', 'lineage': ['https://openalex.org/I1342547582', 'https://openalex.org/I2802286613']}], 'countries': ['CA'], 'is_corresponding': False, 'raw_author_name': 'Xuebin Zhang', 'raw_affiliation_strings': ['e Climate Research Division, Environment and Climate Change Canada, Toronto, Ontario, Canada', 'Climate Research Division, Environment and Climate Change Canada, Toronto, Ontario, Canada'], 'affiliations': [{'raw_affiliation_string': 'e Climate Research Division, Environment and Climate Change Canada, Toronto, Ontario, Canada', 'institution_ids': ['https://openalex.org/I1342547582']}, {'raw_affiliation_string': 'Climate Research Division, Environment and Climate Change Canada, Toronto, Ontario, Canada', 'institution_ids': ['https://openalex.org/I1342547582']}]}, {'author_position': 'middle', 'author': {'id': 'https://openalex.org/A5046034025', 'display_name': 'Guilong Li', 'orcid': 'https://orcid.org/0000-0003-3125-4567'}, 'institutions': [{'id': 'https://openalex.org/I1342547582', 'display_name': 'Environment and Climate Change Canada', 'ror': 'https://ror.org/026ny0e17', 'country_code': 'CA', 'type': 'government', 'lineage': ['https://openalex.org/I1342547582', 'https://openalex.org/I2802286613']}], 'countries': ['CA'], 'is_corresponding': False, 'raw_author_name': 'Guilong Li', 'raw_affiliation_strings': ['e Climate Research Division, Environment and Climate Change Canada, Toronto, Ontario, Canada', 'Climate Research Division, Environment and Climate Change Canada, Toronto, Ontario, Canada'], 'affiliations': [{'raw_affiliation_string': 'e Climate Research Division, Environment and Climate Change Canada, Toronto, Ontario, Canada', 'institution_ids': ['https://openalex.org/I1342547582']}, {'raw_affiliation_string': 'Climate Research Division, Environment and Climate Change Canada, Toronto, Ontario, Canada', 'institution_ids': ['https://openalex.org/I1342547582']}]}, {'author_position': 'middle', 'author': {'id': 'https://openalex.org/A5101472843', 'display_name': 'Ying Sun', 'orcid': 'https://orcid.org/0000-0003-2335-3485'}, 'institutions': [{'id': 'https://openalex.org/I141301092', 'display_name': 'China Meteorological Administration', 'ror': 'https://ror.org/00bx3rb98', 'country_code': 'CN', 'type': 'government', 'lineage': ['https://openalex.org/I141301092']}], 'countries': ['CN'], 'is_corresponding': False, 'raw_author_name': 'Ying Sun', 'raw_affiliation_strings': ['f Laboratory for Climate Studies, National Climate Center, China Meteorological Administration, Beijing, China', 'Laboratory for Climate Studies, National Climate Center, China Meteorological Administration, Beijing, China'], 'affiliations': [{'raw_affiliation_string': 'f Laboratory for Climate Studies, National Climate Center, China Meteorological Administration, Beijing, China', 'institution_ids': ['https://openalex.org/I141301092']}, {'raw_affiliation_string': 'Laboratory for Climate Studies, National Climate Center, China Meteorological Administration, Beijing, China', 'institution_ids': ['https://openalex.org/I141301092']}]}, {'author_position': 'last', 'author': {'id': 'https://openalex.org/A5029017675', 'display_name': 'Michael Wehner', 'orcid': 'https://orcid.org/0000-0001-5991-0082'}, 'institutions': [{'id': 'https://openalex.org/I2800337505', 'display_name': 'Bexley Hall', 'ror': 'https://ror.org/05v69pw95', 'country_code': 'US', 'type': 'education', 'lineage': ['https://openalex.org/I2800337505']}], 'countries': ['US'], 'is_corresponding': False, 'raw_author_name': 'Michael Wehner', 'raw_affiliation_strings': ['g Computational Research Division, Lawrence Berkley National Laboratory, Berkley, California', 'Computational Research Division, Lawrence Berkley National Laboratory, Berkley, California'], 'affiliations': [{'raw_affiliation_string': 'g Computational Research Division, Lawrence Berkley National Laboratory, Berkley, California', 'institution_ids': ['https://openalex.org/I2800337505']}, {'raw_affiliation_string': 'Computational Research Division, Lawrence Berkley National Laboratory, Berkley, California', 'institution_ids': []}]}] | J4: 3 | K4: 6 | L4: 16.6184 | M4: TRUE | N4: 329 | O4: {'volume': '34', 'issue': '9', 'first_page': '3441', 'last_page': '3460'} | P4: {'id': 'https://openalex.org/T10029', 'display_name': 'Climate variability and models', 'score': 0.9998999834060669, 'subfield': {'id': 'https://openalex.org/subfields/2306', 'display_name': 'Global and Planetary Change'}, 'field': {'id': 'https://openalex.org/fields/23', 'display_name': 'Environmental Science'}, 'domain': {'id': 'https://openalex.org/domains/3', 'display_name': 'Physical Sciences'}} | Q4: [{'id': 'https://openalex.org/T10029', 'display_name': 'Climate variability and models', 'score': 0.9998999834060669, 'subfield': {'id': 'https://openalex.org/subfields/2306', 'display_name': 'Global and Planetary Change'}, 'field': {'id': 'https://openalex.org/fields/23', 'display_name': 'Environmental Science'}, 'domain': {'id': 'https://openalex.org/domains/3', 'display_name': 'Physical Sciences'}}, {'id': 'https://openalex.org/T11588', 'display_name': 'Atmospheric and Environmental Gas Dynamics', 'score': 0.9975000023841858, 'subfield': {'id': 'https://openalex.org/subfields/2306', 'display_name': 'Global and Planetary Change'}, 'field': {'id': 'https://openalex.org/fields/23', 'display_name': 'Environmental Science'}, 'domain': {'id': 'https://openalex.org/domains/3', 'display_name': 'Physical Sciences'}}, {'id': 'https://openalex.org/T10466', 'display_name': 'Meteorological Phenomena and Simulations', 'score': 0.996999979019165, 'subfield': {'id': 'https://openalex.org/subfields/1902', 'display_name': 'Atmospheric Science'}, 'field': {'id': 'https://openalex.org/fields/19', 'display_name': 'Earth and Planetary Sciences'}, 'domain': {'id': 'https://openalex.org/domains/3', 'display_name': 'Physical Sciences'}}] | R4: [{'id': 'https://openalex.org/keywords/precipitation', 'display_name': 'Precipitation', 'score': 0.8168666362762451}, {'id': 'https://openalex.org/keywords/coupled-model-intercomparison-project', 'display_name': 'Coupled model intercomparison project', 'score': 0.8089784383773804}, {'id': 'https://openalex.org/keywords/environmental-science', 'display_name': 'Environmental science', 'score': 0.7747020721435547}, {'id': 'https://openalex.org/keywords/climatology', 'display_name': 'Climatology', 'score': 0.7484180331230164}, {'id': 'https://openalex.org/keywords/pooling', 'display_name': 'Pooling', 'score': 0.5613932609558105}, {'id': 'https://openalex.org/keywords/forcing', 'display_name': 'Forcing (mathematics)', 'score': 0.4951871931552887}, {'id': 'https://openalex.org/keywords/climate-model', 'display_name': 'Climate model', 'score': 0.47099965810775757}, {'id': 'https://openalex.org/keywords/surface-air-temperature', 'display_name': 'Surface air temperature', 'score': 0.43429940938949585}, {'id': 'https://openalex.org/keywords/mean-radiant-temperature', 'display_name': 'Mean radiant temperature', 'score': 0.4107043445110321}, {'id': 'https://openalex.org/keywords/atmospheric-sciences', 'display_name': 'Atmospheric sciences', 'score': 0.3687288761138916}, {'id': 'https://openalex.org/keywords/climate-change', 'display_name': 'Climate change', 'score': 0.36225682497024536}, {'id': 'https://openalex.org/keywords/meteorology', 'display_name': 'Meteorology', 'score': 0.28965359926223755}, {'id': 'https://openalex.org/keywords/computer-science', 'display_name': 'Computer science', 'score': 0.13357016444206238}, {'id': 'https://openalex.org/keywords/geology', 'display_name': 'Geology', 'score': 0.10647240281105042}, {'id': 'https://openalex.org/keywords/geography', 'display_name': 'Geography', 'score': 0.07832589745521545}] | S4: [{'id': 'https://openalex.org/C107054158', 'wikidata': 'https://www.wikidata.org/wiki/Q25257', 'display_name': 'Precipitation', 'level': 2, 'score': 0.8168666362762451}, {'id': 'https://openalex.org/C25022447', 'wikidata': 'https://www.wikidata.org/wiki/Q5178021', 'display_name': 'Coupled model intercomparison project', 'level': 4, 'score': 0.8089784383773804}, {'id': 'https://openalex.org/C39432304', 'wikidata': 'https://www.wikidata.org/wiki/Q188847', 'display_name': 'Environmental science', 'level': 0, 'score': 0.7747020721435547}, {'id': 'https://openalex.org/C49204034', 'wikidata': 'https://www.wikidata.org/wiki/Q52139', 'display_name': 'Climatology', 'level': 1, 'score': 0.7484180331230164}, {'id': 'https://openalex.org/C70437156', 'wikidata': 'https://www.wikidata.org/wiki/Q7228652', 'display_name': 'Pooling', 'level': 2, 'score': 0.5613932609558105}, {'id': 'https://openalex.org/C197115733', 'wikidata': 'https://www.wikidata.org/wiki/Q1003136', 'display_name': 'Forcing (mathematics)', 'level': 2, 'score': 0.4951871931552887}, {'id': 'https://openalex.org/C168754636', 'wikidata': 'https://www.wikidata.org/wiki/Q620920', 'display_name': 'Climate model', 'level': 3, 'score': 0.47099965810775757}, {'id': 'https://openalex.org/C2994323764', 'wikidata': 'https://www.wikidata.org/wiki/Q909741', 'display_name': 'Surface air temperature', 'level': 3, 'score': 0.43429940938949585}, {'id': 'https://openalex.org/C42683663', 'wikidata': 'https://www.wikidata.org/wiki/Q3517834', 'display_name': 'Mean radiant temperature', 'level': 3, 'score': 0.4107043445110321}, {'id': 'https://openalex.org/C91586092', 'wikidata': 'https://www.wikidata.org/wiki/Q757520', 'display_name': 'Atmospheric sciences', 'level': 1, 'score': 0.3687288761138916}, {'id': 'https://openalex.org/C132651083', 'wikidata': 'https://www.wikidata.org/wiki/Q7942', 'display_name': 'Climate change', 'level': 2, 'score': 0.36225682497024536}, {'id': 'https://openalex.org/C153294291', 'wikidata': 'https://www.wikidata.org/wiki/Q25261', 'display_name': 'Meteorology', 'level': 1, 'score': 0.28965359926223755}, {'id': 'https://openalex.org/C41008148', 'wikidata': 'https://www.wikidata.org/wiki/Q21198', 'display_name': 'Computer science', 'level': 0, 'score': 0.13357016444206238}, {'id': 'https://openalex.org/C127313418', 'wikidata': 'https://www.wikidata.org/wiki/Q1069', 'display_name': 'Geology', 'level': 0, 'score': 0.10647240281105042}, {'id': 'https://openalex.org/C205649164', 'wikidata': 'https://www.wikidata.org/wiki/Q1071', 'display_name': 'Geography', 'level': 0, 'score': 0.07832589745521545}, {'id': 'https://openalex.org/C111368507', 'wikidata': 'https://www.wikidata.org/wiki/Q43518', 'display_name': 'Oceanography', 'level': 1, 'score': 0.0}, {'id': 'https://openalex.org/C154945302', 'wikidata': 'https://www.wikidata.org/wiki/Q11660', 'display_name': 'Artificial intelligence', 'level': 1, 'score': 0.0}] | T4: [{'display_name': 'Climate action', 'id': 'https://metadata.un.org/sdg/13', 'score': 0.8299999833106995}] | U4: 60
