Workbook

Sheet query2
A1: id | B1: doi | C1: title | D1: publication_year | E1: publication_date | F1: ids | G1: language | H1: type | I1: countries_distinct_count | J1: institutions_distinct_count | K1: fwci | L1: has_fulltext | M1: cited_by_count | N1: citation_normalized_percentile | O1: cited_by_percentile_year | P1: biblio | Q1: sustainable_development_goals | R1: counts_by_year
A2: https://openalex.org/W3128206428 | B2: https://doi.org/10.1038/s41467-021-21219-y | C2: Functional and versatile superhydrophobic coatings via stoichiometric silanization | D2: 2021 | E2: 44239 | F2: {'openalex': 'https://openalex.org/W3128206428', 'doi': 'https://doi.org/10.1038/s41467-021-21219-y', 'mag': '3128206428', 'pmid': 'https://pubmed.ncbi.nlm.nih.gov/33579959'} | G2: en | H2: article | I2: 1 | J2: 5 | K2: 20.071 | L2: TRUE | M2: 294 | N2: {'value': 0.99853177, 'is_in_top_1_percent': True, 'is_in_top_10_percent': True} | O2: {'min': 99, 'max': 100} | P2: {'volume': '12', 'issue': '1', 'first_page': '982', 'last_page': '982'} | Q2: [{'display_name': 'Industry, innovation and infrastructure', 'score': 0.46000000834465027, 'id': 'https://metadata.un.org/sdg/9'}] | R2: [{'year': 2026, 'cited_by_count': 7}, {'year': 2025, 'cited_by_count': 65}, {'year': 2024, 'cited_by_count': 76}, {'year': 2023, 'cited_by_count': 69}, {'year': 2022, 'cited_by_count': 61}, {'year': 2021, 'cited_by_count': 16}]
A3: https://openalex.org/W3197182136 | B3: https://doi.org/10.1088/2631-8695/ac2353 | C3: A review of primary technologies of thin-film solar cells | D3: 2021 | E3: 44440 | F3: {'openalex': 'https://openalex.org/W3197182136', 'doi': 'https://doi.org/10.1088/2631-8695/ac2353', 'mag': '3197182136'} | G3: en | H3: review | I3: 2 | J3: 8 | K3: 8.8239 | L3: FALSE | M3: 124 | N3: {'value': 0.98505979, 'is_in_top_1_percent': False, 'is_in_top_10_percent': True} | O3: {'min': 93, 'max': 100} | P3: {'volume': '3', 'issue': '3', 'first_page': '032001', 'last_page': '032001'} | Q3: [{'score': 0.5099999904632568, 'display_name': 'Industry, innovation and infrastructure', 'id': 'https://metadata.un.org/sdg/9'}] | R3: [{'year': 2026, 'cited_by_count': 4}, {'year': 2025, 'cited_by_count': 32}, {'year': 2024, 'cited_by_count': 44}, {'year': 2023, 'cited_by_count': 24}, {'year': 2022, 'cited_by_count': 18}, {'year': 2021, 'cited_by_count': 2}]
A4: https://openalex.org/W3080210839 | B4: https://doi.org/10.1126/sciadv.aba5847 | C4: Phase transition enhanced superior elasticity in freestanding single-crystalline multiferroic BiFeO <sub>3</sub> membranes | D4: 2020 | E4: 44064 | F4: {'openalex': 'https://openalex.org/W3080210839', 'doi': 'https://doi.org/10.1126/sciadv.aba5847', 'mag': '3080210839', 'pmid': 'https://pubmed.ncbi.nlm.nih.gov/32937363'} | G4: en | H4: article | I4: 3 | J4: 21 | K4: 4.3853 | L4: FALSE | M4: 123 | N4: {'value': 0.9578073, 'is_in_top_1_percent': False, 'is_in_top_10_percent': True} | O4: {'min': 99, 'max': 100} | P4: {'volume': '6', 'issue': '34', 'first_page': None, 'last_page': None} | Q4: [] | R4: [{'year': 2026, 'cited_by_count': 4}, {'year': 2025, 'cited_by_count': 24}, {'year': 2024, 'cited_by_count': 29}, {'year': 2023, 'cited_by_count': 23}, {'year': 2022, 'cited_by_count': 31}, {'year': 2021, 'cited_by_count': 12}]
A5: https://openalex.org/W3097814634 | B5: https://doi.org/10.1038/s41598-020-75393-y | C5: Material properties and structure of natural graphite sheet | D5: 2020 | E5: 44133 | F5: {'openalex': 'https://openalex.org/W3097814634', 'doi': 'https://doi.org/10.1038/s41598-020-75393-y', 'mag': '3097814634', 'pmid': 'https://pubmed.ncbi.nlm.nih.gov/33122759'} | G5: en | H5: article | I5: 2 | J5: 4 | K5: 2.5592 | L5: TRUE | M5: 82 | N5: {'value': 0.90500596, 'is_in_top_1_percent': False, 'is_in_top_10_percent': True} | O5: {'min': 94, 'max': 100} | P5: {'volume': '10', 'issue': '1', 'first_page': '18672', 'last_page': '18672'} | Q5: [{'score': 0.5199999809265137, 'display_name': 'Affordable and clean energy', 'id': 'https://metadata.un.org/sdg/7'}] | R5: [{'year': 2026, 'cited_by_count': 2}, {'year': 2025, 'cited_by_count': 27}, {'year': 2024, 'cited_by_count': 21}, {'year': 2023, 'cited_by_count': 18}, {'year': 2022, 'cited_by_count': 8}, {'year': 2021, 'cited_by_count': 4}, {'year': 2020, 'cited_by_count': 2}]
A6: https://openalex.org/W4283015959 | B6: https://doi.org/10.1016/j.cossms.2022.101016 | C6: Recent progress in bismuth-based high Curie temperature piezo-/ferroelectric perovskites for electromechanical transduction applications | D6: 2022 | E6: 44728 | F6: {'openalex': 'https://openalex.org/W4283015959', 'doi': 'https://doi.org/10.1016/j.cossms.2022.101016'} | G6: en | H6: article | I6: 2 | J6: 13 | K6: 5.1836 | L6: FALSE | M6: 73 | N6: {'value': 0.9703689, 'is_in_top_1_percent': False, 'is_in_top_10_percent': True} | O6: {'min': 97, 'max': 100} | P6: {'volume': '26', 'issue': '5', 'first_page': '101016', 'last_page': '101016'} | Q6: [{'id': 'https://metadata.un.org/sdg/9', 'score': 0.4699999988079071, 'display_name': 'Industry, innovation and infrastructure'}] | R6: [{'year': 2026, 'cited_by_count': 3}, {'year': 2025, 'cited_by_count': 24}, {'year': 2024, 'cited_by_count': 25}, {'year': 2023, 'cited_by_count': 17}, {'year': 2022, 'cited_by_count': 4}]
A7: https://openalex.org/W3160146843 | B7: https://doi.org/10.1016/j.ensm.2021.05.011 | C7: Materials design and fundamental understanding of tellurium-based electrochemistry for rechargeable batteries | D7: 2021 | E7: 44330 | F7: {'openalex': 'https://openalex.org/W3160146843', 'doi': 'https://doi.org/10.1016/j.ensm.2021.05.011', 'mag': '3160146843'} | G7: en | H7: article | I7: 1 | J7: 4 | K7: 5.6152 | L7: FALSE | M7: 71 | N7: {'value': 0.96650302, 'is_in_top_1_percent': False, 'is_in_top_10_percent': True} | O7: {'min': 95, 'max': 100} | P7: {'volume': '40', 'issue': None, 'first_page': '166', 'last_page': '188'} | Q7: [{'score': 0.7900000214576721, 'display_name': 'Affordable and clean energy', 'id': 'https://metadata.un.org/sdg/7'}] | R7: [{'year': 2026, 'cited_by_count': 2}, {'year': 2025, 'cited_by_count': 13}, {'year': 2024, 'cited_by_count': 23}, {'year': 2023, 'cited_by_count': 19}, {'year': 2022, 'cited_by_count': 11}, {'year': 2021, 'cited_by_count': 3}]
A8: https://openalex.org/W4307815345 | B8: https://doi.org/10.1016/j.ijhydene.2022.10.080 | C8: The mechanism and sorption kinetic analysis of hydrogen storage at room temperature using acid functionalized carbon nanotubes | D8: 2022 | E8: 44863 | F8: {'openalex': 'https://openalex.org/W4307815345', 'doi': 'https://doi.org/10.1016/j.ijhydene.2022.10.080'} | G8: en | H8: article | I8: 2 | J8: 4 | K8: 5.0355 | L8: FALSE | M8: 69 | N8: {'value': 0.96913033, 'is_in_top_1_percent': False, 'is_in_top_10_percent': True} | O8: {'min': 89, 'max': 100} | P8: {'volume': '48', 'issue': '5', 'first_page': '1930', 'last_page': '1942'} | Q8: [] | R8: [{'year': 2026, 'cited_by_count': 1}, {'year': 2025, 'cited_by_count': 26}, {'year': 2024, 'cited_by_count': 27}, {'year': 2023, 'cited_by_count': 14}, {'year': 2022, 'cited_by_count': 1}]
A9: https://openalex.org/W4394770414 | B9: https://doi.org/10.1016/j.tips.2024.03.004 | C9: Direct in vivo CAR T cell engineering | D9: 2024 | E9: 45394 | F9: {'openalex': 'https://openalex.org/W4394770414', 'doi': 'https://doi.org/10.1016/j.tips.2024.03.004', 'pmid': 'https://pubmed.ncbi.nlm.nih.gov/38614815'} | G9: en | H9: article | I9: 1 | J9: 4 | K9: 20.5378 | L9: FALSE | M9: 68 | N9: {'value': 0.99619071, 'is_in_top_1_percent': True, 'is_in_top_10_percent': True} | O9: {'min': 99, 'max': 100} | P9: {'volume': '45', 'issue': '5', 'first_page': '406', 'last_page': '418'} | Q9: [{'id': 'https://metadata.un.org/sdg/3', 'score': 0.6100000143051147, 'display_name': 'Good health and well-being'}] | R9: [{'year': 2026, 'cited_by_count': 5}, {'year': 2025, 'cited_by_count': 49}, {'year': 2024, 'cited_by_count': 14}]
A10: https://openalex.org/W3083114603 | B10: https://doi.org/10.1007/s13204-020-01542-4 | C10: Scrutinizing the charge storage mechanism in SrO based composites for asymmetric supercapacitors by diffusion-controlled process | D10: 2020 | E10: 44078 | F10: {'openalex': 'https://openalex.org/W3083114603', 'doi': 'https://doi.org/10.1007/s13204-020-01542-4', 'mag': '3083114603'} | G10: en | H10: article | I10: 4 | J10: 7 | K10: 1.8604 | L10: FALSE | M10: 68 | N10: {'value': 0.85417147, 'is_in_top_1_percent': False, 'is_in_top_10_percent': False} | O10: {'min': 97, 'max': 100} | P10: {'volume': '10', 'issue': '11', 'first_page': '3999', 'last_page': '4011'} | Q10: [{'score': 0.4099999964237213, 'display_name': 'Industry, innovation and infrastructure', 'id': 'https://metadata.un.org/sdg/9'}] | R10: [{'year': 2026, 'cited_by_count': 2}, {'year': 2025, 'cited_by_count': 23}, {'year': 2024, 'cited_by_count': 15}, {'year': 2023, 'cited_by_count': 14}, {'year': 2022, 'cited_by_count': 9}, {'year': 2021, 'cited_by_count': 5}]
A11: https://openalex.org/W4311425960 | B11: https://doi.org/10.1016/j.addma.2022.103357 | C11: Review of transfer learning in modeling additive manufacturing processes | D11: 2022 | E11: 44907 | F11: {'openalex': 'https://openalex.org/W4311425960', 'doi': 'https://doi.org/10.1016/j.addma.2022.103357'} | G11: en | H11: article | I11: 1 | J11: 3 | K11: 8.3579 | L11: FALSE | M11: 67 | N11: {'value': 0.98037312, 'is_in_top_1_percent': False, 'is_in_top_10_percent': True} | O11: {'min': 98, 'max': 100} | P11: {'volume': '61', 'issue': None, 'first_page': '103357', 'last_page': '103357'} | Q11: [{'score': 0.550000011920929, 'display_name': 'Industry, innovation and infrastructure', 'id': 'https://metadata.un.org/sdg/9'}] | R11: [{'year': 2026, 'cited_by_count': 4}, {'year': 2025, 'cited_by_count': 24}, {'year': 2024, 'cited_by_count': 33}, {'year': 2023, 'cited_by_count': 6}]
A12: https://openalex.org/W3169143473 | B12: https://doi.org/10.1016/j.optmat.2021.111258 | C12: Performance analysis of several electron/hole transport layers in thin film MAPbI3-based perovskite solar cells: A simulation study | D12: 2021 | E12: 44356 | F12: {'openalex': 'https://openalex.org/W3169143473', 'doi': 'https://doi.org/10.1016/j.optmat.2021.111258', 'mag': '3169143473'} | G12: en | H12: article | I12: 2 | J12: 3 | K12: 3.71 | L12: FALSE | M12: 64 | N12: {'value': 0.93766708, 'is_in_top_1_percent': False, 'is_in_top_10_percent': True} | O12: {'min': 89, 'max': 100} | P12: {'volume': '118', 'issue': None, 'first_page': '111258', 'last_page': '111258'} | Q12: [{'score': 0.7099999785423279, 'display_name': 'Affordable and clean energy', 'id': 'https://metadata.un.org/sdg/7'}] | R12: [{'year': 2025, 'cited_by_count': 27}, {'year': 2024, 'cited_by_count': 20}, {'year': 2023, 'cited_by_count': 10}, {'year': 2022, 'cited_by_count': 6}, {'year': 2021, 'cited_by_count': 1}]
A13: https://openalex.org/W3139159936 | B13: https://doi.org/10.1016/j.ijhydene.2021.02.077 | C13: Optimizing electrochemical performance of sonochemically and hydrothermally synthesized cobalt phosphate for supercapattery devices | D13: 2021 | E13: 44265 | F13: {'openalex': 'https://openalex.org/W3139159936', 'doi': 'https://doi.org/10.1016/j.ijhydene.2021.02.077', 'mag': '3139159936'} | G13: en | H13: article | I13: 2 | J13: 5 | K13: 3.2506 | L13: FALSE | M13: 62 | N13: {'value': 0.93041065, 'is_in_top_1_percent': False, 'is_in_top_10_percent': True} | O13: {'min': 97, 'max': 100} | P13: {'volume': '46', 'issue': '29', 'first_page': '15807', 'last_page': '15819'} | Q13: [{'id': 'https://metadata.un.org/sdg/7', 'score': 0.8799999952316284, 'display_name': 'Affordable and clean energy'}] | R13: [{'year': 2026, 'cited_by_count': 1}, {'year': 2025, 'cited_by_count': 11}, {'year': 2024, 'cited_by_count': 12}, {'year': 2023, 'cited_by_count': 22}, {'year': 2022, 'cited_by_count': 6}, {'year': 2021, 'cited_by_count': 10}]
... A114: https://openalex.org/W4385202502 | B114: https://doi.org/10.1016/j.aquatox.2023.106640 | C114: rGO outperforms GO in generating oxidative stress and DNA strand breaks in zebrafish liver cells | D114: 2023 | E114: 45131 | F114: {'openalex': 'https://openalex.org/W4385202502', 'doi': 'https://doi.org/10.1016/j.aquatox.2023.106640', 'pmid': 'https://pubmed.ncbi.nlm.nih.gov/37595501'} | G114: en | H114: article | I114: 3 | J114: 10 | K114: 0.5632 | L114: FALSE | M114: 5 | N114: {'value': 0.6152184, 'is_in_top_1_percent': False, 'is_in_top_10_percent': False} | O114: {'min': 89, 'max': 97} | P114: {'volume': '262', 'issue': None, 'first_page': '106640', 'last_page': '106640'} | Q114: [{'score': 0.699999988079071, 'id': 'https://metadata.un.org/sdg/14', 'display_name': 'Life below water'}] | R114: [{'year': 2025, 'cited_by_count': 1}, {'year': 2024, 'cited_by_count': 3}, {'year': 2023, 'cited_by_count': 1}]
A115: https://openalex.org/W3008540537 | B115: https://doi.org/10.1101/2020.02.24.963421 | C115: Convergent evolution of niche structure in Northeast Pacific kelp forests | D115: 2020 | E115: 43887 | F115: {'openalex': 'https://openalex.org/W3008540537', 'doi': 'https://doi.org/10.1101/2020.02.24.963421', 'mag': '3008540537'} | G115: en | H115: preprint | I115: 1 | J115: 4 | L115: TRUE | M115: 5 | P115: {'volume': None, 'issue': None, 'first_page': None, 'last_page': None} | Q115: [{'score': 0.6800000071525574, 'id': 'https://metadata.un.org/sdg/15', 'display_name': 'Life in Land'}] | R115: [{'year': 2024, 'cited_by_count': 2}, {'year': 2023, 'cited_by_count': 1}, {'year': 2020, 'cited_by_count': 2}]
A116: https://openalex.org/W4367367779 | B116: https://doi.org/10.1002/aisy.202300015 | C116: A 3Dâ€Printed Computer | D116: 2023 | E116: 45045 | F116: {'openalex': 'https://openalex.org/W4367367779', 'doi': 'https://doi.org/10.1002/aisy.202300015'} | G116: en | H116: article | I116: 1 | J116: 2 | K116: 0.7006 | L116: TRUE | M116: 4 | N116: {'value': 0.74358744, 'is_in_top_1_percent': False, 'is_in_top_10_percent': False} | O116: {'min': 89, 'max': 96} | P116: {'volume': '5', 'issue': '8', 'first_page': None, 'last_page': None} | Q116: [] | R116: [{'year': 2025, 'cited_by_count': 1}, {'year': 2024, 'cited_by_count': 2}, {'year': 2023, 'cited_by_count': 1}]
A117: https://openalex.org/W4200423026 | B117: https://doi.org/10.1109/wifs53200.2021.9648379 | C117: 3D Print-Scan Resilient Localized Mesh Watermarking | D117: 2021 | E117: 44537 | F117: {'openalex': 'https://openalex.org/W4200423026', 'doi': 'https://doi.org/10.1109/wifs53200.2021.9648379'} | G117: en | H117: article | I117: 2 | J117: 4 | K117: 0.2882 | L117: FALSE | M117: 4 | N117: {'value': 0.57455882, 'is_in_top_1_percent': False, 'is_in_top_10_percent': False} | O117: {'min': 89, 'max': 96} | P117: {'volume': None, 'issue': None, 'first_page': '1', 'last_page': '6'} | Q117: [] | R117: [{'year': 2023, 'cited_by_count': 1}, {'year': 2022, 'cited_by_count': 2}, {'year': 2012, 'cited_by_count': 1}]
A118: https://openalex.org/W4385251277 | B118: https://doi.org/10.1103/physrevlett.131.049701 | C118: Comment on â€œAnisotropic Scattering Caused by Apical Oxygen Vacancies in Thin Films of Overdoped High-Temperature Cuprate Superconductorsâ€ | D118: 2023 | E118: 45132 | F118: {'openalex': 'https://openalex.org/W4385251277', 'doi': 'https://doi.org/10.1103/physrevlett.131.049701', 'pmid': 'https://pubmed.ncbi.nlm.nih.gov/37566842'} | G118: en | H118: article | I118: 3 | J118: 7 | K118: 0.7707 | L118: FALSE | M118: 4 | N118: {'value': 0.68151869, 'is_in_top_1_percent': False, 'is_in_top_10_percent': False} | O118: {'min': 90, 'max': 96} | P118: {'volume': '131', 'issue': '4', 'first_page': '049701', 'last_page': '049701'} | Q118: [] | R118: [{'year': 2025, 'cited_by_count': 1}, {'year': 2024, 'cited_by_count': 1}, {'year': 2023, 'cited_by_count': 2}]
A119: https://openalex.org/W3037279216 | B119: https://doi.org/10.1016/b978-0-12-818475-2.00002-7 | C119: Mechanical properties of two-dimensional materials: atomistic modeling and future directions | D119: 2020 | E119: 43831 | F119: {'openalex': 'https://openalex.org/W3037279216', 'doi': 'https://doi.org/10.1016/b978-0-12-818475-2.00002-7', 'mag': '3037279216'} | G119: en | H119: book-chapter | I119: 1 | J119: 3 | K119: 1.888 | L119: FALSE | M119: 4 | N119: {'value': 0.86023959, 'is_in_top_1_percent': False, 'is_in_top_10_percent': False} | O119: {'min': 89, 'max': 96} | P119: {'volume': None, 'issue': None, 'first_page': '9', 'last_page': '35'} | Q119: [{'score': 0.4699999988079071, 'display_name': 'Industry, innovation and infrastructure', 'id': 'https://metadata.un.org/sdg/9'}] | R119: [{'year': 2023, 'cited_by_count': 1}, {'year': 2022, 'cited_by_count': 2}, {'year': 2021, 'cited_by_count': 1}]
A120: https://openalex.org/W3173423777 | B120: https://doi.org/10.1016/j.nanoen.2021.106280 | C120: Self-powered integrated opto-electro-mechanical nano-actuators | D120: 2021 | E120: 44371 | F120: {'openalex': 'https://openalex.org/W3173423777', 'doi': 'https://doi.org/10.1016/j.nanoen.2021.106280', 'mag': '3173423777'} | G120: en | H120: article | I120: 1 | J120: 2 | K120: 0.601 | L120: FALSE | M120: 4 | N120: {'value': 0.67230664, 'is_in_top_1_percent': False, 'is_in_top_10_percent': False} | O120: {'min': 89, 'max': 97} | P120: {'volume': '88', 'issue': None, 'first_page': '106280', 'last_page': '106280'} | Q120: [{'display_name': 'Affordable and clean energy', 'id': 'https://metadata.un.org/sdg/7', 'score': 0.9100000262260437}] | R120: [{'year': 2022, 'cited_by_count': 3}, {'year': 2021, 'cited_by_count': 1}]
A121: https://openalex.org/W4394579167 | B121: https://doi.org/10.1007/s13233-024-00261-x | C121: Heat-resistant luminescent films: a thermal study of fluorene/thiophene copolymer-elastomer blends | D121: 2024 | E121: 45390 | F121: {'openalex': 'https://openalex.org/W4394579167', 'doi': 'https://doi.org/10.1007/s13233-024-00261-x'} | G121: en | H121: article | I121: 2 | J121: 5 | K121: 0.7167 | L121: FALSE | M121: 4 | N121: {'value': 0.61852671, 'is_in_top_1_percent': False, 'is_in_top_10_percent': False} | O121: {'min': 91, 'max': 99} | P121: {'volume': '32', 'issue': '8', 'first_page': '757', 'last_page': '766'} | Q121: [] | R121: [{'year': 2026, 'cited_by_count': 1}, {'year': 2025, 'cited_by_count': 1}, {'year': 2024, 'cited_by_count': 2}]
A122: https://openalex.org/W4387937498 | B122: https://doi.org/10.1002/batt.202300367 | C122: Preconditioning Operation of Membraneless Vanadium Micro Redox Flow Batteries | D122: 2023 | E122: 45224 | F122: {'openalex': 'https://openalex.org/W4387937498', 'doi': 'https://doi.org/10.1002/batt.202300367'} | G122: en | H122: article | I122: 2 | J122: 6 | K122: 0.5361 | L122: FALSE | M122: 4 | N122: {'value': 0.6564174, 'is_in_top_1_percent': False, 'is_in_top_10_percent': False} | O122: {'min': 91, 'max': 97} | P122: {'volume': '7', 'issue': '2', 'first_page': None, 'last_page': None} | Q122: [{'display_name': 'Affordable and clean energy', 'id': 'https://metadata.un.org/sdg/7', 'score': 0.5899999737739563}] | R122: [{'year': 2025, 'cited_by_count': 1}, {'year': 2024, 'cited_by_count': 3}]
A123: https://openalex.org/W3136656899 | B123: https://doi.org/10.1002/aisy.202100003 | C123: Soft Bionic Sensors and Actuators | D123: 2021 | E123: 44256 | F123: {'openalex': 'https://openalex.org/W3136656899', 'doi': 'https://doi.org/10.1002/aisy.202100003', 'mag': '3136656899'} | G123: en | H123: article | I123: 2 | J123: 2 | K123: 0.3342 | L123: TRUE | M123: 4 | N123: {'value': 0.51777992, 'is_in_top_1_percent': False, 'is_in_top_10_percent': False} | O123: {'min': 89, 'max': 97} | P123: {'volume': '3', 'issue': '3', 'first_page': None, 'last_page': None} | Q123: [{'id': 'https://metadata.un.org/sdg/9', 'score': 0.47999998927116394, 'display_name': 'Industry, innovation and infrastructure'}] | R123: [{'year': 2024, 'cited_by_count': 3}, {'year': 2023, 'cited_by_count': 1}]
A124: https://openalex.org/W4308507325 | B124: https://doi.org/10.1088/1748-0221/17/11/c11002 | C124: Pre-production results from ATLAS ITk Strip Sensors Quality Assurance Testchip | D124: 2022 | E124: 44866 | F124: {'openalex': 'https://openalex.org/W4308507325', 'doi': 'https://doi.org/10.1088/1748-0221/17/11/c11002'} | G124: en | H124: article | I124: 6 | J124: 31 | K124: 0.497 | L124: FALSE | M124: 4 | N124: {'value': 0.90668791, 'is_in_top_1_percent': False, 'is_in_top_10_percent': True} | O124: {'min': 90, 'max': 97} | P124: {'volume': '17', 'issue': '11', 'first_page': 'C11002', 'last_page': 'C11002'} | Q124: [{'id': 'https://metadata.un.org/sdg/9', 'score': 0.5199999809265137, 'display_name': 'Industry, innovation and infrastructure'}] | R124: [{'year': 2024, 'cited_by_count': 1}, {'year': 2023, 'cited_by_count': 3}]
A125: https://openalex.org/W4402221351 | B125: https://doi.org/10.1016/j.jallcom.2024.176341 | C125: Cutting-edge developments in perovskite solar cells: The role of dimensional and mixed-dimensional engineering | D125: 2024 | E125: 45539 | F125: {'openalex': 'https://openalex.org/W4402221351', 'doi': 'https://doi.org/10.1016/j.jallcom.2024.176341'} | G125: en | H125: article | I125: 5 | J125: 6 | K125: 0.9227 | L125: FALSE | M125: 4 | N125: {'value': 0.74642119, 'is_in_top_1_percent': False, 'is_in_top_10_percent': False} | O125: {'min': 90, 'max': 97} | P125: {'volume': '1006', 'issue': None, 'first_page': '176341', 'last_page': '176341'} | Q125: [] | R125: [{'year': 2025, 'cited_by_count': 3}, {'year': 2024, 'cited_by_count': 1}]
A126: https://openalex.org/W4400528642 | B126: https://doi.org/10.1021/acsami.4c01045 | C126: Electrostatic Correlations Lead to High Capacitance in Zwitterion-Containing Thin Films | D126: 2024 | E126: 45484 | F126: {'openalex': 'https://openalex.org/W4400528642', 'doi': 'https://doi.org/10.1021/acsami.4c01045', 'pmid': 'https://pubmed.ncbi.nlm.nih.gov/38990772'} | G126: en | H126: article | I126: 2 | J126: 5 | K126: 0.3572 | L126: FALSE | M126: 3 | N126: {'value': 0.47464376, 'is_in_top_1_percent': False, 'is_in_top_10_percent': False} | O126: {'min': 96, 'max': 97} | P126: {'volume': '16', 'issue': '29', 'first_page': '38290', 'last_page': '38299'} | Q126: [{'display_name': 'Affordable and clean energy', 'score': 0.5699999928474426, 'id': 'https://metadata.un.org/sdg/7'}] | R126: [{'year': 2025, 'cited_by_count': 3}]
A127: https://openalex.org/W4400601698 | B127: https://doi.org/10.1016/j.enconman.2024.118780 | C127: Stationary thin film microgroove-based sorber reactor for sorption heat transformers: Surface modification, sorption dynamics, and crystallization | D127: 2024 | E127: 45486 | F127: {'openalex': 'https://openalex.org/W4400601698', 'doi': 'https://doi.org/10.1016/j.enconman.2024.118780'} | G127: en | H127: article | I127: 1 | J127: 3 | K127: 0.7099 | L127: FALSE | M127: 3 | N127: {'value': 0.64717391, 'is_in_top_1_percent': False, 'is_in_top_10_percent': False} | O127: {'min': 90, 'max': 96} | P127: {'volume': '315', 'issue': None, 'first_page': '118780', 'last_page': '118780'} | Q127: [] | R127: [{'year': 2025, 'cited_by_count': 2}, {'year': 2024, 'cited_by_count': 1}]
... A133: https://openalex.org/W3011360285 | B133: https://doi.org/10.1080/00207543.2020.1735656 | C133: M/PH/C queue under a congestion-based staffing policy with applications in steel industryÂ operations | D133: 2020 | E133: 43901 | F133: {'openalex': 'https://openalex.org/W3011360285', 'doi': 'https://doi.org/10.1080/00207543.2020.1735656', 'mag': '3011360285'} | G133: en | H133: article | I133: 3 | J133: 3 | K133: 0.5085 | L133: FALSE | M133: 3 | N133: {'value': 0.69348537, 'is_in_top_1_percent': False, 'is_in_top_10_percent': False} | O133: {'min': 89, 'max': 94} | P133: {'volume': '59', 'issue': '5', 'first_page': '1319', 'last_page': '1330'} | Q133: [{'score': 0.6600000262260437, 'id': 'https://metadata.un.org/sdg/9', 'display_name': 'Industry, innovation and infrastructure'}] | R133: [{'year': 2024, 'cited_by_count': 1}, {'year': 2021, 'cited_by_count': 1}, {'year': 2020, 'cited_by_count': 1}]
A134: https://openalex.org/W4399390162 | B134: https://doi.org/10.20944/preprints202406.0404.v1 | C134: Physics-Informed Online Learning for Temperature Prediction in Metal AM | D134: 2024 | E134: 45449 | F134: {'openalex': 'https://openalex.org/W4399390162', 'doi': 'https://doi.org/10.20944/preprints202406.0404.v1'} | G134: en | H134: preprint | I134: 1 | J134: 4 | L134: FALSE | M134: 3 | P134: {'volume': None, 'issue': None, 'first_page': None, 'last_page': None} | Q134: [] | R134: [{'year': 2026, 'cited_by_count': 1}, {'year': 2025, 'cited_by_count': 2}]
A135: https://openalex.org/W4393072836 | B135: https://doi.org/10.1111/sjtg.12539 | C135: Guest Editorial: The social life of Chinese infrastructures in Southeast Asia | D135: 2024 | E135: 45373 | F135: {'openalex': 'https://openalex.org/W4393072836', 'doi': 'https://doi.org/10.1111/sjtg.12539'} | G135: en | H135: editorial | I135: 2 | J135: 2 | K135: 11.940961 | L135: FALSE | M135: 3 | N135: {'value': 0.9622204, 'is_in_top_1_percent': False, 'is_in_top_10_percent': True} | O135: {'min': 96, 'max': 97} | P135: {'volume': '45', 'issue': '2', 'first_page': '169', 'last_page': '180'} | Q135: [{'display_name': 'Industry, innovation and infrastructure', 'score': 0.5400000214576721, 'id': 'https://metadata.un.org/sdg/9'}]
A136: https://openalex.org/W4386214571 | B136: https://doi.org/10.1109/fleps57599.2023.10220223 | C136: A 3D Printed Wearable Electromyography Wristband | D136: 2023 | E136: 45116 | F136: {'openalex': 'https://openalex.org/W4386214571', 'doi': 'https://doi.org/10.1109/fleps57599.2023.10220223'} | G136: en | H136: article | I136: 1 | J136: 4 | K136: 0.2253 | L136: FALSE | M136: 2 | N136: {'value': 0.47881622, 'is_in_top_1_percent': False, 'is_in_top_10_percent': False} | O136: {'min': 90, 'max': 95} | P136: {'volume': None, 'issue': None, 'first_page': '1', 'last_page': '4'} | Q136: [] | R136: [{'year': 2025, 'cited_by_count': 1}, {'year': 2024, 'cited_by_count': 1}]
A137: https://openalex.org/W4404316322 | B137: https://doi.org/10.1115/detc2024-142944 | C137: Low-Cost Melt Pool Temperature Prediction Using Visible Light Camera and Machine Learning in Laser Hot-Wire Directed Energy Deposition | D137: 2024 | E137: 45529 | F137: {'openalex': 'https://openalex.org/W4404316322', 'doi': 'https://doi.org/10.1115/detc2024-142944'} | G137: en | H137: article | I137: 1 | J137: 4 | K137: 0.4733 | L137: FALSE | M137: 2 | N137: {'value': 0.60384992, 'is_in_top_1_percent': False, 'is_in_top_10_percent': False} | O137: {'min': 91, 'max': 99} | P137: {'volume': None, 'issue': None, 'first_page': None, 'last_page': None} | Q137: [{'display_name': 'Affordable and clean energy', 'score': 0.8399999737739563, 'id': 'https://metadata.un.org/sdg/7'}] | R137: [{'year': 2026, 'cited_by_count': 1}, {'year': 2025, 'cited_by_count': 1}]
A138: https://openalex.org/W4387698028 | B138: https://doi.org/10.1088/1361-6528/ad0410 | C138: Editorial: Focus on green nanomaterials for a sustainable internet of things | D138: 2023 | E138: 45216 | F138: {'openalex': 'https://openalex.org/W4387698028', 'doi': 'https://doi.org/10.1088/1361-6528/ad0410', 'pmid': 'https://pubmed.ncbi.nlm.nih.gov/37848022'} | G138: en | H138: editorial | I138: 4 | J138: 6 | K138: 0.29970634 | L138: FALSE | M138: 2 | N138: {'value': 0.43692553, 'is_in_top_1_percent': False, 'is_in_top_10_percent': False} | O138: {'min': 90, 'max': 95} | P138: {'volume': '35', 'issue': '4', 'first_page': '040201', 'last_page': '040201'} | Q138: [{'display_name': 'Responsible consumption and production', 'score': 0.4399999976158142, 'id': 'https://metadata.un.org/sdg/12'}] | R138: [{'year': 2025, 'cited_by_count': 1}, {'year': 2024, 'cited_by_count': 1}]
A139: https://openalex.org/W4389118116 | B139: https://doi.org/10.1021/acs.chas.3c00072 | C139: Signage to Indicate the Presence of Engineered Nanomaterials in the Workplace: Lessons from a Trial Study That Led to Implementation in a Worksite | D139: 2023 | E139: 45259 | F139: {'openalex': 'https://openalex.org/W4389118116', 'doi': 'https://doi.org/10.1021/acs.chas.3c00072'} | G139: en | H139: article | I139: 2 | J139: 3 | K139: 1.3505 | L139: FALSE | M139: 2 | N139: {'value': 0.8986711, 'is_in_top_1_percent': False, 'is_in_top_10_percent': False} | O139: {'min': 90, 'max': 95} | P139: {'volume': '31', 'issue': '1', 'first_page': '77', 'last_page': '84'} | Q139: [] | R139: [{'year': 2025, 'cited_by_count': 1}, {'year': 2024, 'cited_by_count': 1}]
A140: https://openalex.org/W4401723141 | B140: https://doi.org/10.1103/physrevapplied.22.024058 | C140: Antiferromagnetic coupling across nonmagnetic transition-metal films alloyed with ferromagnetic elements | D140: 2024 | E140: 45525 | F140: {'openalex': 'https://openalex.org/W4401723141', 'doi': 'https://doi.org/10.1103/physrevapplied.22.024058'} | G140: en | H140: article | I140: 3 | J140: 10 | K140: 0.736 | L140: FALSE | M140: 2 | N140: {'value': 0.69511739, 'is_in_top_1_percent': False, 'is_in_top_10_percent': False} | O140: {'min': 95, 'max': 96} | P140: {'volume': '22', 'issue': '2', 'first_page': None, 'last_page': None} | Q140: [] | R140: [{'year': 2025, 'cited_by_count': 2}]
A141: https://openalex.org/W4319996310 | B141: https://doi.org/10.1109/jflex.2023.3237991 | C141: Speed and Scalability of Ambipolar Deep-Subthreshold TFTs for Ultralow-Power Printed Electronics | D141: 2023 | E141: 44927 | F141: {'openalex': 'https://openalex.org/W4319996310', 'doi': 'https://doi.org/10.1109/jflex.2023.3237991'} | G141: en | H141: article | I141: 2 | J141: 4 | K141: 0.2678 | L141: FALSE | M141: 2 | N141: {'value': 0.50497858, 'is_in_top_1_percent': False, 'is_in_top_10_percent': False} | O141: {'min': 89, 'max': 95} | P141: {'volume': '2', 'issue': '1', 'first_page': '11', 'last_page': '17'} | Q141: [{'id': 'https://metadata.un.org/sdg/7', 'score': 0.8799999952316284, 'display_name': 'Affordable and clean energy'}] | R141: [{'year': 2025, 'cited_by_count': 1}, {'year': 2023, 'cited_by_count': 1}]
A142: https://openalex.org/W4323318307 | B142: https://doi.org/10.3390/bioengineering10030326 | C142: Detecting Safety Anomalies in pHRI Activities via Force Myography | D142: 2023 | E142: 44990 | F142: {'openalex': 'https://openalex.org/W4323318307', 'doi': 'https://doi.org/10.3390/bioengineering10030326', 'pmid': 'https://pubmed.ncbi.nlm.nih.gov/36978717'} | G142: en | H142: article | I142: 1 | J142: 2 | K142: 0.225 | L142: FALSE | M142: 2 | N142: {'value': 0.45254565, 'is_in_top_1_percent': False, 'is_in_top_10_percent': False} | O142: {'min': 89, 'max': 95} | P142: {'volume': '10', 'issue': '3', 'first_page': '326', 'last_page': '326'} | Q142: [] | R142: [{'year': 2025, 'cited_by_count': 1}, {'year': 2023, 'cited_by_count': 1}]
A143: https://openalex.org/W4322731223 | B143: https://doi.org/10.1109/mems49605.2023.10052235 | C143: Modified Beam Structures for Improved Resonant Sensing | D143: 2023 | E143: 44941 | F143: {'openalex': 'https://openalex.org/W4322731223', 'doi': 'https://doi.org/10.1109/mems49605.2023.10052235'} | G143: en | H143: article | I143: 1 | J143: 2 | K143: 0.2836 | L143: FALSE | M143: 2 | N143: {'value': 0.51571983, 'is_in_top_1_percent': False, 'is_in_top_10_percent': False} | O143: {'min': 89, 'max': 94} | P143: {'volume': None, 'issue': None, 'first_page': '779', 'last_page': '782'} | Q143: [{'id': 'https://metadata.un.org/sdg/7', 'score': 0.5099999904632568, 'display_name': 'Affordable and clean energy'}] | R143: [{'year': 2024, 'cited_by_count': 1}, {'year': 2023, 'cited_by_count': 1}]
A144: https://openalex.org/W4391638944 | B144: https://doi.org/10.1149/ma2023-02371770mtgabs | C144: Measuring Thermal Conductivity of Single Thickness Fibrous Gas Diffusion Layers Using Transient Plane Source Method | D144: 2023 | E144: 45282 | F144: {'openalex': 'https://openalex.org/W4391638944', 'doi': 'https://doi.org/10.1149/ma2023-02371770mtgabs'} | G144: en | H144: article | I144: 1 | J144: 5 | K144: 0.4331 | L144: FALSE | M144: 2 | N144: {'value': 0.58864057, 'is_in_top_1_percent': False, 'is_in_top_10_percent': False} | O144: {'min': 95, 'max': 96} | P144: {'volume': 'MA2023-02', 'issue': '37', 'first_page': '1770', 'last_page': '1770'} | Q144: [{'id': 'https://metadata.un.org/sdg/6', 'score': 0.75, 'display_name': 'Clean water and sanitation'}] | R144: [{'year': 2025, 'cited_by_count': 2}]
A145: https://openalex.org/W3217242043 | B145: https://doi.org/10.1002/solr.202100992 | C145: Serendipitous Doping in Nickel Oxide upon Microwaveâ€Induced Lowâ€Temperature Crystallization Enhances Efficiency of Perovskite Solar Cells | D145: 2021 | E145: 44530 | F145: {'openalex': 'https://openalex.org/W3217242043', 'doi': 'https://doi.org/10.1002/solr.202100992', 'mag': '3217242043'} | G145: en | H145: article | I145: 3 | J145: 8 | K145: 0.2005 | L145: FALSE | M145: 2 | N145: {'value': 0.52472715, 'is_in_top_1_percent': False, 'is_in_top_10_percent': False} | O145: {'min': 94, 'max': 96} | P145: {'volume': '6', 'issue': '2', 'first_page': None, 'last_page': None} | Q145: [{'score': 0.7900000214576721, 'id': 'https://metadata.un.org/sdg/7', 'display_name': 'Affordable and clean energy'}] | R145: [{'year': 2023, 'cited_by_count': 2}]
...

Sheet rio results
A1: Authors | B1: Author full names | C1: Author(s) ID | D1: Title | E1: Year | F1: Source title | G1: Volume | H1: Issue | I1: Art. No. | J1: Page start | K1: Page end | L1: Cited by | M1: DOI | N1: Link | O1: Affiliations | P1: Authors with affiliations | Q1: Correspondence Address | R1: Editors | S1: Publisher | T1: ISSN | U1: ISBN | V1: CODEN | W1: PubMed ID | X1: Language of Original Document | Y1: Abbreviated Source Title | Z1: Document Type | AA1: Publication Stage | AB1: Open Access | AC1: Source | AD1: EID
A2: Zhang, L.; Zhou, A.G.; Sun, B.R.; Chen, K.S.; Yu, H.-Z. | B2: Zhang, Lishen (57197774098); Zhou, Alvin G.C. (57221976275); Sun, Brigitta R. (57221981307); Chen, Kennedy S. (57215129380); Yu, Huazhong Hogan (7405855808) | C2: 57197774098; 57221976275; 57221981307; 57215129380; 7405855808 | D2: Functional and versatile superhydrophobic coatings via stoichiometric silanization | E2: 2021 | F2: Nature Communications | G2: 12 | H2: 1 | I2: 982 | L2: 279 | M2: 10.1038/s41467-021-21219-y | N2: https://www.scopus.com/inward/record.uri?eid=2-s2.0-85100856146&doi=10.1038%2Fs41467-021-21219-y&partnerID=40&md5=1c9709e9a52862247d20f96acfb64228 | O2: Simon Fraser University, Burnaby, BC, Canada | P2: Zhang, Lishen, Simon Fraser University, Burnaby, BC, Canada; Zhou, Alvin G.C., Simon Fraser University, Burnaby, BC, Canada; Sun, Brigitta R., Simon Fraser University, Burnaby, BC, Canada; Chen, Kennedy S., Simon Fraser University, Burnaby, BC, Canada; Yu, Huazhong Hogan, Simon Fraser University, Burnaby, BC, Canada | Q2: H.-Z. Yu; Department of Chemistry, Simon Fraser University, Burnaby, Canada; email: hogan_yu@sfu.ca | S2: Nature Research | W2: 33579959 | X2: English | Y2: Nat. Commun. | Z2: Article | AA2: Final | AB2: All Open Access; Gold Open Access; Green Accepted Open Access; Green Open Access | AC2: Scopus | AD2: 2-s2.0-85100856146
A3: Pearce, L.A.; Min, J.E.; Piske, M.; Zhou, H.; Homayra, F.; Slaunwhite, A.; Irvine, M.; McGowan, G.; Nosyk, B. | B3: Pearce, Lindsay A. (57202779892); Min, Jeong-eun (56007375400); Piske, Micah (55565383400); Zhou, Haoxuan (57213170548); Homayra, Fahmida (55960372900); Slaunwhite, Amanda Kathleen (56479230500); Irvine, Michael A. (56921713500); McGowan, Gina (56313570200); Nosyk, Bohdan (12809172100) | C3: 57202779892; 56007375400; 55565383400; 57213170548; 55960372900; 56479230500; 56921713500; 56313570200; 12809172100 | D3: Opioid agonist treatment and risk of mortality during opioid overdose public health emergency: Population based retrospective cohort study | E3: 2020 | F3: The BMJ | G3: 368 | I3: m772 | L3: 170 | M3: 10.1136/bmj.m772 | N3: https://www.scopus.com/inward/record.uri?eid=2-s2.0-85082731697&doi=10.1136%2Fbmj.m772&partnerID=40&md5=f1c5435206fedf49c48f60e06b9f7c14 | O3: Health Economic Research Unit, British Columbia Centre for Excellence in HIV-AIDS, Vancouver, BC, Canada; BC Centre for Disease Control, Vancouver, BC, Canada; British Columbia Ministry of Mental Health and Addictions, Victoria, BC, Canada; Faculty of Health Sciences, Simon Fraser University, Burnaby, BC, Canada | P3: Pearce, Lindsay A., Health Economic Research Unit, British Columbia Centre for Excellence in HIV-AIDS, Vancouver, BC, Canada; Min, Jeong-eun, Health Economic Research Unit, British Columbia Centre for Excellence in HIV-AIDS, Vancouver, BC, Canada; Piske, Micah, Health Economic Research Unit, British Columbia Centre for Excellence in HIV-AIDS, Vancouver, BC, Canada; Zhou, Haoxuan, Health Economic Research Unit, British Columbia Centre for Excellence in HIV-AIDS, Vancouver, BC, Canada; Homayra, Fahmida, Health Economic Research Unit, British Columbia Centre for Excellence in HIV-AIDS, Vancouver, BC, Canada; Slaunwhite, Amanda Kathleen, BC Centre for Disease Control, Vancouver, BC, Canada; Irvine, Michael A., BC Centre for Disease Control, Vancouver, BC, Canada; McGowan, Gina, British Columbia Ministry of Mental Health and Addictions, Victoria, BC, Canada; Nosyk, Bohdan, Health Economic Research Unit, British Columbia Centre for Excellence in HIV-AIDS, Vancouver, BC, Canada, Faculty of Health Sciences, Simon Fraser University, Burnaby, BC, Canada | Q3: B. Nosyk; Health Economic Research Unit, British Columbia Centre for Excellence in HIV/AIDS, Vancouver, V6Z 1Y6, Canada; email: bnosyk@cfenet.ubc.ca | S3: BMJ Publishing Group subscriptions@bmjgroup.com | T3: 00071447; 09598146; 17561833 | V3: BMJOA | W3: 32234712 | X3: English | Y3: BMJ | Z3: Article | AA3: Final | AB3: All Open Access; Green Accepted Open Access; Green Open Access; Hybrid Gold Open Access | AC3: Scopus | AD3: 2-s2.0-85082731697
A4: Higginbottom, D.B.; Kurkjian, A.T.K.; Chartrand, C.; Kazemi, M.; Brunelle, N.A.; MacQuarrie, E.R.; Klein, J.R.; Lee-Hone, N.R.; Stacho, J.; Ruether, M.; Bowness, C.; Bergeron, L.; DeAbreu, A.; Harrigan, S.R.; Kanaganayagam, J.; Marsden, D.W.; Richards, T.S.; Stott, L.A.; Roorda, S.; Morse, K.J.; Thewalt, M.L.W.; Simmons, S. | B4: Higginbottom, Daniel B. (55330606100); Kurkjian, Alexander T.K. (57203221971); Chartrand, Camille (57204605790); Kazemi, Moein (57223359408); Brunelle, Nicholas A. (57209575083); MacQuarrie, Evan R. (57188644453); Klein, James R. (57224657048); Lee-Hone, Nicholas R. (36998669900); Stacho, Jakub (57223357653); Ruether, Myles (57223768812); Bowness, Camille (57201136091); Bergeron, Laurent (57215486728); DeAbreu, Adam (56572674100); Harrigan, Stephen R. (57202744897); Kanaganayagam, Joshua (57222237504); Marsden, Danica W. (36615535300); Richards, Timothy S. (57201129737); Stott, Leea A. (57223368667); Roorda, Sjoerd (57206537236); Morse, Kevin J. (55904832900); Thewalt, Michael L.W. (7006609975); Simmons, Stephanie (36460336500) | C4: 55330606100; 57203221971; 57204605790; 57223359408; 57209575083; 57188644453; 57224657048; 36998669900; 57223357653; 57223768812; 57201136091; 57215486728; 56572674100; 57202744897; 57222237504; 36615535300; 57201129737; 57223368667; 57206537236; 55904832900; 7006609975; 36460336500 | D4: Optical observation of single spins in silicon | E4: 2022 | F4: Nature | G4: 607 | H4: 7918 | J4: 266 | K4: 270 | L4: 142 | M4: 10.1038/s41586-022-04821-y | N4: https://www.scopus.com/inward/record.uri?eid=2-s2.0-85133989154&doi=10.1038%2Fs41586-022-04821-y&partnerID=40&md5=1c1948c613feda6c3e6912afbf89622e | O4: Department of Physics, Simon Fraser University, Burnaby, BC, Canada; Photonic, Coquitlam, BC, Canada; Department of Physics, University of Montreal, Montreal, QC, Canada | P4: Higginbottom, Daniel B., Department of Physics, Simon Fraser University, Burnaby, BC, Canada; Kurkjian, Alexander T.K., Department of Physics, Simon Fraser University, Burnaby, BC, Canada, Photonic, Coquitlam, BC, Canada; Chartrand, Camille, Department of Physics, Simon Fraser University, Burnaby, BC, Canada, Photonic, Coquitlam, BC, Canada; Kazemi, Moein, Department of Physics, Simon Fraser University, Burnaby, BC, Canada; Brunelle, Nicholas A., Department of Physics, Simon Fraser University, Burnaby, BC, Canada; MacQuarrie, Evan R., Department of Physics, Simon Fraser University, Burnaby, BC, Canada, Photonic, Coquitlam, BC, Canada; Klein, James R., Department of Physics, Simon Fraser University, Burnaby, BC, Canada; Lee-Hone, Nicholas R., Department of Physics, Simon Fraser University, Burnaby, BC, Canada, Photonic, Coquitlam, BC, Canada; Stacho, Jakub, Department of Physics, Simon Fraser University, Burnaby, BC, Canada; Ruether, Myles, Department of Physics, Simon Fraser University, Burnaby, BC, Canada; Bowness, Camille, Department of Physics, Simon Fraser University, Burnaby, BC, Canada, Photonic, Coquitlam, BC, Canada; Bergeron, Laurent, Department of Physics, Simon Fraser University, Burnaby, BC, Canada; DeAbreu, Adam, Department of Physics, Simon Fraser University, Burnaby, BC, Canada; Harrigan, Stephen R., Department of Physics, Simon Fraser University, Burnaby, BC, Canada; Kanaganayagam, Joshua, Department of Physics, Simon Fraser University, Burnaby, BC, Canada; Marsden, Danica W., Department of Physics, Simon Fraser University, Burnaby, BC, Canada; Richards, Timothy S., Department of Physics, Simon Fraser University, Burnaby, BC, Canada; Stott, Leea A., Department of Physics, Simon Fraser University, Burnaby, BC, Canada; Roorda, Sjoerd, Department of Physics, University of Montreal, Montreal, QC, Canada; Morse, Kevin J., Department of Physics, Simon Fraser University, Burnaby, BC, Canada, Photonic, Coquitlam, BC, Canada; Thewalt, Michael L.W., Department of Physics, Simon Fraser University, Burnaby, BC, Canada; Simmons, Stephanie, Department of Physics, Simon Fraser University, Burnaby, BC, Canada, Photonic, Coquitlam, BC, Canada | Q4: S. Simmons; Department of Physics, Simon Fraser University, Burnaby, Canada; email: s.simmons@sfu.ca | S4: Nature Research | T4: 280836 | U4: 9780203448410; 0203448413 | V4: NATUA | W4: 35831600 | X4: English | Y4: Nature | Z4: Article | AA4: Final | AC4: Scopus | AD4: 2-s2.0-85133989154
A5: Li, X.; Aftab, S.; Hussain, S.; Kabir, F.; Henaish, A.M.A.; Al-Sehemi, A.G.; Pallavolu, M.R.; Ganesh, G. | B5: Li, Xin (56098157600); Aftab, Sikandar (57200114034); Hussain, Sajjad Z. (56435246200); Kabir, Fahmid (57204906651); Henaish, A. M.A. (56524476600); Al-Sehemi, Abdullah G. (6507858932); Pallavolu, Mohan Reddy (57201352403); Ganesh, Koyyada (55843979000) | C5: 56098157600; 57200114034; 56435246200; 57204906651; 56524476600; 6507858932; 57201352403; 55843979000 | D5: Dimensional diversity (0D, 1D, 2D, and 3D) in perovskite solar cells: exploring the potential of mixed-dimensional integrations | E5: 2024 | F5: Journal of Materials Chemistry A | G5: 12 | H5: 8 | J5: 4421 | K5: 4440 | L5: 122 | M5: 10.1039/d3ta06953b | N5: https://www.scopus.com/inward/record.uri?eid=2-s2.0-85184412995&doi=10.1039%2Fd3ta06953b&partnerID=40&md5=185ab9e781db04c445744d9690dac7c0 | O5: National University of Defense Technology China, Changsha, Hunan, China; Advanced Laser Technology Laboratory of Anhui Province, Hefei, Anhui, China; Department of Intelligent Mechatronics Engineering, Sejong University, Seoul, South Korea; Department of Nanotechnology and Advanced Materials Engineering, Sejong University, Seoul, South Korea; School of Engineering Science, Simon Fraser University, Burnaby, BC, Canada; Department of Physics, Tanta University, Tanta, Gharbia, Egypt; NANOTECH Center, Ural Federal University, Yekaterinburg, Sverdlovskaya, Russian Federation; King Khalid University, Abha, Asir, Saudi Arabia; Department of Chemistry, King Khalid University, Abha, Asir, Saudi Arabia; School of Chemical Engineering, Yeungnam University, Gyeongsan, Gyeongsangbuk-do, South Korea; Department of Chemistry, K L Deemed to be University, Vaddeswaram, AP, India | P5: Li, Xin, National University of Defense Technology China, Changsha, Hunan, China, Advanced Laser Technology Laboratory of Anhui Province, Hefei, Anhui, China; Aftab, Sikandar, Department of Intelligent Mechatronics Engineering, Sejong University, Seoul, South Korea; Hussain, Sajjad Z., Department of Nanotechnology and Advanced Materials Engineering, Sejong University, Seoul, South Korea; Kabir, Fahmid, School of Engineering Science, Simon Fraser University, Burnaby, BC, Canada; Henaish, A. M.A., Department of Physics, Tanta University, Tanta, Gharbia, Egypt, NANOTECH Center, Ural Federal University, Yekaterinburg, Sverdlovskaya, Russian Federation; Al-Sehemi, Abdullah G., King Khalid University, Abha, Asir, Saudi Arabia, Department of Chemistry, King Khalid University, Abha, Asir, Saudi Arabia; Pallavolu, Mohan Reddy, School of Chemical Engineering, Yeungnam University, Gyeongsan, Gyeongsangbuk-do, South Korea; Ganesh, Koyyada, School of Chemical Engineering, Yeungnam University, Gyeongsan, Gyeongsangbuk-do, South Korea, Department of Chemistry, K L Deemed to be University, Vaddeswaram, AP, India | Q5: S. Aftab; Department of Intelligent Mechatronics Engineering, Sejong University, Seoul, 05006, South Korea; email: aftab@sejong.ac.kr; M.R. Pallavolu; School of Chemical Engineering, Yeungnam University, Gyeongsan, 38541, South Korea; email: pmreddy@yu.ac.kr; G. Koyyada; School of Chemical Engineering, Yeungnam University, Gyeongsan, 38541, South Korea; email: ganeshkoyyada@gmail.com | S5: Royal Society of Chemistry | T5: 20507488 | V5: JMCAE | X5: English | Y5: J. Mater. Chem. A | Z5: Review | AA5: Final | AB5: All Open Access; Bronze Open Access | AC5: Scopus | AD5: 2-s2.0-85184412995
A6: Efaz1, E.T.; Rhaman, M.M.; Safayat-Al-Imam, S.; Bashar, K.L.; Kabir, F.; Mourtaza, M.D.E.; Sakib, S.N.; Mozahid, F.A. | B6: Efaz1, Erteza Tawsif (57298797900); Rhaman, Md Meganur (55975350800); Safayat-Al-Imam, Safayat Al (56412939400); Bashar, Khandaker Lubaba (57189522753); Kabir, Fahmid (57204906651); Mourtaza, Md Ehasan (57297792200); Sakib, Syed Nazmus (56412971600); Mozahid, Faisal (57203888125) | C6: 57298797900; 55975350800; 56412939400; 57189522753; 57204906651; 57297792200; 56412971600; 57203888125 | D6: A review of primary technologies of thin-film solar cells | E6: 2021 | F6: Engineering Research Express | G6: 3 | H6: 3 | I6: 32001 | L6: 121 | M6: 10.1088/2631-8695/ac2353 | N6: https://www.scopus.com/inward/record.uri?eid=2-s2.0-85117206710&doi=10.1088%2F2631-8695%2Fac2353&partnerID=40&md5=396afdd55a88a66e82bcadce31051e6f | O6: Department of Electrical and Electronic Engineering, Ahsanullah University of Science and Technology, Dhaka, Bangladesh; Faculty of Applied Sciences, Simon Fraser University, Burnaby, BC, Canada; Department of Business Administration, East West University, Dhaka, Bangladesh; Department of Electronics and Telecommunication Engineering, Daffodil International University, Dhaka, Bangladesh; Department of Glass and Ceramic Engineering, Bangladesh University of Engineering and Technology, Dhaka, Dhaka, Bangladesh | P6: Efaz1, Erteza Tawsif, Department of Electrical and Electronic Engineering, Ahsanullah University of Science and Technology, Dhaka, Bangladesh; Rhaman, Md Meganur, Department of Electrical and Electronic Engineering, Ahsanullah University of Science and Technology, Dhaka, Bangladesh; Safayat-Al-Imam, Safayat Al, Department of Electrical and Electronic Engineering, Ahsanullah University of Science and Technology, Dhaka, Bangladesh; Bashar, Khandaker Lubaba, Department of Electrical and Electronic Engineering, Ahsanullah University of Science and Technology, Dhaka, Bangladesh; Kabir, Fahmid, Faculty of Applied Sciences, Simon Fraser University, Burnaby, BC, Canada; Mourtaza, Md Ehasan, Department of Business Administration, East West University, Dhaka, Bangladesh; Sakib, Syed Nazmus, Department of Electronics and Telecommunication Engineering, Daffodil International University, Dhaka, Bangladesh; Mozahid, Faisal, Department of Glass and Ceramic Engineering, Bangladesh University of Engineering and Technology, Dhaka, Dhaka, Bangladesh | Q6: E.T. Efaz1; Department of Electrical & Electronic Engineering, Ahsanullah University of Science & Technology, Dhaka, 1208, Bangladesh; email: ertezatawsif@gmail.com | S6: IOP Publishing Ltd | X6: English | Y6: Eng. Res. Exp. | Z6: Review | AA6: Final | AB6: All Open Access; Bronze Open Access | AC6: Scopus | AD6: 2-s2.0-85117206710
