Workbook

Sheet query3
A1: id | B1: doi | C1: title | D1: publication_year | E1: publication_date | F1: ids | G1: language | H1: type | I1: institutions | J1: countries_distinct_count | K1: institutions_distinct_count | L1: fwci | M1: cited_by_count | N1: citation_normalized_percentile | O1: cited_by_percentile_year | P1: biblio | Q1: sustainable_development_goals | R1: counts_by_year
A2: https://openalex.org/W3010336234 | B2: https://doi.org/10.1016/s0140-6736(20)30526-2 | C2: COVID-19: the gendered impacts of the outbreak | D2: 2020 | E2: 43891 | F2: {'openalex': 'https://openalex.org/W3010336234', 'doi': 'https://doi.org/10.1016/s0140-6736(20)30526-2', 'mag': '3010336234', 'pmid': 'https://pubmed.ncbi.nlm.nih.gov/32151325'} | G2: en | H2: article | I2: [] | J2: 3 | K2: 3 | L2: 332.2687 | M2: 1743 | N2: {'value': 1.0, 'is_in_top_1_percent': True, 'is_in_top_10_percent': True} | O2: {'min': 90, 'max': 100} | P2: {'volume': '395', 'issue': '10227', 'first_page': '846', 'last_page': '848'} | Q2: [{'score': 0.8100000023841858, 'id': 'https://metadata.un.org/sdg/3', 'display_name': 'Good health and well-being'}] | R2: [{'year': 2026, 'cited_by_count': 5}, {'year': 2025, 'cited_by_count': 44}, {'year': 2024, 'cited_by_count': 116}, {'year': 2023, 'cited_by_count': 209}, {'year': 2022, 'cited_by_count': 325}, {'year': 2021, 'cited_by_count': 532}, {'year': 2020, 'cited_by_count': 510}, {'year': 2019, 'cited_by_count': 1}]
A3: https://openalex.org/W4383913712 | B3: https://doi.org/10.1111/1748-8583.12524 | C3: Human resource management in the age of generative artificial intelligence: Perspectives and research directions on ChatGPT | D3: 2023 | E3: 45108 | F3: {'openalex': 'https://openalex.org/W4383913712', 'doi': 'https://doi.org/10.1111/1748-8583.12524'} | G3: en | H3: article | I3: [] | J3: 7 | K3: 23 | L3: 25.9729 | M3: 671 | N3: {'value': 0.99602829, 'is_in_top_1_percent': True, 'is_in_top_10_percent': True} | O3: {'min': 89, 'max': 100} | P3: {'volume': '33', 'issue': '3', 'first_page': '606', 'last_page': '659'} | Q3: [{'display_name': 'Decent work and economic growth', 'score': 0.7099999785423279, 'id': 'https://metadata.un.org/sdg/8'}] | R3: [{'year': 2026, 'cited_by_count': 36}, {'year': 2025, 'cited_by_count': 316}, {'year': 2024, 'cited_by_count': 252}, {'year': 2023, 'cited_by_count': 66}, {'year': 2020, 'cited_by_count': 1}]
A4: https://openalex.org/W3038709602 | B4: https://doi.org/10.1080/14494035.2020.1787628 | C4: Mobilizing Policy (In)Capacity to Fight COVID-19: Understanding Variations in State Responses | D4: 2020 | E4: 44014 | F4: {'openalex': 'https://openalex.org/W3038709602', 'doi': 'https://doi.org/10.1080/14494035.2020.1787628', 'mag': '3038709602', 'pmid': 'https://pubmed.ncbi.nlm.nih.gov/35039722'} | G4: en | H4: article | I4: [] | J4: 3 | K4: 5 | L4: 143.6959 | M4: 553 | N4: {'value': 0.99973491, 'is_in_top_1_percent': True, 'is_in_top_10_percent': True} | O4: {'min': 99, 'max': 100} | P4: {'volume': '39', 'issue': '3', 'first_page': '285', 'last_page': '308'} | Q4: [{'display_name': 'Good health and well-being', 'score': 0.75, 'id': 'https://metadata.un.org/sdg/3'}] | R4: [{'year': 2026, 'cited_by_count': 10}, {'year': 2025, 'cited_by_count': 59}, {'year': 2024, 'cited_by_count': 71}, {'year': 2023, 'cited_by_count': 103}, {'year': 2022, 'cited_by_count': 126}, {'year': 2021, 'cited_by_count': 148}, {'year': 2020, 'cited_by_count': 35}]
A5: https://openalex.org/W3021430513 | B5: https://doi.org/10.1017/s0008423920000396 | C5: How Right-Leaning Media Coverage of COVID-19 Facilitated the Spread of Misinformation in the Early Stages of the Pandemic in the U.S. | D5: 2020 | E5: 43952 | F5: {'openalex': 'https://openalex.org/W3021430513', 'doi': 'https://doi.org/10.1017/s0008423920000396', 'mag': '3021430513'} | G5: en | H5: article | I5: [] | J5: 2 | K5: 3 | L5: 116.8417 | M5: 441 | N5: {'value': 0.99959241, 'is_in_top_1_percent': True, 'is_in_top_10_percent': True} | O5: {'min': 99, 'max': 100} | P5: {'volume': '53', 'issue': '2', 'first_page': '335', 'last_page': '342'} | Q5: [{'id': 'https://metadata.un.org/sdg/3', 'display_name': 'Good health and well-being', 'score': 0.8199999928474426}] | R5: [{'year': 2026, 'cited_by_count': 3}, {'year': 2025, 'cited_by_count': 31}, {'year': 2024, 'cited_by_count': 72}, {'year': 2023, 'cited_by_count': 80}, {'year': 2022, 'cited_by_count': 114}, {'year': 2021, 'cited_by_count': 100}, {'year': 2020, 'cited_by_count': 41}]
A6: https://openalex.org/W3202368191 | B6: https://doi.org/10.1016/j.jclepro.2021.129099 | C6: Digital agricultural technologies for food loss and waste prevention and reduction: Global trends, adoption opportunities and barriers | D6: 2021 | E6: 44468 | F6: {'openalex': 'https://openalex.org/W3202368191', 'doi': 'https://doi.org/10.1016/j.jclepro.2021.129099', 'mag': '3202368191'} | G6: en | H6: article | I6: [] | J6: 1 | K6: 3 | L6: 21.2312 | M6: 203 | N6: {'value': 0.99773959, 'is_in_top_1_percent': True, 'is_in_top_10_percent': True} | O6: {'min': 89, 'max': 100} | P6: {'volume': '323', 'issue': None, 'first_page': '129099', 'last_page': '129099'} | Q6: [{'score': 0.7799999713897705, 'display_name': 'Zero hunger', 'id': 'https://metadata.un.org/sdg/2'}] | R6: [{'year': 2026, 'cited_by_count': 11}, {'year': 2025, 'cited_by_count': 56}, {'year': 2024, 'cited_by_count': 62}, {'year': 2023, 'cited_by_count': 41}, {'year': 2022, 'cited_by_count': 32}, {'year': 2021, 'cited_by_count': 1}]
A7: https://openalex.org/W4387643322 | B7: https://doi.org/10.1016/j.chbah.2023.100022 | C7: ChatGPT in education: Methods, potentials, and limitations | D7: 2023 | E7: 45139 | F7: {'openalex': 'https://openalex.org/W4387643322', 'doi': 'https://doi.org/10.1016/j.chbah.2023.100022'} | G7: en | H7: article | I7: [] | J7: 1 | K7: 2 | L7: 7.6368 | M7: 197 | N7: {'value': 0.97616972, 'is_in_top_1_percent': False, 'is_in_top_10_percent': True} | O7: {'min': 94, 'max': 100} | P7: {'volume': '1', 'issue': '2', 'first_page': '100022', 'last_page': '100022'} | Q7: [{'display_name': 'Quality Education', 'score': 0.7799999713897705, 'id': 'https://metadata.un.org/sdg/4'}] | R7: [{'year': 2026, 'cited_by_count': 14}, {'year': 2025, 'cited_by_count': 97}, {'year': 2024, 'cited_by_count': 84}, {'year': 2023, 'cited_by_count': 2}]
A8: https://openalex.org/W3130387723 | B8: https://doi.org/10.1177/2053168021993979 | C8: How populism and conservative media fuel conspiracy beliefs about COVID-19 and what it means for COVID-19 behaviors | D8: 2021 | E8: 44197 | F8: {'openalex': 'https://openalex.org/W3130387723', 'doi': 'https://doi.org/10.1177/2053168021993979', 'mag': '3130387723'} | G8: en | H8: article | I8: [] | J8: 2 | K8: 2 | L8: 54.4455 | M8: 175 | N8: {'value': 0.99911792, 'is_in_top_1_percent': True, 'is_in_top_10_percent': True} | O8: {'min': 99, 'max': 100} | P8: {'volume': '8', 'issue': '1', 'first_page': None, 'last_page': None} | Q8: [{'display_name': 'Good health and well-being', 'score': 0.7900000214576721, 'id': 'https://metadata.un.org/sdg/3'}] | R8: [{'year': 2026, 'cited_by_count': 5}, {'year': 2025, 'cited_by_count': 20}, {'year': 2024, 'cited_by_count': 32}, {'year': 2023, 'cited_by_count': 31}, {'year': 2022, 'cited_by_count': 61}, {'year': 2021, 'cited_by_count': 26}]
A9: https://openalex.org/W3135252207 | B9: https://doi.org/10.21203/rs.3.rs-311311/v1 | C9: Energy system analytics and good governance -U4RIA goals of Energy Modelling for Policy Support | D9: 2021 | E9: 44265 | F9: {'openalex': 'https://openalex.org/W3135252207', 'doi': 'https://doi.org/10.21203/rs.3.rs-311311/v1', 'mag': '3135252207'} | G9: en | H9: preprint | I9: [] | J9: 13 | K9: 36 | M9: 169 | P9: {'volume': None, 'issue': None, 'first_page': None, 'last_page': None} | Q9: [] | R9: [{'year': 2025, 'cited_by_count': 5}, {'year': 2024, 'cited_by_count': 24}, {'year': 2023, 'cited_by_count': 23}, {'year': 2022, 'cited_by_count': 12}, {'year': 2021, 'cited_by_count': 105}]
A10: https://openalex.org/W3112317149 | B10: https://doi.org/10.1093/biosci/biaa144 | C10: Indigenous Systems of Management for Culturally and Ecologically Resilient Pacific Salmon (<i>Oncorhynchus</i>spp.) Fisheries | D10: 2020 | E10: 44132 | F10: {'openalex': 'https://openalex.org/W3112317149', 'doi': 'https://doi.org/10.1093/biosci/biaa144', 'mag': '3112317149', 'pmid': 'https://pubmed.ncbi.nlm.nih.gov/33613129'} | G10: en | H10: article | I10: [] | J10: 3 | K10: 20 | L10: 17.4097 | M10: 156 | N10: {'value': 0.99638182, 'is_in_top_1_percent': True, 'is_in_top_10_percent': True} | O10: {'min': 99, 'max': 100} | P10: {'volume': '71', 'issue': '2', 'first_page': '186', 'last_page': '204'} | Q10: [] | R10: [{'year': 2026, 'cited_by_count': 10}, {'year': 2025, 'cited_by_count': 43}, {'year': 2024, 'cited_by_count': 27}, {'year': 2023, 'cited_by_count': 31}, {'year': 2022, 'cited_by_count': 32}, {'year': 2021, 'cited_by_count': 13}]
A11: https://openalex.org/W3024728740 | B11: https://doi.org/10.1016/s0140-6736(20)31032-1 | C11: Global coordination on cross-border travel and trade measures crucial to COVID-19 response | D11: 2020 | E11: 43952 | F11: {'openalex': 'https://openalex.org/W3024728740', 'doi': 'https://doi.org/10.1016/s0140-6736(20)31032-1', 'mag': '3024728740', 'pmid': 'https://pubmed.ncbi.nlm.nih.gov/32416788'} | G11: en | H11: article | I11: [] | J11: 4 | K11: 4 | L11: 42.2019 | M11: 135 | N11: {'value': 0.99770258, 'is_in_top_1_percent': True, 'is_in_top_10_percent': True} | O11: {'min': 98, 'max': 100} | P11: {'volume': '395', 'issue': '10237', 'first_page': '1593', 'last_page': '1595'} | Q11: [{'score': 0.5199999809265137, 'display_name': 'Good health and well-being', 'id': 'https://metadata.un.org/sdg/3'}] | R11: [{'year': 2025, 'cited_by_count': 5}, {'year': 2024, 'cited_by_count': 9}, {'year': 2023, 'cited_by_count': 40}, {'year': 2022, 'cited_by_count': 37}, {'year': 2021, 'cited_by_count': 27}, {'year': 2020, 'cited_by_count': 17}]
A12: https://openalex.org/W3033762036 | B12: https://doi.org/10.1016/j.marpol.2020.104039 | C12: Considering Indigenous Peoples and local communities in governance of the global ocean commons | D12: 2020 | E12: 43988 | F12: {'openalex': 'https://openalex.org/W3033762036', 'doi': 'https://doi.org/10.1016/j.marpol.2020.104039', 'mag': '3033762036'} | G12: en | H12: article | I12: [] | J12: 4 | K12: 11 | L12: 11.3656 | M12: 133 | N12: {'value': 0.99008262, 'is_in_top_1_percent': True, 'is_in_top_10_percent': True} | O12: {'min': 90, 'max': 100} | P12: {'volume': '119', 'issue': None, 'first_page': '104039', 'last_page': '104039'} | Q12: [{'id': 'https://metadata.un.org/sdg/14', 'display_name': 'Life below water', 'score': 0.44999998807907104}] | R12: [{'year': 2026, 'cited_by_count': 3}, {'year': 2025, 'cited_by_count': 17}, {'year': 2024, 'cited_by_count': 40}, {'year': 2023, 'cited_by_count': 26}, {'year': 2022, 'cited_by_count': 21}, {'year': 2021, 'cited_by_count': 21}, {'year': 2020, 'cited_by_count': 4}, {'year': 2019, 'cited_by_count': 1}]
A13: https://openalex.org/W3133990882 | B13: https://doi.org/10.1111/rego.12392 | C13: Assessing the regulatory challenges of emerging disruptive technologies | D13: 2021 | E13: 44259 | F13: {'openalex': 'https://openalex.org/W3133990882', 'doi': 'https://doi.org/10.1111/rego.12392', 'mag': '3133990882'} | G13: en | H13: article | I13: [] | J13: 2 | K13: 3 | L13: 23.1344 | M13: 124 | N13: {'value': 0.99549441, 'is_in_top_1_percent': True, 'is_in_top_10_percent': True} | O13: {'min': 89, 'max': 100} | P13: {'volume': '15', 'issue': '4', 'first_page': '1009', 'last_page': '1019'} | Q13: [{'score': 0.4699999988079071, 'display_name': 'Peace, Justice and strong institutions', 'id': 'https://metadata.un.org/sdg/16'}] | R13: [{'year': 2026, 'cited_by_count': 7}, {'year': 2025, 'cited_by_count': 32}, {'year': 2024, 'cited_by_count': 26}, {'year': 2023, 'cited_by_count': 32}, {'year': 2022, 'cited_by_count': 20}, {'year': 2021, 'cited_by_count': 6}, {'year': 2020, 'cited_by_count': 1}]
A14: https://openalex.org/W3024740263 | B14: https://doi.org/10.1017/s0008423920000463 | C14: Novel Coronavirus, Old Partisanship: COVID-19 Attitudes and Behaviours in the United States and Canada | D14: 2020 | E14: 43963 | F14: {'openalex': 'https://openalex.org/W3024740263', 'doi': 'https://doi.org/10.1017/s0008423920000463', 'mag': '3024740263'} | G14: en | H14: article | I14: [] | J14: 2 | K14: 3 | L14: 74.4061 | M14: 110 | N14: {'value': 0.99931782, 'is_in_top_1_percent': True, 'is_in_top_10_percent': True} | O14: {'min': 97, 'max': 100} | P14: {'volume': '53', 'issue': '2', 'first_page': '357', 'last_page': '364'} | Q14: [{'score': 0.8500000238418579, 'id': 'https://metadata.un.org/sdg/3', 'display_name': 'Good health and well-being'}] | R14: [{'year': 2026, 'cited_by_count': 1}, {'year': 2025, 'cited_by_count': 6}, {'year': 2024, 'cited_by_count': 14}, {'year': 2023, 'cited_by_count': 22}, {'year': 2022, 'cited_by_count': 19}, {'year': 2021, 'cited_by_count': 37}, {'year': 2020, 'cited_by_count': 11}]
A15: https://openalex.org/W3004603131 | B15: https://doi.org/10.1177/0308518x20904070 | C15: Banking on refugees: Racialized expropriation in the fintech era | D15: 2020 | E15: 43865 | F15: {'openalex': 'https://openalex.org/W3004603131', 'doi': 'https://doi.org/10.1177/0308518x20904070', 'mag': '3004603131'} | G15: en | H15: article | I15: [] | J15: 2 | K15: 2 | L15: 11.6731 | M15: 108 | N15: {'value': 0.98377692, 'is_in_top_1_percent': False, 'is_in_top_10_percent': True} | O15: {'min': 97, 'max': 100} | P15: {'volume': '52', 'issue': '8', 'first_page': '1498', 'last_page': '1515'} | Q15: [{'score': 0.49000000953674316, 'display_name': 'Reduced inequalities', 'id': 'https://metadata.un.org/sdg/10'}] | R15: [{'year': 2026, 'cited_by_count': 12}, {'year': 2025, 'cited_by_count': 35}, {'year': 2024, 'cited_by_count': 12}, {'year': 2023, 'cited_by_count': 19}, {'year': 2022, 'cited_by_count': 21}, {'year': 2021, 'cited_by_count': 4}, {'year': 2020, 'cited_by_count': 5}]
A16: https://openalex.org/W4224236076 | B16: https://doi.org/10.1016/j.trip.2022.100602 | C16: Is the 15-minute city within reach? Evaluating walking and cycling accessibility to grocery stores in Vancouver | D16: 2022 | E16: 44669 | F16: {'openalex': 'https://openalex.org/W4224236076', 'doi': 'https://doi.org/10.1016/j.trip.2022.100602', 'pmid': 'https://pubmed.ncbi.nlm.nih.gov/37981961'} | G16: en | H16: article | I16: [] | J16: 1 | K16: 3 | L16: 22.4454 | M16: 106 | N16: {'value': 0.99740818, 'is_in_top_1_percent': True, 'is_in_top_10_percent': True} | O16: {'min': 98, 'max': 100} | P16: {'volume': '14', 'issue': None, 'first_page': '100602', 'last_page': '100602'} | Q16: [{'score': 0.5799999833106995, 'id': 'https://metadata.un.org/sdg/11', 'display_name': 'Sustainable cities and communities'}] | R16: [{'year': 2026, 'cited_by_count': 5}, {'year': 2025, 'cited_by_count': 48}, {'year': 2024, 'cited_by_count': 33}, {'year': 2023, 'cited_by_count': 14}, {'year': 2022, 'cited_by_count': 6}]
A17: https://openalex.org/W4360603406 | B17: https://doi.org/10.1016/s0140-6736(23)00012-0 | C17: Conceptualising commercial entities in public health: beyond unhealthy commodities and transnational corporations | D17: 2023 | E17: 45008 | F17: {'openalex': 'https://openalex.org/W4360603406', 'doi': 'https://doi.org/10.1016/s0140-6736(23)00012-0', 'pmid': 'https://pubmed.ncbi.nlm.nih.gov/36966783'} | G17: en | H17: review | I17: [] | J17: 7 | K17: 12 | L17: 34.9744 | M17: 105 | N17: {'value': 0.99886156, 'is_in_top_1_percent': True, 'is_in_top_10_percent': True} | O17: {'min': 99, 'max': 100} | P17: {'volume': '401', 'issue': '10383', 'first_page': '1214', 'last_page': '1228'} | Q17: [] | R17: [{'year': 2026, 'cited_by_count': 5}, {'year': 2025, 'cited_by_count': 34}, {'year': 2024, 'cited_by_count': 35}, {'year': 2023, 'cited_by_count': 31}]
A18: https://openalex.org/W2998016237 | B18: https://doi.org/10.1111/add.14947 | C18: The cascade of care for opioid use disorder: a retrospective study in British Columbia, Canada | D18: 2020 | E18: 43833 | F18: {'openalex': 'https://openalex.org/W2998016237', 'doi': 'https://doi.org/10.1111/add.14947', 'mag': '2998016237', 'pmid': 'https://pubmed.ncbi.nlm.nih.gov/31899565'} | G18: en | H18: article | I18: [] | J18: 1 | K18: 9 | L18: 10.4768 | M18: 95 | N18: {'value': 0.98737794, 'is_in_top_1_percent': False, 'is_in_top_10_percent': True} | O18: {'min': 97, 'max': 100} | P18: {'volume': '115', 'issue': '8', 'first_page': '1482', 'last_page': '1493'} | Q18: [{'display_name': 'No poverty', 'score': 0.5, 'id': 'https://metadata.un.org/sdg/1'}] | R18: [{'year': 2026, 'cited_by_count': 1}, {'year': 2025, 'cited_by_count': 20}, {'year': 2024, 'cited_by_count': 15}, {'year': 2023, 'cited_by_count': 16}, {'year': 2022, 'cited_by_count': 20}, {'year': 2021, 'cited_by_count': 16}, {'year': 2020, 'cited_by_count': 7}]
A19: https://openalex.org/W3158732668 | B19: https://doi.org/10.1016/s2468-2667(21)00070-0 | C19: A global public health convention for the 21st century | D19: 2021 | E19: 44322 | F19: {'openalex': 'https://openalex.org/W3158732668', 'doi': 'https://doi.org/10.1016/s2468-2667(21)00070-0', 'mag': '3158732668', 'pmid': 'https://pubmed.ncbi.nlm.nih.gov/33964227'} | G19: en | H19: review | I19: [] | J19: 6 | K19: 21 | L19: 5.2114 | M19: 88 | N19: {'value': 0.96591309, 'is_in_top_1_percent': False, 'is_in_top_10_percent': True} | O19: {'min': 99, 'max': 100} | P19: {'volume': '6', 'issue': '6', 'first_page': 'e428', 'last_page': 'e433'} | Q19: [{'display_name': 'Partnerships for the goals', 'score': 0.49000000953674316, 'id': 'https://metadata.un.org/sdg/17'}] | R19: [{'year': 2025, 'cited_by_count': 7}, {'year': 2024, 'cited_by_count': 12}, {'year': 2023, 'cited_by_count': 40}, {'year': 2022, 'cited_by_count': 15}, {'year': 2021, 'cited_by_count': 14}]
A20: https://openalex.org/W3165160003 | B20: https://doi.org/10.1016/j.copsyc.2021.04.009 | C20: Recent developments in the social identity approach to the psychology of climate change | D20: 2021 | E20: 44317 | F20: {'openalex': 'https://openalex.org/W3165160003', 'doi': 'https://doi.org/10.1016/j.copsyc.2021.04.009', 'mag': '3165160003'} | G20: en | H20: review | I20: [] | J20: 1 | K20: 4 | L20: 23.5931 | M20: 88 | N20: {'value': 0.99503831, 'is_in_top_1_percent': True, 'is_in_top_10_percent': True} | O20: {'min': 97, 'max': 100} | P20: {'volume': '42', 'issue': None, 'first_page': '95', 'last_page': '101'} | Q20: [{'score': 0.5600000023841858, 'id': 'https://metadata.un.org/sdg/13', 'display_name': 'Climate action'}] | R20: [{'year': 2026, 'cited_by_count': 5}, {'year': 2025, 'cited_by_count': 18}, {'year': 2024, 'cited_by_count': 25}, {'year': 2023, 'cited_by_count': 23}, {'year': 2022, 'cited_by_count': 12}, {'year': 2021, 'cited_by_count': 5}]
A21: https://openalex.org/W3188001216 | B21: https://doi.org/10.1080/19491247.2021.1940686 | C21: â€˜Trappedâ€™, â€˜anxiousâ€™ and â€˜traumatisedâ€™: COVID-19 intensified the impact of housing inequality on Australiansâ€™ mental health | D21: 2021 | E21: 44412 | F21: {'openalex': 'https://openalex.org/W3188001216', 'doi': 'https://doi.org/10.1080/19491247.2021.1940686', 'mag': '3188001216'} | G21: en | H21: article | I21: [] | J21: 4 | K21: 9 | L21: 8.3266 | M21: 87 | N21: {'value': 0.97822198, 'is_in_top_1_percent': False, 'is_in_top_10_percent': True} | O21: {'min': 93, 'max': 100} | P21: {'volume': '23', 'issue': '2', 'first_page': '260', 'last_page': '291'} | Q21: [{'score': 0.5, 'display_name': 'No poverty', 'id': 'https://metadata.un.org/sdg/1'}] | R21: [{'year': 2025, 'cited_by_count': 17}, {'year': 2024, 'cited_by_count': 34}, {'year': 2023, 'cited_by_count': 17}, {'year': 2022, 'cited_by_count': 17}, {'year': 2021, 'cited_by_count': 2}]
... A38: https://openalex.org/W4307130818 | B38: https://doi.org/10.1177/00207314221134040 | C38: Is Neoliberalism Killing Us? A Cross Sectional Study of the Impact of Neoliberal Beliefs on Health and Social Wellbeing in the Midst of the COVID-19 Pandemic | D38: 2022 | E38: 44856 | F38: {'openalex': 'https://openalex.org/W4307130818', 'doi': 'https://doi.org/10.1177/00207314221134040', 'pmid': 'https://pubmed.ncbi.nlm.nih.gov/36278290'} | G38: en | H38: article | I38: [] | J38: 1 | K38: 2 | L38: 8.0921 | M38: 53 | N38: {'value': 0.98440659, 'is_in_top_1_percent': False, 'is_in_top_10_percent': True} | O38: {'min': 99, 'max': 100} | P38: {'volume': '53', 'issue': '3', 'first_page': '363', 'last_page': '373'} | Q38: [{'id': 'https://metadata.un.org/sdg/1', 'display_name': 'No poverty', 'score': 0.6800000071525574}] | R38: [{'year': 2026, 'cited_by_count': 2}, {'year': 2025, 'cited_by_count': 11}, {'year': 2024, 'cited_by_count': 40}]
A39: https://openalex.org/W4389685183 | B39: https://doi.org/10.4324/9781003343431 | C39: Designing Public Policies | D39: 2023 | E39: 45273 | F39: {'openalex': 'https://openalex.org/W4389685183', 'doi': 'https://doi.org/10.4324/9781003343431'} | G39: en | H39: book | I39: [] | J39: 1 | K39: 2 | M39: 53 | P39: {'volume': None, 'issue': None, 'first_page': None, 'last_page': None} | Q39: [] | R39: [{'year': 2026, 'cited_by_count': 5}, {'year': 2025, 'cited_by_count': 14}, {'year': 2024, 'cited_by_count': 6}, {'year': 2023, 'cited_by_count': 2}, {'year': 2022, 'cited_by_count': 11}, {'year': 2021, 'cited_by_count': 2}, {'year': 2020, 'cited_by_count': 2}, {'year': 2017, 'cited_by_count': 2}, {'year': 2016, 'cited_by_count': 1}, {'year': 2015, 'cited_by_count': 2}, {'year': 2014, 'cited_by_count': 3}, {'year': 2013, 'cited_by_count': 1}, {'year': 2012, 'cited_by_count': 1}]
A40: https://openalex.org/W3097822616 | B40: https://doi.org/10.1139/facets-2021-0018 | C40: Letâ€™s do better: public representations of COVID-19 science | D40: 2021 | E40: 44197 | F40: {'openalex': 'https://openalex.org/W3097822616', 'doi': 'https://doi.org/10.1139/facets-2021-0018', 'mag': '3097822616'} | G40: en | H40: article | I40: [] | J40: 1 | K40: 4 | L40: 15.9698 | M40: 52 | N40: {'value': 0.99013861, 'is_in_top_1_percent': True, 'is_in_top_10_percent': True} | O40: {'min': 97, 'max': 100} | P40: {'volume': '6', 'issue': None, 'first_page': '403', 'last_page': '423'} | Q40: [] | R40: [{'year': 2026, 'cited_by_count': 1}, {'year': 2025, 'cited_by_count': 7}, {'year': 2024, 'cited_by_count': 11}, {'year': 2023, 'cited_by_count': 17}, {'year': 2022, 'cited_by_count': 12}, {'year': 2021, 'cited_by_count': 4}]
A41: https://openalex.org/W3117903907 | B41: https://doi.org/10.1136/bmjopen-2020-048353 | C41: Evaluation of risk mitigation measures for people with substance use disorders to address the dual public health crises of COVID-19 and overdose in British Columbia: a mixed-method study protocol | D41: 2021 | E41: 44348 | F41: {'openalex': 'https://openalex.org/W3117903907', 'doi': 'https://doi.org/10.1136/bmjopen-2020-048353', 'mag': '3117903907', 'pmid': 'https://pubmed.ncbi.nlm.nih.gov/34108170'} | G41: en | H41: article | I41: [] | J41: 1 | K41: 15 | L41: 9.0336 | M41: 52 | N41: {'value': 0.9836983, 'is_in_top_1_percent': False, 'is_in_top_10_percent': True} | O41: {'min': 93, 'max': 100} | P41: {'volume': '11', 'issue': '6', 'first_page': 'e048353', 'last_page': 'e048353'} | Q41: [{'id': 'https://metadata.un.org/sdg/3', 'display_name': 'Good health and well-being', 'score': 0.800000011920929}] | R41: [{'year': 2026, 'cited_by_count': 1}, {'year': 2025, 'cited_by_count': 4}, {'year': 2024, 'cited_by_count': 14}, {'year': 2023, 'cited_by_count': 23}, {'year': 2022, 'cited_by_count': 8}, {'year': 2021, 'cited_by_count': 2}]
A42: https://openalex.org/W4405056567 | B42: https://doi.org/10.1126/science.adn1477 | C42: Ecological erosion and expanding extinction risk of sharks and rays | D42: 2024 | E42: 45631 | F42: {'openalex': 'https://openalex.org/W4405056567', 'doi': 'https://doi.org/10.1126/science.adn1477', 'pmid': 'https://pubmed.ncbi.nlm.nih.gov/39636992'} | G42: en | H42: article | I42: [] | J42: 5 | K42: 15 | L42: 36.7019 | M42: 50 | N42: {'value': 0.99922988, 'is_in_top_1_percent': True, 'is_in_top_10_percent': True} | O42: {'min': 90, 'max': 100} | P42: {'volume': '386', 'issue': '6726', 'first_page': 'eadn1477', 'last_page': 'eadn1477'} | Q42: [{'score': 0.5199999809265137, 'id': 'https://metadata.un.org/sdg/14', 'display_name': 'Life below water'}] | R42: [{'year': 2026, 'cited_by_count': 10}, {'year': 2025, 'cited_by_count': 39}, {'year': 2024, 'cited_by_count': 1}]
A43: https://openalex.org/W3040179572 | B43: https://doi.org/10.1371/journal.pmed.1003172 | C43: Associations of substance use, psychosis, and mortality among people living in precarious housing or homelessness: A longitudinal, community-based study in Vancouver, Canada | D43: 2020 | E43: 44018 | F43: {'openalex': 'https://openalex.org/W3040179572', 'doi': 'https://doi.org/10.1371/journal.pmed.1003172', 'mag': '3040179572', 'pmid': 'https://pubmed.ncbi.nlm.nih.gov/32628679'} | G43: en | H43: article | I43: [] | J43: 1 | K43: 20 | L43: 9.6234 | M43: 47 | N43: {'value': 0.98266187, 'is_in_top_1_percent': False, 'is_in_top_10_percent': True} | O43: {'min': 97, 'max': 100} | P43: {'volume': '17', 'issue': '7', 'first_page': 'e1003172', 'last_page': 'e1003172'} | Q43: [{'id': 'https://metadata.un.org/sdg/3', 'display_name': 'Good health and well-being', 'score': 0.8999999761581421}] | R43: [{'year': 2026, 'cited_by_count': 1}, {'year': 2025, 'cited_by_count': 5}, {'year': 2024, 'cited_by_count': 5}, {'year': 2023, 'cited_by_count': 9}, {'year': 2022, 'cited_by_count': 10}, {'year': 2021, 'cited_by_count': 17}]
A44: https://openalex.org/W3035757489 | B44: https://doi.org/10.1002/ejsp.2703 | C44: On the protective role of identification with a stigmatized identity: Promoting engagement and discouraging disengagement coping strategies | D44: 2020 | E44: 44033 | F44: {'openalex': 'https://openalex.org/W3035757489', 'doi': 'https://doi.org/10.1002/ejsp.2703', 'mag': '3035757489'} | G44: en | H44: article | I44: [] | J44: 5 | K44: 6 | L44: 9.0682 | M44: 47 | N44: {'value': 0.97807194, 'is_in_top_1_percent': False, 'is_in_top_10_percent': True} | O44: {'min': 96, 'max': 99} | P44: {'volume': '50', 'issue': '6', 'first_page': '1125', 'last_page': '1142'} | Q44: [{'score': 0.6000000238418579, 'id': 'https://metadata.un.org/sdg/10', 'display_name': 'Reduced inequalities'}] | R44: [{'year': 2026, 'cited_by_count': 1}, {'year': 2025, 'cited_by_count': 10}, {'year': 2024, 'cited_by_count': 10}, {'year': 2023, 'cited_by_count': 8}, {'year': 2022, 'cited_by_count': 8}, {'year': 2021, 'cited_by_count': 7}, {'year': 2020, 'cited_by_count': 3}]
A45: https://openalex.org/W3186602906 | B45: https://doi.org/10.1136/bmjgh-2021-006794 | C45: Building a multisystemic understanding of societal resilience to the COVID-19 pandemic | D45: 2021 | E45: 44378 | F45: {'openalex': 'https://openalex.org/W3186602906', 'doi': 'https://doi.org/10.1136/bmjgh-2021-006794', 'mag': '3186602906', 'pmid': 'https://pubmed.ncbi.nlm.nih.gov/34301677'} | G45: en | H45: review | I45: [] | J45: 5 | K45: 29 | L45: 3.5826 | M45: 47 | N45: {'value': 0.9379845, 'is_in_top_1_percent': False, 'is_in_top_10_percent': True} | O45: {'min': 97, 'max': 100} | P45: {'volume': '6', 'issue': '7', 'first_page': 'e006794', 'last_page': 'e006794'} | Q45: [] | R45: [{'year': 2026, 'cited_by_count': 1}, {'year': 2025, 'cited_by_count': 6}, {'year': 2024, 'cited_by_count': 15}, {'year': 2023, 'cited_by_count': 15}, {'year': 2022, 'cited_by_count': 10}]
A46: https://openalex.org/W4376273128 | B46: https://doi.org/10.1016/j.polgeo.2023.102904 | C46: Asymmetries in urban, suburban, and rural place-based resentment | D46: 2023 | E46: 45058 | F46: {'openalex': 'https://openalex.org/W4376273128', 'doi': 'https://doi.org/10.1016/j.polgeo.2023.102904'} | G46: en | H46: article | I46: [] | J46: 1 | K46: 2 | L46: 26.702 | M46: 47 | N46: {'value': 0.99655693, 'is_in_top_1_percent': True, 'is_in_top_10_percent': True} | O46: {'min': 89, 'max': 100} | P46: {'volume': '105', 'issue': None, 'first_page': '102904', 'last_page': '102904'} | Q46: [{'id': 'https://metadata.un.org/sdg/1', 'display_name': 'No poverty', 'score': 0.4699999988079071}] | R46: [{'year': 2026, 'cited_by_count': 2}, {'year': 2025, 'cited_by_count': 25}, {'year': 2024, 'cited_by_count': 15}, {'year': 2023, 'cited_by_count': 4}, {'year': 2022, 'cited_by_count': 1}]
A47: https://openalex.org/W4281746126 | B47: https://doi.org/10.1111/bjet.13246 | C47: Conceptions and perspectives of data literacy in secondary education | D47: 2022 | E47: 44713 | F47: {'openalex': 'https://openalex.org/W4281746126', 'doi': 'https://doi.org/10.1111/bjet.13246'} | G47: en | H47: article | I47: [] | J47: 1 | K47: 1 | L47: 17.801 | M47: 46 | N47: {'value': 0.98758539, 'is_in_top_1_percent': False, 'is_in_top_10_percent': True} | O47: {'min': 96, 'max': 100} | P47: {'volume': '53', 'issue': '5', 'first_page': '1080', 'last_page': '1095'} | Q47: [{'id': 'https://metadata.un.org/sdg/4', 'display_name': 'Quality Education', 'score': 0.8899999856948853}] | R47: [{'year': 2026, 'cited_by_count': 4}, {'year': 2025, 'cited_by_count': 12}, {'year': 2024, 'cited_by_count': 18}, {'year': 2023, 'cited_by_count': 9}, {'year': 2022, 'cited_by_count': 3}]
A48: https://openalex.org/W3040074229 | B48: https://doi.org/10.1016/j.cities.2020.102816 | C48: Under pressure: Factors shaping urban greenspace provision in a mid-sized city | D48: 2020 | E48: 44016 | F48: {'openalex': 'https://openalex.org/W3040074229', 'doi': 'https://doi.org/10.1016/j.cities.2020.102816', 'mag': '3040074229', 'pmid': 'https://pubmed.ncbi.nlm.nih.gov/32834327'} | G48: en | H48: article | I48: [] | J48: 2 | K48: 4 | L48: 2.8588 | M48: 46 | N48: {'value': 0.9164395, 'is_in_top_1_percent': False, 'is_in_top_10_percent': True} | O48: {'min': 98, 'max': 99} | P48: {'volume': '106', 'issue': None, 'first_page': '102816', 'last_page': '102816'} | Q48: [{'score': 0.41999998688697815, 'display_name': 'Sustainable cities and communities', 'id': 'https://metadata.un.org/sdg/11'}] | R48: [{'year': 2025, 'cited_by_count': 8}, {'year': 2024, 'cited_by_count': 8}, {'year': 2023, 'cited_by_count': 11}, {'year': 2022, 'cited_by_count': 11}, {'year': 2021, 'cited_by_count': 8}]
A49: https://openalex.org/W4405021649 | B49: https://doi.org/10.3389/fmed.2024.1495582 | C49: Why we need to be careful with LLMs in medicine | D49: 2024 | E49: 45630 | F49: {'openalex': 'https://openalex.org/W4405021649', 'doi': 'https://doi.org/10.3389/fmed.2024.1495582', 'pmid': 'https://pubmed.ncbi.nlm.nih.gov/39697212'} | G49: en | H49: article | I49: [] | J49: 1 | K49: 1 | L49: 6.5255 | M49: 46 | N49: {'value': 0.96979969, 'is_in_top_1_percent': False, 'is_in_top_10_percent': True} | O49: {'min': 99, 'max': 100} | P49: {'volume': '11', 'issue': None, 'first_page': '1495582', 'last_page': '1495582'} | Q49: [{'id': 'https://metadata.un.org/sdg/5', 'display_name': 'Gender equality', 'score': 0.46000000834465027}] | R49: [{'year': 2026, 'cited_by_count': 7}, {'year': 2025, 'cited_by_count': 39}]
A50: https://openalex.org/W3126397122 | B50: https://doi.org/10.1007/s10433-020-00599-y | C50: Ageing in place processes in the neighbourhood environment: aÂ proposed conceptual framework from a capability approach | D50: 2021 | E50: 44234 | F50: {'openalex': 'https://openalex.org/W3126397122', 'doi': 'https://doi.org/10.1007/s10433-020-00599-y', 'mag': '3126397122', 'pmid': 'https://pubmed.ncbi.nlm.nih.gov/35250420'} | G50: en | H50: article | I50: [] | J50: 1 | K50: 2 | L50: 8.7113 | M50: 45 | N50: {'value': 0.97450912, 'is_in_top_1_percent': False, 'is_in_top_10_percent': True} | O50: {'min': 89, 'max': 100} | P50: {'volume': '19', 'issue': '1', 'first_page': '63', 'last_page': '74'} | Q50: [{'id': 'https://metadata.un.org/sdg/11', 'display_name': 'Sustainable cities and communities', 'score': 0.41999998688697815}] | R50: [{'year': 2026, 'cited_by_count': 4}, {'year': 2025, 'cited_by_count': 17}, {'year': 2024, 'cited_by_count': 9}, {'year': 2023, 'cited_by_count': 8}, {'year': 2022, 'cited_by_count': 6}, {'year': 2021, 'cited_by_count': 1}]
A51: https://openalex.org/W3201507460 | B51: https://doi.org/10.1016/j.erss.2021.102255 | C51: Unsettling transitions: Representing Indigenous peoples and knowledge in transitions research | D51: 2021 | E51: 44453 | F51: {'openalex': 'https://openalex.org/W3201507460', 'doi': 'https://doi.org/10.1016/j.erss.2021.102255', 'mag': '3201507460'} | G51: en | H51: article | I51: [] | J51: 2 | K51: 3 | L51: 3.9144 | M51: 45 | N51: {'value': 0.93785528, 'is_in_top_1_percent': False, 'is_in_top_10_percent': True} | O51: {'min': 93, 'max': 100} | P51: {'volume': '81', 'issue': None, 'first_page': '102255', 'last_page': '102255'} | Q51: [{'id': 'https://metadata.un.org/sdg/10', 'display_name': 'Reduced inequalities', 'score': 0.4000000059604645}] | R51: [{'year': 2026, 'cited_by_count': 6}, {'year': 2025, 'cited_by_count': 6}, {'year': 2024, 'cited_by_count': 15}, {'year': 2023, 'cited_by_count': 14}, {'year': 2022, 'cited_by_count': 2}, {'year': 2021, 'cited_by_count': 2}]
... A188: https://openalex.org/W4391215992 | B188: https://doi.org/10.1016/j.tree.2024.01.001 | C188: Relational place-based solutions for environmental policy misalignments | D188: 2024 | E188: 45316 | F188: {'openalex': 'https://openalex.org/W4391215992', 'doi': 'https://doi.org/10.1016/j.tree.2024.01.001'} | G188: en | H188: article | I188: [] | J188: 1 | K188: 11 | L188: 3.5872 | M188: 12 | N188: {'value': 0.92637074, 'is_in_top_1_percent': False, 'is_in_top_10_percent': True} | O188: {'min': 96, 'max': 100} | P188: {'volume': '39', 'issue': '3', 'first_page': '217', 'last_page': '220'} | Q188: [{'score': 0.5400000214576721, 'id': 'https://metadata.un.org/sdg/13', 'display_name': 'Climate action'}] | R188: [{'year': 2026, 'cited_by_count': 4}, {'year': 2025, 'cited_by_count': 5}, {'year': 2024, 'cited_by_count': 3}]
A189: https://openalex.org/W3195573675 | B189: https://doi.org/10.21203/rs.3.rs-759005/v1 | C189: COVID-19 vaccine hesitancy in Africa: A scoping review | D189: 2021 | E189: 44424 | F189: {'openalex': 'https://openalex.org/W3195573675', 'doi': 'https://doi.org/10.21203/rs.3.rs-759005/v1', 'mag': '3195573675'} | G189: en | H189: review | I189: [] | J189: 2 | K189: 7 | M189: 12 | P189: {'volume': None, 'issue': None, 'first_page': None, 'last_page': None} | Q189: [{'id': 'https://metadata.un.org/sdg/3', 'score': 0.8299999833106995, 'display_name': 'Good health and well-being'}] | R189: [{'year': 2025, 'cited_by_count': 3}, {'year': 2024, 'cited_by_count': 3}, {'year': 2023, 'cited_by_count': 4}, {'year': 2022, 'cited_by_count': 2}]
A190: https://openalex.org/W4206514936 | B190: https://doi.org/10.1371/journal.pgph.0000078 | C190: Analyzing natural herd immunity media discourse in the United Kingdom and the United States | D190: 2022 | E190: 44573 | F190: {'openalex': 'https://openalex.org/W4206514936', 'doi': 'https://doi.org/10.1371/journal.pgph.0000078', 'pmid': 'https://pubmed.ncbi.nlm.nih.gov/36962077'} | G190: en | H190: article | I190: [] | J190: 2 | K190: 4 | L190: 1.904 | M190: 12 | N190: {'value': 0.84684191, 'is_in_top_1_percent': False, 'is_in_top_10_percent': False} | O190: {'min': 94, 'max': 98} | P190: {'volume': '2', 'issue': '1', 'first_page': 'e0000078', 'last_page': 'e0000078'} | Q190: [{'id': 'https://metadata.un.org/sdg/3', 'score': 0.7400000095367432, 'display_name': 'Good health and well-being'}] | R190: [{'year': 2025, 'cited_by_count': 4}, {'year': 2024, 'cited_by_count': 3}, {'year': 2023, 'cited_by_count': 3}, {'year': 2022, 'cited_by_count': 2}]
A191: https://openalex.org/W4289523079 | B191: https://doi.org/10.1017/gov.2022.26 | C191: What Do We Know about Power Sharing after 50 Years? | D191: 2022 | E191: 44775 | F191: {'openalex': 'https://openalex.org/W4289523079', 'doi': 'https://doi.org/10.1017/gov.2022.26'} | G191: en | H191: article | I191: [] | J191: 5 | K191: 5 | L191: 4.5481 | M191: 12 | N191: {'value': 0.94528662, 'is_in_top_1_percent': False, 'is_in_top_10_percent': True} | O191: {'min': 94, 'max': 99} | P191: {'volume': '58', 'issue': '4', 'first_page': '899', 'last_page': '920'} | Q191: [] | R191: [{'year': 2025, 'cited_by_count': 6}, {'year': 2024, 'cited_by_count': 2}, {'year': 2023, 'cited_by_count': 4}]
A192: https://openalex.org/W4224110254 | B192: https://doi.org/10.1177/14713012221084173 | C192: Out-of-home participation among people living with dementia: A study in four countries | D192: 2022 | E192: 44668 | F192: {'openalex': 'https://openalex.org/W4224110254', 'doi': 'https://doi.org/10.1177/14713012221084173', 'pmid': 'https://pubmed.ncbi.nlm.nih.gov/35435030'} | G192: en | H192: article | I192: [] | J192: 4 | K192: 11 | L192: 1.7453 | M192: 12 | N192: {'value': 0.83614929, 'is_in_top_1_percent': False, 'is_in_top_10_percent': False} | O192: {'min': 89, 'max': 99} | P192: {'volume': '21', 'issue': '5', 'first_page': '1636', 'last_page': '1652'} | Q192: [{'id': 'https://metadata.un.org/sdg/10', 'display_name': 'Reduced inequalities', 'score': 0.5699999928474426}] | R192: [{'year': 2026, 'cited_by_count': 1}, {'year': 2025, 'cited_by_count': 2}, {'year': 2024, 'cited_by_count': 8}, {'year': 2023, 'cited_by_count': 1}]
...

Sheet rio results
A1: Authors | B1: Author full names | C1: Author(s) ID | D1: Title | E1: Year | F1: Source title | G1: Volume | H1: Issue | I1: Art. No. | J1: Page start | K1: Page end | L1: Cited by | M1: DOI | N1: Link | O1: Affiliations | P1: Authors with affiliations | Q1: Correspondence Address | R1: Editors | S1: Publisher | T1: ISSN | U1: ISBN | V1: CODEN | W1: PubMed ID | X1: Language of Original Document | Y1: Abbreviated Source Title | Z1: Document Type | AA1: Publication Stage | AB1: Open Access | AC1: Source | AD1: EID
A2: Sachs, J.D.; S Abdool Karim, S.S.A.; Aknin, L.B.; Allen, J.; Brosbøl, K.; Colombo, F.; Barron, G.C.; Espinosa, M.F.; Gaspar, V.; Gaviria, A.; Haines, A.; Hotez, P.J.; Koundouri, P.; Bascuñán, F.L.; Lee, J.-K.; Pate, M.A.; Ramos, G.; Reddy, K.S.; Serageldin, I.; Thwaites, J.; Vike-Freiberga, V.; Wang, C.; Were, M.K.; Xue, L.; Bahadur, C.; Bottazzi, M.E.; Bullen, C.; Laryea-Adjei, G.; Ben Amor, Y.B.; Karadağ, O.; Lafortune, G.; Torres, E.; Barredo, L.; Bartels, J.G.E.; Joshi, N.; Hellard, M.; Huynh, U.K.; Khandelwal, S.; Lazarus, J.V.; Michie, S. | B2: Sachs, Jeffrey David (7101926169); S Abdool Karim, Salim Safurdeen S. (57159115100); Aknin, Lara B. (23984324100); Allen, Joseph A. (16834469500); Brosbøl, Kirsten (57219249780); Colombo, Francesca (57222157141); Barron, Gabriela Cuevas (57224643988); Espinosa, Maria Fernanda (57225440135); Gaspar, Vítor (7003585319); Gaviria, Alejandro (6602903221); Haines, Andy P. (19334435800); Hotez, Peter J. (7004958298); Koundouri, Phoebe C. (14060612200); Bascuñán, Felipe Larraín (57883443700); Lee, Jong-koo (25028188800); Pate, Muhammad Ali (36175181000); Ramos, Gabriela (43061495200); Reddy, K. Srinath (35417788900); Serageldin, Ismail (6603772913); Thwaites, John W. (57219255286); Vike-Freiberga, Vaira (26647851600); Wang, Chen (57196394775); Were, Miriam K. (24761349500); Xue, Lan (36350478100); Bahadur, Chandrika (6504617035); Bottazzi, Maria Elena (6603937133); Bullen, Christopher R. (56560797800); Laryea-Adjei, George (15819414000); Ben Amor, Yanis (42160940900); Karadağ, Ozge (37057020400); Lafortune, Guillaume (57218225190); Torres, Emma (58374077200); Barredo, Lauren (57219108849); Bartels, Juliana G.E. (57219255704); Joshi, Neena (59883988200); Hellard, Margaret E. (7004178983); Huynh, Uyen Kim (57039258100); Khandelwal, Shweta (57201619873); Lazarus, J. V. (55431519100); Michie, Susan F. (7004779970) | C2: 7101926169; 57159115100; 23984324100; 16834469500; 57219249780; 57222157141; 57224643988; 57225440135; 7003585319; 6602903221; 19334435800; 7004958298; 14060612200; 57883443700; 25028188800; 36175181000; 43061495200; 35417788900; 6603772913; 57219255286; 26647851600; 57196394775; 24761349500; 36350478100; 6504617035; 6603937133; 56560797800; 15819414000; 42160940900; 37057020400; 57218225190; 58374077200; 57219108849; 57219255704; 59883988200; 7004178983; 57039258100; 57201619873; 55431519100; 7004779970 | D2: The Lancet Commission on lessons for the future from the COVID-19 pandemic | E2: 2022 | F2: The Lancet | G2: 400 | H2: 10359 | J2: 1224 | K2: 1280 | L2: 601 | M2: 10.1016/S0140-6736(22)01585-9 | N2: https://www.scopus.com/inward/record.uri?eid=2-s2.0-85139284208&doi=10.1016%2FS0140-6736%2822%2901585-9&partnerID=40&md5=163f0ab62a00294402fe6fd220cd7bc2 | O2: Center for Sustainable Development, Columbia University, New York, NY, United States; Mailman School of Public Health, New York, NY, United States; Simon Fraser University, Burnaby, BC, Canada; Department of Global Health and Population, Harvard T.H. Chan School of Public Health, Boston, MA, United States; Department of Environmental Health, Harvard T.H. Chan School of Public Health, Boston, MA, United States; Parliamentarians for the Global Goals, Copenhagen, Denmark; Health Division, L'Organisation de Coopération et de Développement Economiques, Paris, Ile-de-France, France; UHC2030, Geneva, Switzerland; Robert Bosch Academy, Berlin, Germany; International Monetary Fund, Washington, D.C., DC, United States; Ministry of National Education, Bogota, Colombia; Department of Public Health, London School of Hygiene & Tropical Medicine, London, United Kingdom; Department of Population Health, London School of Hygiene & Tropical Medicine, London, United Kingdom; National School of Tropical Medicine, Baylor College of Medicine, Houston, TX, United States; Department of International & European Economic Studies, Athens University of Economics and Business, Athens, Attica, Greece; Department of Technology, Technical University of Denmark, Lyngby, Hovedstaden, Denmark; European Association of Environmental and Resource Economists, Athens, Greece; Department of Economics, Pontificia Universidad Católica de Chile, Santiago, RM, Chile; National Academy of Medicine of Korea, Seoul, Seoul, South Korea; UNESCO United Nations Educational, Scientific and Cultural Organization, Paris, France; Public Health Foundation of India, New Delhi, India; Bibliotheca Alexandrina, Alexandria, Egypt; Monash University, Melbourne, VIC, Australia; Nizami Ganjavi International Center, Baku, Azerbaijan; Beijing Tiantan Hospital, Capital Medical University, Beijing, China; China-Japan Friendship Hospital, Beijing, Beijing, China; Champions of an AIDS-Free Generation in Africa, Nairobi, Kenya; Schwarzman College, Tsinghua University, Beijing, China; The Lancet COVID-19 Commission Regional Task Force: India, New Delhi, India; National Institute for Health Innovation, University of Auckland, Auckland, AUK, New Zealand; UNICEF, New York, NY, United States; Sustainable Development Solutions Network, Paris, France; United Nations, New York, NY, United States; Burnet Institute, Melbourne, VIC, Australia; UNICEF, New York, NY, United States; Instituto de Salud Global de Barcelona, Barcelona, Barcelona, Spain; Centre for Behaviour Change, University College London, London, United Kingdom | P2: Sachs, Jeffrey David, Center for Sustainable Development, Columbia University, New York, NY, United States; S Abdool Karim, Salim Safurdeen S., Mailman School of Public Health, New York, NY, United States; Aknin, Lara B., Simon Fraser University, Burnaby, BC, Canada; Allen, Joseph A., Department of Environmental Health, Harvard T.H. Chan School of Public Health, Boston, MA, United States; Brosbøl, Kirsten, Parliamentarians for the Global Goals, Copenhagen, Denmark; Colombo, Francesca, Health Division, L'Organisation de Coopération et de Développement Economiques, Paris, Ile-de-France, France; Barron, Gabriela Cuevas, UHC2030, Geneva, Switzerland; Espinosa, Maria Fernanda, Robert Bosch Academy, Berlin, Germany; Gaspar, Vítor, International Monetary Fund, Washington, D.C., DC, United States; Gaviria, Alejandro, Ministry of National Education, Bogota, Colombia; Haines, Andy P., Department of Public Health, London School of Hygiene & Tropical Medicine, London, United Kingdom, Department of Population Health, London School of Hygiene & Tropical Medicine, London, United Kingdom; Hotez, Peter J., National School of Tropical Medicine, Baylor College of Medicine, Houston, TX, United States; Koundouri, Phoebe C., Department of International & European Economic Studies, Athens University of Economics and Business, Athens, Attica, Greece, Department of Technology, Technical University of Denmark, Lyngby, Hovedstaden, Denmark, European Association of Environmental and Resource Economists, Athens, Greece; Bascuñán, Felipe Larraín, Department of Economics, Pontificia Universidad Católica de Chile, Santiago, RM, Chile; Lee, Jong-koo, National Academy of Medicine of Korea, Seoul, Seoul, South Korea; Pate, Muhammad Ali, Department of Global Health and Population, Harvard T.H. Chan School of Public Health, Boston, MA, United States; Ramos, Gabriela, UNESCO United Nations Educational, Scientific and Cultural Organization, Paris, France; Reddy, K. Srinath, Public Health Foundation of India, New Delhi, India; Serageldin, Ismail, Bibliotheca Alexandrina, Alexandria, Egypt; Thwaites, John W., Monash University, Melbourne, VIC, Australia; Vike-Freiberga, Vaira, Nizami Ganjavi International Center, Baku, Azerbaijan; Wang, Chen, Beijing Tiantan Hospital, Capital Medical University, Beijing, China, China-Japan Friendship Hospital, Beijing, Beijing, China; Were, Miriam K., Champions of an AIDS-Free Generation in Africa, Nairobi, Kenya; Xue, Lan, Schwarzman College, Tsinghua University, Beijing, China; Bahadur, Chandrika, The Lancet COVID-19 Commission Regional Task Force: India, New Delhi, India; Bottazzi, Maria Elena, National School of Tropical Medicine, Baylor College of Medicine, Houston, TX, United States; Bullen, Christopher R., National Institute for Health Innovation, University of Auckland, Auckland, AUK, New Zealand; Laryea-Adjei, George, UNICEF, New York, NY, United States; Ben Amor, Yanis, Center for Sustainable Development, Columbia University, New York, NY, United States; Karadağ, Ozge, Center for Sustainable Development, Columbia University, New York, NY, United States; Lafortune, Guillaume, Sustainable Development Solutions Network, Paris, France; Torres, Emma, United Nations, New York, NY, United States; Barredo, Lauren, United Nations, New York, NY, United States; Bartels, Juliana G.E., Center for Sustainable Development, Columbia University, New York, NY, United States; Joshi, Neena, United Nations, New York, NY, United States; Hellard, Margaret E., Burnet Institute, Melbourne, VIC, Australia; Huynh, Uyen Kim, UNICEF, New York, NY, United States; Khandelwal, Shweta, Public Health Foundation of India, New Delhi, India; Lazarus, J. V., Instituto de Salud Global de Barcelona, Barcelona, Barcelona, Spain; Michie, Susan F., Centre for Behaviour Change, University College London, London, United Kingdom | Q2: J.D. Sachs; Center for Sustainable Development, Columbia University, New York, United States; email: sachs@columbia.edu | S2: Elsevier B.V. | T2: 01406736; 1474547X | V2: LANCA | W2: 36115368 | X2: English | Y2: Lancet | Z2: Review | AA2: Final | AB2: All Open Access; Green Accepted Open Access; Green Open Access | AC2: Scopus | AD2: 2-s2.0-85139284208
A3: Budhwar, P.; Chowdhury, S.; Wood, G.; Aguinis, H.; Bamber, G.J.; Beltran, J.R.; Boselie, P.; Cooke, F.; Decker, S.; DeNisi, A.; Prasanta K. Dey, P.K.; Guest, D.; Knoblich, A.J.; Malik, A.; Paauwe, J.; Papagiannidis, S.; Patel, C.; Pereira, V.; Ren, S.; Rogelberg, S.; Saunders, M.N.K.; Tung, R.L.; Varma, A. | B3: Budhwar, Pawan S. (6701694690); Chowdhury, Soumyadeb (57201962502); Wood, Geoffrey T. (10043338900); Aguinis, Herman (7006100196); Bamber, Greg J. (6602312369); Beltran, Jose R. (58485320200); Boselie, Paul (8717563000); Cooke, Fang Lee (7102561934); Decker, Stephanie (35832594400); DeNisi, Angelo S. (6602731645); Prasanta K. Dey, Prasanta Kumar (34568899900); Guest, David E. (7005035099); Knoblich, Andrew J. (58486780800); Malik, Ashish (56208258600); Paauwe, Jaap (6507836949); Papagiannidis, Savvas (8848778400); Patel, Charmi (56258661200); Pereira, Vijay Edward (37108422900); Ren, Shuang (51665996800); Rogelberg, Steven G. (6701498798); Saunders, Mark N.K. (7201859502); Tung, Rosalie L. (7004507673); Varma, Arup (7202665999) | C3: 6701694690; 57201962502; 10043338900; 7006100196; 6602312369; 58485320200; 8717563000; 7102561934; 35832594400; 6602731645; 34568899900; 7005035099; 58486780800; 56208258600; 6507836949; 8848778400; 56258661200; 37108422900; 51665996800; 6701498798; 7201859502; 7004507673; 7202665999 | D3: Human resource management in the age of generative artificial intelligence: Perspectives and research directions on ChatGPT | E3: 2023 | F3: Human Resource Management Journal | G3: 33 | H3: 3 | J3: 606 | K3: 659 | L3: 600 | M3: 10.1111/1748-8583.12524 | N3: https://www.scopus.com/inward/record.uri?eid=2-s2.0-85164660060&doi=10.1111%2F1748-8583.12524&partnerID=40&md5=e9c678da5e21f530c252436b62be8bf6 | O3: Aston University, Birmingham, West Midlands, United Kingdom; Information, TBS Business School, Toulouse, Occitanie, France; DAN Department of Management and Organizational Studies, Western University, London, ON, Canada; Cranfield University, Cranfield, Bedfordshire, United Kingdom; University of Bath, Bath, Somerset, United Kingdom; Trinity Business School, Dublin, Leinster, Ireland; GW School of Business, Washington, D.C., United States; Monash University, Melbourne, VIC, Australia; Department of Human Resources & Organizational Behavior, Rutgers School of Business-Camden, Camden, NJ, United States; Department of Human Resource Studies, Tilburg University, Tilburg, Noord-Brabant, Netherlands; Utrecht University School of Governance, Utrecht, Netherlands; Monash University, Melbourne, VIC, Australia; Department of Strategy and International Business, Birmingham Business School, Birmingham, United Kingdom; A. B. Freeman School of Business, New Orleans, LA, United States; Department of Operations and Information Management, Aston Business School, Birmingham, West Midlands, United Kingdom; King’s Business School, London, United Kingdom; Organizational Science, The University of North Carolina at Charlotte, Charlotte, NC, United States; College of Human and Social Futures, Newcastle Business School, Newcastle, NSW, Australia; Newcastle University Business School, United Kingdom, Newcastle, Tyne and Wear, United Kingdom; Henley Business School, Reading, Berkshire, United Kingdom; NEOMA Business School, Mont-Saint-Aignan, Normandie, France; Queen’s Business School, Queen's University Belfast, Belfast, Northern Ireland, United Kingdom; Department of Management, Birmingham Business School, Birmingham, United Kingdom; Simon Fraser University, Burnaby, BC, Canada; Quinlan School of Business, Loyola University Chicago, Chicago, IL, United States | P3: Budhwar, Pawan S., Aston University, Birmingham, West Midlands, United Kingdom; Chowdhury, Soumyadeb, Information, TBS Business School, Toulouse, Occitanie, France; Wood, Geoffrey T., DAN Department of Management and Organizational Studies, Western University, London, ON, Canada, Cranfield University, Cranfield, Bedfordshire, United Kingdom, University of Bath, Bath, Somerset, United Kingdom, Trinity Business School, Dublin, Leinster, Ireland; Aguinis, Herman, GW School of Business, Washington, D.C., United States; Bamber, Greg J., Monash University, Melbourne, VIC, Australia, Department of Human Resources & Organizational Behavior, Rutgers School of Business-Camden, Camden, NJ, United States, Department of Human Resource Studies, Tilburg University, Tilburg, Noord-Brabant, Netherlands; Beltran, Jose R., Department of Human Resources & Organizational Behavior, Rutgers School of Business-Camden, Camden, NJ, United States; Boselie, Paul, Utrecht University School of Governance, Utrecht, Netherlands; Cooke, Fang Lee, Monash University, Melbourne, VIC, Australia; Decker, Stephanie, Department of Strategy and International Business, Birmingham Business School, Birmingham, United Kingdom; DeNisi, Angelo S., A. B. Freeman School of Business, New Orleans, LA, United States; Prasanta K. Dey, Prasanta Kumar, Department of Operations and Information Management, Aston Business School, Birmingham, West Midlands, United Kingdom; Guest, David E., King’s Business School, London, United Kingdom; Knoblich, Andrew J., Organizational Science, The University of North Carolina at Charlotte, Charlotte, NC, United States; Malik, Ashish, College of Human and Social Futures, Newcastle Business School, Newcastle, NSW, Australia; Paauwe, Jaap, Department of Human Resource Studies, Tilburg University, Tilburg, Noord-Brabant, Netherlands; Papagiannidis, Savvas, Newcastle University Business School, United Kingdom, Newcastle, Tyne and Wear, United Kingdom; Patel, Charmi, Henley Business School, Reading, Berkshire, United Kingdom; Pereira, Vijay Edward, NEOMA Business School, Mont-Saint-Aignan, Normandie, France; Ren, Shuang, Queen’s Business School, Queen's University Belfast, Belfast, Northern Ireland, United Kingdom; Rogelberg, Steven G., Organizational Science, The University of North Carolina at Charlotte, Charlotte, NC, United States; Saunders, Mark N.K., Department of Management, Birmingham Business School, Birmingham, United Kingdom; Tung, Rosalie L., Simon Fraser University, Burnaby, BC, Canada; Varma, Arup, Quinlan School of Business, Loyola University Chicago, Chicago, IL, United States | Q3: S. Chowdhury; Information, Operations and Management Sciences Department, TBS Business School, Toulouse, France; email: s.chowdhury@tbs-education.fr | S3: John Wiley and Sons Inc | T3: 9545395 | X3: English | Y3: Hum. Resour. Manage. J. | Z3: Review | AA3: Final | AB3: All Open Access; Green Accepted Open Access; Green Open Access; Hybrid Gold Open Access | AC3: Scopus | AD3: 2-s2.0-85164660060
A4: Capano, G.; Howlett, M.; Jarvis, D.S.L.; Ramesh, M.; Goyal, N. | B4: Capano, Giliberto (23767017600); Howlett, Michael P. (7004315057); Jarvis, Darryl Stuart L. (35758736700); Ramesh, M. (7006248680); Goyal, Nihit (57194183948) | C4: 23767017600; 7004315057; 35758736700; 7006248680; 57194183948 | D4: Mobilizing Policy (In)Capacity to Fight COVID-19: Understanding Variations in State Responses | E4: 2020 | F4: Policy and Society | J4: 285 | K4: 308 | L4: 445 | M4: 10.1080/14494035.2020.1787628 | N4: https://www.scopus.com/inward/record.uri?eid=2-s2.0-85087618935&doi=10.1080%2F14494035.2020.1787628&partnerID=40&md5=22c83a7148d8510ce0cb367510b516ce | O4: Alma Mater Studiorum Università di Bologna, Bologna, BO, Italy; Simon Fraser University, Burnaby, BC, Canada; The Education University of Hong Kong, Hong Kong, Hong Kong; National University of Singapore, Singapore City, Singapore | P4: Capano, Giliberto, Alma Mater Studiorum Università di Bologna, Bologna, BO, Italy; Howlett, Michael P., Simon Fraser University, Burnaby, BC, Canada; Jarvis, Darryl Stuart L., The Education University of Hong Kong, Hong Kong, Hong Kong; Ramesh, M., National University of Singapore, Singapore City, Singapore; Goyal, Nihit, National University of Singapore, Singapore City, Singapore | Q4: G. Capano; University of Bologna, Italy; email: giliberto.capano@unibo.it | S4: Taylor and Francis Ltd. | T4: 14494035 | X4: English | Y4: Policy Soc. | Z4: Article | AA4: Final | AB4: All Open Access; Gold Open Access; Green Accepted Open Access; Green Open Access | AC4: Scopus | AD4: 2-s2.0-85087618935
A5: Motta, M.; Stecula, D.A.; Farhart, C. | B5: Motta, Matthew P. (57200447460); Stecula, Dominik Andrzej (56071614400); Farhart, Christina E. (56004173900) | C5: 57200447460; 56071614400; 56004173900 | D5: How right-leaning media coverage of Covid-19 facilitated the spread of misinformation in the early stages of the pandemic in the U.S. | E5: 2020 | F5: Canadian Journal of Political Science | G5: 53 | H5: 2 | J5: 335 | K5: 342 | L5: 341 | M5: 10.1017/S0008423920000396 | N5: https://www.scopus.com/inward/record.uri?eid=2-s2.0-85084363001&doi=10.1017%2FS0008423920000396&partnerID=40&md5=3ce09a13e790658b2882442f7ed652ce | O5: Department of Political Science, Oklahoma State University, Stillwater, OK, United States; University of Pennsylvania Annenberg School for Communications, Philadelphia, PA, United States; Centre for Public Opinion and Political Representation, Simon Fraser University, Burnaby, BC, Canada; Department of Political Science, Carleton College, USA, Northfield, MN, United States | P5: Motta, Matthew P., Department of Political Science, Oklahoma State University, Stillwater, OK, United States; Stecula, Dominik Andrzej, University of Pennsylvania Annenberg School for Communications, Philadelphia, PA, United States, Centre for Public Opinion and Political Representation, Simon Fraser University, Burnaby, BC, Canada; Farhart, Christina E., Department of Political Science, Carleton College, USA, Northfield, MN, United States | Q5: M. Motta; Department of Political Science, Oklahoma State University, 210 Murray Hall, Stillwater, 74078, United States; email: matthew.motta@okstate.edu | S5: Cambridge University Press journals_subscriptions@cup.cam.ac.uk | T5: 84239 | X5: English | Y5: Can. J. Polit. Sci. | Z5: Article | AA5: Final | AB5: All Open Access; Green Final Open Access; Green Open Access; Hybrid Gold Open Access | AC5: Scopus | AD5: 2-s2.0-85084363001
A6: Capano, G.; Howlett, M. | B6: Capano, Giliberto (23767017600); Howlett, Michael P. (7004315057) | C6: 23767017600; 7004315057 | D6: The Knowns and Unknowns of Policy Instrument Analysis: Policy Tools and the Current Research Agenda on Policy Mixes | E6: 2020 | F6: SAGE Open | G6: 10 | H6: 1 | L6: 297 | M6: 10.1177/2158244019900568 | N6: https://www.scopus.com/inward/record.uri?eid=2-s2.0-85078118455&doi=10.1177%2F2158244019900568&partnerID=40&md5=3c1feae0b9dda08d509a37a2b1e1483e | O6: Alma Mater Studiorum Università di Bologna, Bologna, BO, Italy; Simon Fraser University, Burnaby, BC, Canada | P6: Capano, Giliberto, Alma Mater Studiorum Università di Bologna, Bologna, BO, Italy; Howlett, Michael P., Simon Fraser University, Burnaby, BC, Canada | Q6: M. Howlett; Simon Fraser University, Burnaby, Canada; email: howlett@sfu.ca | S6: SAGE Publications Inc. | X6: English | Y6: SAGE Open | Z6: Article | AA6: Final | AB6: All Open Access; Gold Open Access; Green Accepted Open Access; Green Open Access | AC6: Scopus | AD6: 2-s2.0-85078118455
