Workbook

Sheet works2024
A1: id | B1: doi | C1: title | D1: publication_year | E1: publication_date | F1: ids | G1: language | H1: type | I1: countries_distinct_count | J1: institutions_distinct_count | K1: fwci | L1: cited_by_count | M1: citation_normalized_percentile | N1: sustainable_development_goals | O1: counts_by_year
A2: https://openalex.org/W2900744207 | B2: https://doi.org/10.4324/9781003469490-14 | C2: When Social Comparison Goes Awry: The Case of Pluralistic Ignorance | D2: 2024 | E2: 45344 | F2: {'openalex': 'https://openalex.org/W2900744207', 'doi': 'https://doi.org/10.4324/9781003469490-14', 'mag': '2900744207'} | G2: en | H2: book-chapter | I2: 2 | J2: 2 | K2: 149.0051 | L2: 235 | M2: {'value': 0.99980505, 'is_in_top_1_percent': True, 'is_in_top_10_percent': True} | N2: [{'display_name': 'Reduced inequalities', 'id': 'https://metadata.un.org/sdg/10', 'score': 0.7900000214576721}] | O2: [{'year': 2025, 'cited_by_count': 12}, {'year': 2024, 'cited_by_count': 18}, {'year': 2023, 'cited_by_count': 4}, {'year': 2022, 'cited_by_count': 6}, {'year': 2021, 'cited_by_count': 18}, {'year': 2020, 'cited_by_count': 19}, {'year': 2019, 'cited_by_count': 7}, {'year': 2018, 'cited_by_count': 14}, {'year': 2017, 'cited_by_count': 9}, {'year': 2016, 'cited_by_count': 11}, {'year': 2015, 'cited_by_count': 13}, {'year': 2014, 'cited_by_count': 9}, {'year': 2013, 'cited_by_count': 8}, {'year': 2012, 'cited_by_count': 4}]
A3: https://openalex.org/W4402715971 | B3: https://doi.org/10.1109/cvpr52733.2024.01840 | C3: PixelSplat: 3D Gaussian Splats from Image Pairs for Scalable Generalizable 3D Reconstruction | D3: 2024 | E3: 45459 | F3: {'openalex': 'https://openalex.org/W4402715971', 'doi': 'https://doi.org/10.1109/cvpr52733.2024.01840'} | G3: en | H3: article | I3: 2 | J3: 4 | K3: 91.3088 | L3: 142 | M3: {'value': 0.99918467, 'is_in_top_1_percent': True, 'is_in_top_10_percent': True} | N3: [] | O3: [{'year': 2026, 'cited_by_count': 7}, {'year': 2025, 'cited_by_count': 103}, {'year': 2024, 'cited_by_count': 32}]
A4: https://openalex.org/W4392983637 | B4: https://doi.org/10.1016/j.bushor.2024.03.001 | C4: Beware of botshit: How to manage the epistemic risks of generative chatbots | D4: 2024 | E4: 45371 | F4: {'openalex': 'https://openalex.org/W4392983637', 'doi': 'https://doi.org/10.1016/j.bushor.2024.03.001'} | G4: en | H4: article | I4: 3 | J4: 3 | K4: 75.7209 | L4: 93 | M4: {'value': 0.99960221, 'is_in_top_1_percent': True, 'is_in_top_10_percent': True} | N4: [] | O4: [{'year': 2026, 'cited_by_count': 7}, {'year': 2025, 'cited_by_count': 63}, {'year': 2024, 'cited_by_count': 23}]
A5: https://openalex.org/W4392950747 | B5: https://doi.org/10.1016/j.tree.2024.02.004 | C5: Priority effects transcend scales and disciplines in biology | D5: 2024 | E5: 45370 | F5: {'openalex': 'https://openalex.org/W4392950747', 'doi': 'https://doi.org/10.1016/j.tree.2024.02.004', 'pmid': 'https://pubmed.ncbi.nlm.nih.gov/38508922'} | G5: en | H5: article | I5: 6 | J5: 19 | K5: 60.5976 | L5: 52 | M5: {'value': 0.99933431, 'is_in_top_1_percent': True, 'is_in_top_10_percent': True} | N5: [] | O5: [{'year': 2026, 'cited_by_count': 6}, {'year': 2025, 'cited_by_count': 25}, {'year': 2024, 'cited_by_count': 21}]
A6: https://openalex.org/W4401211183 | B6: https://doi.org/10.1126/science.adl2362 | C6: Ecological roles and importance of sharks in the Anthropocene Ocean | D6: 2024 | E6: 45505 | F6: {'openalex': 'https://openalex.org/W4401211183', 'doi': 'https://doi.org/10.1126/science.adl2362', 'pmid': 'https://pubmed.ncbi.nlm.nih.gov/39088608'} | G6: en | H6: review | I6: 8 | J6: 30 | K6: 58.9835 | L6: 83 | M6: {'value': 0.99983356, 'is_in_top_1_percent': True, 'is_in_top_10_percent': True} | N6: [{'display_name': 'Life below water', 'id': 'https://metadata.un.org/sdg/14', 'score': 0.800000011920929}] | O6: [{'year': 2026, 'cited_by_count': 8}, {'year': 2025, 'cited_by_count': 65}, {'year': 2024, 'cited_by_count': 10}]
A7: https://openalex.org/W4398142197 | B7: https://doi.org/10.1080/25741292.2024.2353929 | C7: Calibration and specification in policy practice: Micro-dimensions of policy design | D7: 2024 | E7: 45384 | F7: {'openalex': 'https://openalex.org/W4398142197', 'doi': 'https://doi.org/10.1080/25741292.2024.2353929'} | G7: en | H7: article | I7: 2 | J7: 2 | K7: 57.8277 | L7: 25 | M7: {'value': 0.9989344, 'is_in_top_1_percent': True, 'is_in_top_10_percent': True} | N7: [{'id': 'https://metadata.un.org/sdg/1', 'display_name': 'No poverty', 'score': 0.5600000023841858}] | O7: [{'year': 2026, 'cited_by_count': 2}, {'year': 2025, 'cited_by_count': 20}, {'year': 2024, 'cited_by_count': 3}]
A8: https://openalex.org/W4399666151 | B8: https://doi.org/10.1109/jsac.2024.3414597 | C8: WiShield: Privacy Against Wi-Fi Human Tracking | D8: 2024 | E8: 45457 | F8: {'openalex': 'https://openalex.org/W4399666151', 'doi': 'https://doi.org/10.1109/jsac.2024.3414597'} | G8: en | H8: article | I8: 3 | J8: 8 | K8: 53.6056 | L8: 46 | M8: {'value': 0.99917021, 'is_in_top_1_percent': True, 'is_in_top_10_percent': True} | N8: [] | O8: [{'year': 2026, 'cited_by_count': 1}, {'year': 2025, 'cited_by_count': 44}, {'year': 2024, 'cited_by_count': 1}]
A9: https://openalex.org/W4390658537 | B9: https://doi.org/10.1332/030557321x16841388707452 | C9: Types of learning and varieties of innovation: how does policy learning enable policy innovation? | D9: 2024 | E9: 45299 | F9: {'openalex': 'https://openalex.org/W4390658537', 'doi': 'https://doi.org/10.1332/030557321x16841388707452'} | G9: en | H9: article | I9: 2 | J9: 2 | K9: 50.7781 | L9: 22 | M9: {'value': 0.99851606, 'is_in_top_1_percent': True, 'is_in_top_10_percent': True} | N9: [] | O9: [{'year': 2025, 'cited_by_count': 10}, {'year': 2024, 'cited_by_count': 12}]
A10: https://openalex.org/W4403897136 | B10: https://doi.org/10.1016/j.jcyt.2024.10.008 | C10: Delphi-driven consensus definition for mesenchymal stromal cells and clinical reporting guidelines for mesenchymal stromal cellâ€“based therapeutics | D10: 2024 | E10: 45595 | F10: {'openalex': 'https://openalex.org/W4403897136', 'doi': 'https://doi.org/10.1016/j.jcyt.2024.10.008', 'pmid': 'https://pubmed.ncbi.nlm.nih.gov/39580717'} | G10: en | H10: article | I10: 3 | J10: 24 | K10: 50.1096 | L10: 43 | M10: {'value': 0.99903708, 'is_in_top_1_percent': True, 'is_in_top_10_percent': True} | N10: [] | O10: [{'year': 2026, 'cited_by_count': 6}, {'year': 2025, 'cited_by_count': 37}]
A11: https://openalex.org/W4390718539 | B11: https://doi.org/10.1136/bmj-2023-076336 | C11: Effect of Risk Mitigation Guidance for opioid and stimulant dispensations on mortality and acute care visits during dual public health emergencies: retrospective cohort study | D11: 2024 | E11: 45301 | F11: {'openalex': 'https://openalex.org/W4390718539', 'doi': 'https://doi.org/10.1136/bmj-2023-076336', 'pmid': 'https://pubmed.ncbi.nlm.nih.gov/38199614'} | G11: en | H11: article | I11: 1 | J11: 12 | K11: 47.3804 | L11: 83 | M11: {'value': 0.99942541, 'is_in_top_1_percent': True, 'is_in_top_10_percent': True} | N11: [{'display_name': 'Good health and well-being', 'id': 'https://metadata.un.org/sdg/3', 'score': 0.8799999952316284}] | O11: [{'year': 2026, 'cited_by_count': 4}, {'year': 2025, 'cited_by_count': 42}, {'year': 2024, 'cited_by_count': 37}]
A12: https://openalex.org/W4402742293 | B12: https://doi.org/10.1109/comst.2024.3465447 | C12: Large Language Model (LLM) for Telecommunications: A Comprehensive Survey on Principles, Key Techniques, and Opportunities | D12: 2024 | E12: 45558 | F12: {'openalex': 'https://openalex.org/W4402742293', 'doi': 'https://doi.org/10.1109/comst.2024.3465447'} | G12: en | H12: article | I12: 2 | J12: 14 | K12: 46.9178 | L12: 129 | M12: {'value': 0.99899925, 'is_in_top_1_percent': True, 'is_in_top_10_percent': True} | N12: [] | O12: [{'year': 2026, 'cited_by_count': 11}, {'year': 2025, 'cited_by_count': 97}, {'year': 2024, 'cited_by_count': 21}]
A13: https://openalex.org/W4403842396 | B13: https://doi.org/10.1007/978-3-031-72640-8_10 | C13: MVDiffusion++: A Dense High-Resolution Multi-view Diffusion Model forÂ Single orÂ Sparse-View 3D Object Reconstruction | D13: 2024 | E13: 45593 | F13: {'openalex': 'https://openalex.org/W4403842396', 'doi': 'https://doi.org/10.1007/978-3-031-72640-8_10'} | G13: en | H13: book-chapter | I13: 2 | J13: 9 | K13: 44.785 | L13: 19 | M13: {'value': 0.99767225, 'is_in_top_1_percent': True, 'is_in_top_10_percent': True} | N13: [] | O13: [{'year': 2026, 'cited_by_count': 1}, {'year': 2025, 'cited_by_count': 14}, {'year': 2024, 'cited_by_count': 4}]
... A122: https://openalex.org/W4398236701 | B122: https://doi.org/10.1017/aaq.2024.26 | C122: LÃ­Äºwat Climbers Could See the Ocean from the Peak of QáºƒelqáºƒelÃºsten: Evaluating Oral Traditions with Viewshed Analyses from the Mount Meager Volcanic Complex Prior to Its 2360 BP Eruption | D122: 2024 | E122: 45435 | F122: {'openalex': 'https://openalex.org/W4398236701', 'doi': 'https://doi.org/10.1017/aaq.2024.26'} | G122: en | H122: article | I122: 1 | J122: 5 | K122: 11.9466 | L122: 7 | M122: {'value': 0.98008795, 'is_in_top_1_percent': False, 'is_in_top_10_percent': True} | N122: [{'id': 'https://metadata.un.org/sdg/14', 'score': 0.8700000047683716, 'display_name': 'Life below water'}] | O122: [{'year': 2026, 'cited_by_count': 1}, {'year': 2025, 'cited_by_count': 5}, {'year': 2024, 'cited_by_count': 1}]
A123: https://openalex.org/W4393072836 | B123: https://doi.org/10.1111/sjtg.12539 | C123: Guest Editorial: The social life of Chinese infrastructures in Southeast Asia | D123: 2024 | E123: 45373 | F123: {'openalex': 'https://openalex.org/W4393072836', 'doi': 'https://doi.org/10.1111/sjtg.12539'} | G123: en | H123: editorial | I123: 2 | J123: 2 | K123: 11.940961 | L123: 3 | M123: {'value': 0.9622204, 'is_in_top_1_percent': False, 'is_in_top_10_percent': True} | N123: [{'display_name': 'Industry, innovation and infrastructure', 'id': 'https://metadata.un.org/sdg/9', 'score': 0.5400000214576721}]
A124: https://openalex.org/W4399575743 | B124: https://doi.org/10.1371/journal.pone.0301775 | C124: Agropastoral and dietary practices of the northern Levant facing Late Holocene climate and environmental change: Isotopic analysis of plants, animals and humans from Bronze to Iron Age Tell Tweini | D124: 2024 | E124: 45455 | F124: {'openalex': 'https://openalex.org/W4399575743', 'doi': 'https://doi.org/10.1371/journal.pone.0301775', 'pmid': 'https://pubmed.ncbi.nlm.nih.gov/38865323'} | G124: en | H124: article | I124: 3 | J124: 8 | K124: 11.9315 | L124: 7 | M124: {'value': 0.98033421, 'is_in_top_1_percent': False, 'is_in_top_10_percent': True} | N124: [{'display_name': 'Life below water', 'id': 'https://metadata.un.org/sdg/14', 'score': 0.6700000166893005}] | O124: [{'year': 2025, 'cited_by_count': 6}, {'year': 2024, 'cited_by_count': 1}]
A125: https://openalex.org/W4403650529 | B125: https://doi.org/10.1007/978-3-031-72390-2_33 | C125: TrIND: Representing Anatomical Trees byÂ Denoising Diffusion ofÂ Implicit Neural Fields | D125: 2024 | E125: 45292 | F125: {'openalex': 'https://openalex.org/W4403650529', 'doi': 'https://doi.org/10.1007/978-3-031-72390-2_33'} | G125: en | H125: book-chapter | I125: 1 | J125: 2 | K125: 11.7855 | L125: 5 | M125: {'value': 0.98277467, 'is_in_top_1_percent': False, 'is_in_top_10_percent': True} | N125: [] | O125: [{'year': 2025, 'cited_by_count': 5}]
A126: https://openalex.org/W4402490890 | B126: https://doi.org/10.1017/s0266078424000075 | C126: English-medium education and the perpetuation of girlsâ€™ disadvantage | D126: 2024 | E126: 45536 | F126: {'openalex': 'https://openalex.org/W4402490890', 'doi': 'https://doi.org/10.1017/s0266078424000075'} | G126: en | H126: article | I126: 5 | J126: 11 | K126: 11.6751 | L126: 3 | M126: {'value': 0.98029815, 'is_in_top_1_percent': False, 'is_in_top_10_percent': True} | N126: [{'score': 0.46000000834465027, 'id': 'https://metadata.un.org/sdg/5', 'display_name': 'Gender equality'}] | O126: [{'year': 2025, 'cited_by_count': 3}]
A127: https://openalex.org/W4405178229 | B127: https://doi.org/10.1073/pnas.2404632121 | C127: Early human collective practices and symbolism in the Early Upper Paleolithic of Southwest Asia | D127: 2024 | E127: 45635 | F127: {'openalex': 'https://openalex.org/W4405178229', 'doi': 'https://doi.org/10.1073/pnas.2404632121', 'pmid': 'https://pubmed.ncbi.nlm.nih.gov/39652761'} | G127: en | H127: article | I127: 6 | J127: 26 | K127: 11.6476 | L127: 3 | M127: {'value': 0.98186022, 'is_in_top_1_percent': False, 'is_in_top_10_percent': True} | N127: [] | O127: [{'year': 2025, 'cited_by_count': 3}]
A128: https://openalex.org/W4399031176 | B128: https://doi.org/10.1007/978-3-031-61175-9_1 | C128: Disentangling the Problem Space: A Validated Problem Statement for Sustainability Support Systems | D128: 2024 | E128: 45292 | F128: {'openalex': 'https://openalex.org/W4399031176', 'doi': 'https://doi.org/10.1007/978-3-031-61175-9_1'} | G128: en | H128: book-chapter | I128: 2 | J128: 4 | K128: 11.6162 | L128: 4 | M128: {'value': 0.98370237, 'is_in_top_1_percent': False, 'is_in_top_10_percent': True} | N128: [{'score': 0.41999998688697815, 'id': 'https://metadata.un.org/sdg/12', 'display_name': 'Responsible consumption and production'}] | O128: [{'year': 2025, 'cited_by_count': 3}, {'year': 2024, 'cited_by_count': 1}]
A129: https://openalex.org/W4405097124 | B129: https://doi.org/10.1016/j.ijcci.2024.100708 | C129: Critical Artificial Intelligence literacy: A scoping review and framework synthesis | D129: 2024 | E129: 45632 | F129: {'openalex': 'https://openalex.org/W4405097124', 'doi': 'https://doi.org/10.1016/j.ijcci.2024.100708'} | G129: en | H129: review | I129: 1 | J129: 4 | K129: 11.6114 | L129: 27 | M129: {'value': 0.98522969, 'is_in_top_1_percent': False, 'is_in_top_10_percent': True} | N129: [{'score': 0.8799999952316284, 'id': 'https://metadata.un.org/sdg/4', 'display_name': 'Quality Education'}] | O129: [{'year': 2026, 'cited_by_count': 1}, {'year': 2025, 'cited_by_count': 25}, {'year': 2024, 'cited_by_count': 1}]
A130: https://openalex.org/W4401705192 | B130: https://doi.org/10.1057/s41267-024-00721-7 | C130: Techno-nationalism and cross-border acquisitions in an age of geopolitical rivalry | D130: 2024 | E130: 45523 | F130: {'openalex': 'https://openalex.org/W4401705192', 'doi': 'https://doi.org/10.1057/s41267-024-00721-7'} | G130: en | H130: article | I130: 1 | J130: 4 | K130: 11.5663 | L130: 20 | M130: {'value': 0.98359626, 'is_in_top_1_percent': False, 'is_in_top_10_percent': True} | N130: [] | O130: [{'year': 2026, 'cited_by_count': 7}, {'year': 2025, 'cited_by_count': 13}]
A131: https://openalex.org/W4399640511 | B131: https://doi.org/10.1007/s10567-024-00490-7 | C131: What is Parental Monitoring? | D131: 2024 | E131: 45444 | F131: {'openalex': 'https://openalex.org/W4399640511', 'doi': 'https://doi.org/10.1007/s10567-024-00490-7', 'pmid': 'https://pubmed.ncbi.nlm.nih.gov/38869680'} | G131: en | H131: review | I131: 2 | J131: 12 | K131: 11.5102 | L131: 17 | M131: {'value': 0.98990633, 'is_in_top_1_percent': False, 'is_in_top_10_percent': True} | N131: [] | O131: [{'year': 2025, 'cited_by_count': 10}, {'year': 2024, 'cited_by_count': 7}]
A132: https://openalex.org/W4393316810 | B132: https://doi.org/10.1111/jopy.12929 | C132: Diversity in singlehood experiences: Testing an attachment theory model of subâ€groups of singles | D132: 2024 | E132: 45380 | F132: {'openalex': 'https://openalex.org/W4393316810', 'doi': 'https://doi.org/10.1111/jopy.12929', 'pmid': 'https://pubmed.ncbi.nlm.nih.gov/38549507'} | G132: en | H132: article | I132: 2 | J132: 4 | K132: 11.4547 | L132: 17 | M132: {'value': 0.98802159, 'is_in_top_1_percent': False, 'is_in_top_10_percent': True} | N132: [{'id': 'https://metadata.un.org/sdg/10', 'display_name': 'Reduced inequalities', 'score': 0.5799999833106995}] | O132: [{'year': 2026, 'cited_by_count': 1}, {'year': 2025, 'cited_by_count': 12}, {'year': 2024, 'cited_by_count': 4}]
A133: https://openalex.org/W4401883861 | B133: https://doi.org/10.1108/edi-10-2023-0335 | C133: Beyond the resume: HR studentsâ€™ evaluations of interview performances by first and second language speakers | D133: 2024 | E133: 45530 | F133: {'openalex': 'https://openalex.org/W4401883861', 'doi': 'https://doi.org/10.1108/edi-10-2023-0335'} | G133: en | H133: article | I133: 2 | J133: 5 | K133: 11.452 | L133: 4 | M133: {'value': 0.98349291, 'is_in_top_1_percent': False, 'is_in_top_10_percent': True} | N133: [{'score': 0.5699999928474426, 'display_name': 'Reduced inequalities', 'id': 'https://metadata.un.org/sdg/10'}] | O133: [{'year': 2026, 'cited_by_count': 1}, {'year': 2025, 'cited_by_count': 1}, {'year': 2024, 'cited_by_count': 2}]
A134: https://openalex.org/W4402266216 | B134: https://doi.org/10.1371/journal.pone.0306813 | C134: Overfishing and climate change elevate extinction risk of endemic sharks and rays in the southwest Indian Ocean hotspot | D134: 2024 | E134: 45540 | F134: {'openalex': 'https://openalex.org/W4402266216', 'doi': 'https://doi.org/10.1371/journal.pone.0306813', 'pmid': 'https://pubmed.ncbi.nlm.nih.gov/39236015'} | G134: en | H134: article | I134: 7 | J134: 20 | K134: 11.3927 | L134: 17 | M134: {'value': 0.98976365, 'is_in_top_1_percent': False, 'is_in_top_10_percent': True} | N134: [] | O134: [{'year': 2026, 'cited_by_count': 3}, {'year': 2025, 'cited_by_count': 13}, {'year': 2023, 'cited_by_count': 1}]
A135: https://openalex.org/W4399366865 | B135: https://doi.org/10.1016/j.cub.2024.05.019 | C135: Maternal investment evolves with larger body size and higher diversification rate in sharks and rays | D135: 2024 | E135: 45444 | F135: {'openalex': 'https://openalex.org/W4399366865', 'doi': 'https://doi.org/10.1016/j.cub.2024.05.019'} | G135: en | H135: article | I135: 2 | J135: 4 | K135: 11.3703 | L135: 18 | M135: {'value': 0.98951442, 'is_in_top_1_percent': False, 'is_in_top_10_percent': True} | N135: [] | O135: [{'year': 2026, 'cited_by_count': 1}, {'year': 2025, 'cited_by_count': 12}, {'year': 2024, 'cited_by_count': 3}, {'year': 2023, 'cited_by_count': 1}, {'year': 2022, 'cited_by_count': 1}]
... A2128: https://openalex.org/W4392093461 | B2128: https://doi.org/10.1139/cjfas-2023-0306 | C2128: Forestry and stream temperatures: a response to comment by R.D. Moore | D2128: 2024 | E2128: 45345 | F2128: {'openalex': 'https://openalex.org/W4392093461', 'doi': 'https://doi.org/10.1139/cjfas-2023-0306'} | G2128: en | H2128: article | I2128: 1 | J2128: 4 | K2128: 0 | L2128: 0 | M2128: {'value': 0.01542486, 'is_in_top_1_percent': False, 'is_in_top_10_percent': False} | N2128: [{'display_name': 'Life in Land', 'id': 'https://metadata.un.org/sdg/15', 'score': 0.46000000834465027}] | O2128: []
A2129: https://openalex.org/W4392094683 | B2129: https://doi.org/10.1016/j.psyneuen.2023.106846 | C2129: =- Beyond the limited evidence for an association between childhood maltreatment and DNA methylation: the moderating role of genetic sensitivity to the environment -> #NAME? | D2129: 2024 | E2129: 45323 | F2129: {'openalex': 'https://openalex.org/W4392094683', 'doi': 'https://doi.org/10.1016/j.psyneuen.2023.106846'} | G2129: en | H2129: article | I2129: 1 | J2129: 10 | K2129: 0 | L2129: 0 | M2129: {'value': 0.02909351, 'is_in_top_1_percent': False, 'is_in_top_10_percent': False} | N2129: [] | O2129: []
A2130: https://openalex.org/W4392112157 | B2130: https://doi.org/10.1016/j.psyneuen.2023.106844 | C2130: =- Sensitization Effect of Perinatal Adversity on the association between Cumulative childhood and Adolescence Adversity and a Polyepigenetic Stress Score at the End of Adolescence: a Prospective Study -> #NAME? | D2130: 2024 | E2130: 45323 | F2130: {'openalex': 'https://openalex.org/W4392112157', 'doi': 'https://doi.org/10.1016/j.psyneuen.2023.106844'} | G2130: en | H2130: article | I2130: 1 | J2130: 1 | K2130: 0 | L2130: 0 | M2130: {'value': 0.03200094, 'is_in_top_1_percent': False, 'is_in_top_10_percent': False} | N2130: [] | O2130: []
A2131: https://openalex.org/W4392121382 | B2131: https://doi.org/10.1016/j.psyneuen.2023.106913 | C2131: Sensitization Effect of Perinatal Adversity on the Association Between Cumulative Childhood and Adolescence Adversity and a Polyepigenetic Stress Score at the End of Adolescence: A Prospective Study | D2131: 2024 | E2131: 45323 | F2131: {'openalex': 'https://openalex.org/W4392121382', 'doi': 'https://doi.org/10.1016/j.psyneuen.2023.106913'} | G2131: en | H2131: article | I2131: 1 | J2131: 5 | K2131: 0 | L2131: 0 | M2131: {'value': 0.0304958, 'is_in_top_1_percent': False, 'is_in_top_10_percent': False} | N2131: [] | O2131: []
A2132: https://openalex.org/W4392155912 | B2132: https://doi.org/10.54210/bj.2024.1110 | C2132: Good (virtual) grief: The potential of online communities for bereaved older adults during Covid-19 | D2132: 2024 | E2132: 45344 | F2132: {'openalex': 'https://openalex.org/W4392155912', 'doi': 'https://doi.org/10.54210/bj.2024.1110'} | G2132: en | H2132: article | I2132: 1 | J2132: 2 | K2132: 0 | L2132: 0 | M2132: {'value': 0.03065205, 'is_in_top_1_percent': False, 'is_in_top_10_percent': False} | N2132: [] | O2132: []
A2133: https://openalex.org/W4392169274 | B2133: https://doi.org/10.1103/physrevresearch.6.013204 | C2133: Characterization and optimized engineering of bosonic quantum interfaces under single-mode operational constraints | D2133: 2024 | E2133: 45348 | F2133: {'openalex': 'https://openalex.org/W4392169274', 'doi': 'https://doi.org/10.1103/physrevresearch.6.013204'} | G2133: en | H2133: article | I2133: 2 | J2133: 3 | K2133: 0 | L2133: 0 | M2133: {'value': 0.01505652, 'is_in_top_1_percent': False, 'is_in_top_10_percent': False} | N2133: [] | O2133: []
A2134: https://openalex.org/W4392174233 | B2134: https://doi.org/10.1007/978-981-97-0523-8_54 | C2134: Analysis and Forecast of USD/EUR Exchange Rate Based on ARIMA and GARCH Models | D2134: 2024 | E2134: 45292 | F2134: {'openalex': 'https://openalex.org/W4392174233', 'doi': 'https://doi.org/10.1007/978-981-97-0523-8_54'} | G2134: en | H2134: book-chapter | I2134: 3 | J2134: 3 | K2134: 0 | L2134: 0 | M2134: {'value': 0.08225806, 'is_in_top_1_percent': False, 'is_in_top_10_percent': False} | N2134: [] | O2134: []
A2135: https://openalex.org/W4392294111 | B2135: https://doi.org/10.1177/02697580241232436 | C2135: Towards a multifactorial framework of the Romaâ€™s victimisation: Discrimination, risky situations, and acceptance of violence as correlates of physical assault and harassment | D2135: 2024 | E2135: 45351 | F2135: {'openalex': 'https://openalex.org/W4392294111', 'doi': 'https://doi.org/10.1177/02697580241232436'} | G2135: en | H2135: article | I2135: 3 | J2135: 4 | K2135: 0 | L2135: 0 | M2135: {'value': 0.04142418, 'is_in_top_1_percent': False, 'is_in_top_10_percent': False} | N2135: [{'display_name': 'Peace, Justice and strong institutions', 'id': 'https://metadata.un.org/sdg/16', 'score': 0.5799999833106995}] | O2135: []
A2136: https://openalex.org/W4392295921 | B2136: https://doi.org/10.1037/tmb0000125.supp | C2136: Supplemental Material for Smartphones Undermine Social Connectedness More in Men Than Women: A Mini Mega-Analysis | D2136: 2024 | E2136: 45292 | F2136: {'openalex': 'https://openalex.org/W4392295921', 'doi': 'https://doi.org/10.1037/tmb0000125.supp'} | G2136: en | H2136: article | I2136: 2 | J2136: 3 | K2136: 0 | L2136: 0 | M2136: {'value': 0.03358903, 'is_in_top_1_percent': False, 'is_in_top_10_percent': False} | N2136: [{'display_name': 'Gender equality', 'id': 'https://metadata.un.org/sdg/5', 'score': 0.4399999976158142}] | O2136: []
A2137: https://openalex.org/W4392305793 | B2137: https://doi.org/10.5220/0012351300003654 | C2137: Military Badge Detection and Classification Algorithm for Automatic Processing of Documents | D2137: 2024 | E2137: 45292 | F2137: {'openalex': 'https://openalex.org/W4392305793', 'doi': 'https://doi.org/10.5220/0012351300003654'} | G2137: en | H2137: article | I2137: 1 | J2137: 3 | K2137: 0 | L2137: 0 | M2137: {'value': 0.02603913, 'is_in_top_1_percent': False, 'is_in_top_10_percent': False} | N2137: [] | O2137: []
A2138: https://openalex.org/W4392342931 | B2138: https://doi.org/10.18806/tesl.v40i1/1384 | C2138: Multisemiotics, Race, and Academic Literacies | D2138: 2024 | E2138: 45354 | F2138: {'openalex': 'https://openalex.org/W4392342931', 'doi': 'https://doi.org/10.18806/tesl.v40i1/1384'} | G2138: en | H2138: article | I2138: 1 | J2138: 2 | K2138: 0 | L2138: 0 | M2138: {'value': 0.02790536, 'is_in_top_1_percent': False, 'is_in_top_10_percent': False} | N2138: [{'display_name': 'Quality Education', 'id': 'https://metadata.un.org/sdg/4', 'score': 0.8500000238418579}] | O2138: []
A2139: https://openalex.org/W4392343223 | B2139: https://doi.org/10.18806/tesl.v40i1/1381 | C2139: Second Language Writing in Canada | D2139: 2024 | E2139: 45354 | F2139: {'openalex': 'https://openalex.org/W4392343223', 'doi': 'https://doi.org/10.18806/tesl.v40i1/1381'} | G2139: en | H2139: article | I2139: 1 | J2139: 3 | K2139: 0 | L2139: 0 | M2139: {'value': 0.03112805, 'is_in_top_1_percent': False, 'is_in_top_10_percent': False} | N2139: [{'display_name': 'Quality Education', 'id': 'https://metadata.un.org/sdg/4', 'score': 0.8700000047683716}] | O2139: []
A2140: https://openalex.org/W4392351102 | B2140: https://doi.org/10.1038/s44183-024-00051-z | C2140: Author Correction: Targeting ocean conservation outcomes through threat reduction | D2140: 2024 | E2140: 45353 | F2140: {'openalex': 'https://openalex.org/W4392351102', 'doi': 'https://doi.org/10.1038/s44183-024-00051-z'} | G2140: en | H2140: article | I2140: 7 | J2140: 14 | K2140: 0 | L2140: 0 | M2140: {'value': 0.02982918, 'is_in_top_1_percent': False, 'is_in_top_10_percent': False} | N2140: [{'display_name': 'Life below water', 'id': 'https://metadata.un.org/sdg/14', 'score': 0.49000000953674316}] | O2140: []
...

Sheet rio results
A1: Title | B1: Authors | C1: Number of Authors | D1: Scopus Author Ids | E1: Year | F1: Full date | G1: Scopus Source title | H1: Language | I1: Citations | J1: Field-Weighted Citation Impact | K1: DOI | L1: Publication type | M1: Open Access | N1: Institutions | O1: Number of Institutions | P1: Scopus Affiliation IDs | Q1: Scopus Affiliation names | R1: Scopus Author ID First Author | S1: Scopus Author ID Last Author | T1: Scopus Author ID Corresponding Author | U1: Scopus Author ID Single Author | V1: Country/Region | W1: Topic Cluster name | X1: Topic name
A2: “Real impact”: Challenges and opportunities in bridging the gap between research and practice – Making a difference in industry, policy, and society | B2: Dwivedi, Y.K.| Jeyaraj, A.| Hughes, L.| Davies, G.H.| Ahuja, M.| Albashrawi, M.A.| Al-Busaidi, A.S.| Al-Sharhan, S.| Al-Sulaiti, K.I.| Altinay, L.| Amalaya, S.| Archak, S.| Ballestar, M.T.| Bhagwat, S.A.| Bharadwaj, A.| Bhushan, A.| Bose, I.| Budhwar, P.| Bunker, D.| Capatina, A.| Carter, L.| Constantiou, I.| Coombs, C.| Crick, T.| Csáki, C.| Darnige, Y.| Dé, R.| Delbridge, R.| Dubey, R.| Gauld, R.| Gutti, R.K.| Hattingh, M.| Haug, A.| Hendricks, L.| Hino, A.| Hsu, C.H.C.| Iivari, N.| Janssen, M.| Jebabli, I.| Jones, P.| Junglas, I.| Kaushik, A.| Khazanchi, D.| Kodama, M.| Kraus, S.| Kumar, V.| Maier, C.| Malik, T.| Matthee, M.| McCarthy, I.P.| Meier, M.| Metri, B.| Micu, A.| Micu, A.-E.| Misra, S.K.| Mishra, A.| Molin-Juustila, T.| Oppermann, L.| O'Regan, N.| Pal, A.| Pandey, N.| Pappas, I.O.| Parker, A.| Pathak, K.| Pienta, D.| Polyviou, A.| Raman, R.| Ribeiro-Navarrete, S.| Ritala, P.| Rosemann, M.| Sarker, S.| Saxena, P.| Schlagwein, D.| Schultze, H.| Sharma, C.| Sharma, S.K.| Simintiras, A.| Singh, V.K.| Smuts, H.| Soldatos, J.| Tiwari, M.K.| Thatcher, J.B.| Vanberghen, C.| Varga, Á.| Vassilakopoulou, P.| Venkatesh, V.| Viglia, G.| Vorley, T.| Wade, M.| Walton, P. | C2: 90 | D2: 35239818900| 16426012500| 57205405210| 57199302634| 7101943053| 57188808764| 55633735500| 6602231773| 57191046640| 6507918447| 58743115600| 14919251500| 57024150400| 56207846800| 7004584448| 58862220500| 52663129200| 6701694690| 15520858500| 35209737400| 7201576525| 12141851800| 7003564476| 14032736300| 36447492200| 58861222200| 14011831800| 6701780449| 36991875200| 6701641862| 15755463000| 54935562100| 57788631900| 57678650900| 54388937800| 7404947039| 22979790000| 16199813000| 56274399100| 55523712300| 22979521800| 58709804800| 6506490534| 55624713900| 57207720523| 57212901290| 35366765400| 58776832300| 36912599800| 57210460027| 57326260300| 14071708100| 58355484100| 35211557400| 57898178300| 57203177364| 33867644000| 15045267400| 6603501742| 57193541504| 57813546700| 55387371600| 57213532596| 58862957700| 57194239065| 55604816600| 55808097300| 56676383100| 24778958800| 6701701206| 35611469700| 58861470600| 37013671400| 9633409300| 59860576800| 58263883500| 6507763214| 57908232100| 35303384200| 8662280800| 60105149700| 7006547020| 58148049100| 24178030000| 36605482100| 35614985000| 41961835900| 23394080600| 7201453261| 59849258600 | E2: 2024 | F2: 45566 | G2: International Journal of Information Management | H2: English | I2: 60 | J2: 73.65 | K2: 10.1016/j.ijinfomgt.2023.102750 | L2: Editorial | M2: Green | N2: King Fahd University of Petroleum and Minerals| Temple University| Fraunhofer Institute for Applied Information Technology| Corvinus University of Budapest| Hong Kong Polytechnic University| Libera Universita Internazionale degli Studi Sociali Guido Carli| Indian Institute of Management Mumbai| Delft University of Technology| Universidad Rey Juan Carlos| University of Bamberg| Loughborough University| Swansea University| Lappeenranta-Lahti University of Technology| European University Institute, San Domenico di Fiesole| Norwegian University of Science and Technology| University of Tennessee, Knoxville| Liverpool John Moores University| Aston University| Virginia Polytechnic Institute and State University| University of Nebraska Omaha| Sultan Qaboos University| Indian Institute of Management Bangalore| ESIC| Management Center Innsbruck| Copenhagen Business School| University of Hyderabad| International University of Rabat| University of Portsmouth| International Institute for Management Development| University of Pretoria| Ovidius University of Constanta| Indian Institute of Management Calcutta| University of Oulu| Oxford Brookes University| University of Otago| Dunarea de Jos University of Galati| University of Sydney| Wright State University| Indian Institute of Management Nagpur| Jaipuria Institute of Management, Lucknow| Cyprus University of Technology| Indian Institute of Management Ahmedabad| University of Oxford| University of Economics and Human Sciences in Warsaw| University of Johannesburg| BASF| ICAR - National Bureau of Plant Genetic Resources| University of Agder| European Commission| Cardiff University| Simon Fraser University| University of Tennessee System| Free University of Bozen-Bolzano| Queensland University of Technology| Symbiosis International University| University of Siegen| College of Charleston| Nihon University| University of Louisville| Waseda University| Emory University| Dundalk Institute of Technology| Edith Cowan University| University of Virginia| Open University Milton Keynes| Montpellier Business School | O2: 66 | P2: 60004572| 60170469| 60104400| 60018306| 60105210| 60020633| 60212277| 60009506| 60071768| 60280380| 60281944| 60160406| 60014564| 113062318| 60012678| 60018940| 60012113| 60116269| 60000928| 126380484| 60033308| 60116225| 125711596| 60025709| 60008717| 60212023| 60020188| 60116333| 60000891| 60001434| 130822119| 60071271| 60023998| 60170149| 60112781| 60028355| 60170411| 60109020| 60100347| 60017311| 60029516| 60021902| 128322922| 130822134| 60004100| 60023462| 60086490| 60008928| 60012954| 60117886| 60006288| 60111570| 60013340| 60015938| 60018988| 60002561| 60009914| 60000717| 128388341| 60011372| 60018491| 60016374| 60115581| 60023386| 60097670| 60002596| 60070899| 60022123| 60080184| 60013141| 60026867| 60026851| 101703527| 60015574| 60116456| 60077474| 60103620| 60268510| 60226620| 60014304| 60011019| 60021918| 60007616| 130821208| 60024260| 130821966| 60030398| 60122660| 60024316| 60029640| 60019299| 60027090| 60025475| 101885340| 60067221| 123054520 | Q2: Swansea University| School of Management| Symbiosis International (Deemed University)| Wright State University| Edith Cowan University| University of Louisville| KFUPM Business School| King Fahd University of Petroleum and Minerals| Sultan Qaboos University| International University of Science and Technology in Kuwait (IUK)| Al Rayyan International University College| Oxford Brookes Business School| Oxford Brookes University| KPMG| ICAR - National Bureau of Plant Genetic Resources, New Delhi| Universidad Rey Juan Carlos| The Open University| Goizueta Business School| Emory University| Bank Muscat SAOG| Indian Institute of Management Ahmedabad| Aston Business School| Natural Hazards Research Australia| The University of Sydney| Universitatea Dunarea de Jos din Galati| The University of Sydney Business School| Copenhagen Business School| Loughborough University, School of Business and Economics| Loughborough University| Budapesti Corvinus Egyetem| Data & Artificial Intelligence Practice Director| Indian Institute of Management Bangalore| Cardiff University| Cardiff Business School| Montpellier Business School| Liverpool John Moores University| Liverpool Business School| Otago Business School| Otago Medical School| University of Otago| University of Hyderabad| University of Pretoria| Norwegian Labour and Welfare Administration (NAV)| Chief Marketing Officer (CMO)| MCI - The Entrepreneurial School| Waseda University| School of Hotel and Tourism Management, The Hong Kong Polytechnic University| The Hong Kong Polytechnic University| Oulun Yliopisto| Faculteit Techniek, Bestuur en Management, TU Delft| Delft University of Technology| International University of Rabat| College of Charleston| Dundalk Institute of Technology| University of Nebraska Omaha| Nihon University| Free University of Bozen-Bolzano| University of Johannesburg| SRV Media Private Ltd| Universität Bamberg| Simon Fraser University| LUISS University| Indian Institute of Management Nagpur| Ovidius University of Constanta| Jaipuria Institute of Management, Lucknow| Fraunhofer Institute for Applied Information Technology FIT| Indian Institute of Management Calcutta| Indian Institute of Management Mumbai| Universitetet i Agder| Norges Teknisk-Naturvitenskapelige Universitet| Green Templeton College| University of Oxford| Somerset House| The University of Tennessee, Knoxville| Haslam College of Business| Cyprus University of Technology| VIZJA University| ESIC University| LUT kauppakorkeakoulu| LUT University| Queensland University of Technology| University of Virginia| BASF SE| IT Strategy & Transformation Professional| Universität Siegen| Innov-acts Ltd| Temple University| Fox School of Business| European University Institute, San Domenico di Fiesole| European Commission| Virginia Tech, Pamplin College of Business| Virginia Polytechnic Institute and State University| University of Portsmouth| University of Aosta Valley| International Institute for Management Development, Lausanne| Capgemini UK Ltd | R2: 35239818900 | S2: 59849258600 | T2: 35239818900 | U2: - | V2: Austria| Spain| Hong Kong| Denmark| Romania| Hungary| Qatar| Belgium| Ireland| Poland| United States| Germany| Saudi Arabia| Switzerland| Netherlands| New Zealand| India| United Kingdom| Oman| Japan| Finland| South Africa| Morocco| Italy| France| Cyprus| Norway| Australia| Kuwait| Canada | W2: Sustainable Development in Higher Education Practices | X2: Transforming Management Education for Business Relevance
A3: Trust in Generative AI among Students: An exploratory study | B3: Amoozadeh, M.| Daniels, D.| Nam, D.| Kumar, A.| Chen, S.| Hilton, M.| Srinivasa Ragavan, S.| Alipour, M.A. | C3: 8 | D3: 58669011600| 58668959400| 57200512561| 58745732300| 58950677000| 56754178400| 57188555414| 55342288200 | E3: 2024 | F3: 45358 | G3: SIGCSE 2024 - Proceedings of the 55th ACM Technical Symposium on Computer Science Education | H3: English | I3: 71 | J3: 46.65 | K3: 10.1145/3626252.3630842 | L3: Conference Paper | N3: Simon Fraser University| Indian Institute of Technology Kanpur| Carnegie Mellon University| University of Houston | O3: 4 | P3: 60005837| 60018491| 60027950| 60021988 | Q3: University of Houston| Simon Fraser University| Carnegie Mellon University| Indian Institute of Technology Kanpur | R3: 58669011600 | S3: 55342288200 | T3: - | U3: - | V3: India| United States| Canada | W3: Integration of Robotics and Computational Thinking in Education | X3: Enhancing Programming Education through Collaborative Learning
A4: PixelSplat: 3D Gaussian Splats from Image Pairs for Scalable Generalizable 3D Reconstruction | B4: Charatan, D.| Li, S.L.| Tagliasacchi, A.| Sitzmann, V. | C4: 4 | D4: 57222107728| 59058332700| 25123272600| 57195995941 | E4: 2024 | F4: 45292 | G4: Proceedings of the IEEE Computer Society Conference on Computer Vision and Pattern Recognition | H4: English | I4: 127 | J4: 43.9 | K4: 10.1109/CVPR52733.2024.01840 | L4: Conference Paper | N4: Simon Fraser University| Massachusetts Institute of Technology| University of Toronto | O4: 3 | P4: 60022195| 60018491| 60016849 | Q4: Massachusetts Institute of Technology| Simon Fraser University| University of Toronto | R4: 57222107728 | S4: 57195995941 | T4: - | U4: - | V4: United States| Canada | W4: Image Segmentation, Deep Neural Networks and Object Detection | X4: Neural Representations for 3D Shape Reconstruction
A5: When Social Comparison Goes Awry: The Case of Pluralistic Ignorance | B5: Miller, D.T.| McFarland, C. | C5: 2 | D5: 24547388400| 7006712946 | E5: 2024 | F5: 45292 | G5: Social Comparison: Contemporary Theory and Research | H5: English | I5: 156 | J5: 41.93 | K5: 10.4324/9781003469490-14 | L5: Chapter | N5: Simon Fraser University| Princeton University | O5: 2 | P5: 60003269| 60018491 | Q5: Princeton University| Simon Fraser University | R5: 24547388400 | S5: 7006712946 | T5: - | U5: - | V5: United States| Canada | W5: - | X5: -
A6: The Human Phenotype Ontology in 2024: phenotypes around the world | B6: Gargano, M.A.| Matentzoglu, N.| Coleman, B.| Addo-Lartey, E.B.| Anagnostopoulos, A.V.| Anderton, J.| Avillach, P.| Bagley, A.M.| Bakštein, E.| Balhoff, J.P.| Baynam, G.| Bello, S.M.| Berk, M.| Bertram, H.| Bishop, S.| Blau, H.| Bodenstein, D.F.| Botas, P.| Boztug, K.| Čady, J.| Callahan, T.J.| Cameron, R.| Carbon, S.J.| Castellanos, F.| Caufield, J.H.| Chan, L.E.| Chute, C.G.| Cruz-Rojo, J.| Dahan-Oliel, N.| Davids, J.R.| Dieuleveult, M.| Souza, V.| de Vries, B.B.A.| Vries, E.| DePaulo, J.R.| Derfalvi, B.| Dhombres, F.| Diaz-Byrd, C.| Dingemans, A.J.M.| Donadille, B.| Duyzend, M.| Elfeky, R.| Essaid, S.| Fabrizzi, C.| Fico, G.| Firth, H.V.| Freudenberg-Hua, Y.| Fullerton, J.M.| Gabriel, D.L.| Gilmour, K.| Giordano, J.| Goes, F.S.| Moses, R.G.| Green, I.| Griese, M.| Groza, T.| Gu, W.| Guthrie, J.| Gyori, B.| Hamosh, A.| Hanauer, M.| Hanušová, K.| He, Y.| Hegde, H.| Helbig, I.| Holasová, K.| Hoyt, C.T.| Huang, S.| Hurwitz, E.| Jacobsen, J.O.B.| Jiang, X.| Joseph, L.| Keramatian, K.| King, B.| Knoflach, K.| Koolen, D.A.| Kraus, M.L.| Kroll, C.| Kusters, M.| Ladewig, M.S.| Lagorce, D.| Lai, M.-C.| Lapunzina, P.| Laraway, B.| Lewis-Smith, D.| Li, X.| Lucano, C.| Majd, M.| Marazita, M.L.| Martinez-Glez, V.| McHenry, T.H.| McInnis, M.G.| McMurry, J.A.| Mihulová, M.| Millett, C.E.| Mitchell, P.B.| Moslerová, V.| Narutomi, K.| Nematollahi, S.| Nevado, J.| Nierenberg, A.A.| Čajbiková, N.N.| Nurnberger, J.I.| Ogishima, S.| Olson, D.| Ortiz, A.| Pachajoa, H.| Nanclares, G.P.| Peters, A.| Putman, T.| Rapp, C.K.| Rath, A.| Reese, J.| Rekerle, L.| Roberts, A.M.| Roy, S.| Sanders, S.J.| Schuetz, C.| Schulte, E.C.| Schulze, T.G.| Schwarz, M.| Scott, K.| Seelow, D.| Seitz, B.| Shen, Y.| Similuk, M.N.| Simon, E.S.| Singh, B.| Smedley, D.| Smith, C.L.| Smolinsky, J.T.| Sperry, S.| Stafford, E.| Stefancsik, R.| Steinhaus, R.| Strawbridge, R.| Sundaramurthi, J.C.| Talapova, P.| Castano, J.A.T.| Tesner, P.| Thomas, R.H.| Thurm, A.| Turnovec, M.| van Gijn, M.E.| Vasilevsky, N.A.| Vlčková, M.| Walden, A.| Wang, K.| Wapner, R.| Ware, J.S.| Wiafe, A.A.| Wiafe, S.A.| Wiggins, L.D.| Williams, A.E.| Wu, C.| Wyrwoll, M.J.| Xiong, H.| Yalin, N.| Yamamoto, Y.| Yatham, L.N.| Yocum, A.K.| Young, A.H.| Yüksel, Z.| Zandi, P.P.| Zankl, A.| Zarante, I.| Zvolský, M.| Toro, S.| Carmody, L.C.| Harris, N.L.| Munoz-Torres, M.C.| Danis, D.| Mungall, C.J.| Köhler, S.| Haendel, M.A.| Robinson, P.N. | C6: 176 | D6: 57205369227| 55995233100| 57223987007| 58799366900| 7005821953| 55358983700| 23972137300| 6701402791| 43060996500| 8637283900| 14324494700| 7004458522| 56760657800| 55555286200| 57218540916| 57205368715| 57212143319| 56266713000| 23472047500| 58799397700| 57192690777| 57454524400| 25959932700| 57209759767| 55329017200| 57215269031| 7006581202| 23492044500| 26666618400| 7006137984| 58865254600| 58865185400| 35459485900| 58865118700| 7004398249| 6506801256| 17134972700| 57482295200| 6603889334| 24375975100| 54683806700| 55645792800| 55995422800| 58799484300| 57199166504| 7003796141| 23099581700| 57213535028| 36975473900| 7006078464| 57191251562| 7004026363| 58799549800| 58799456700| 55139651700| 19638535200| 58799456800| 58559518000| 55892870500| 7003914063| 57200751247| 58345021100| 7404942594| 57202943644| 57201570366| 58799367500| 56305849200| 58799367600| 58705407200| 25932216600| 58799367700| 48061091300| 14060234300| 59029143100| 57221544436| 8893458500| 58540254500| 58799340600| 26434305600| 14015783100| 24171041300| 57211913020| 57214815403| 37761873400| 56974503600| 59886894800| 58345021200| 55533211300| 7006257137| 12763977000| 58799519200| 35353379600| 8308311600| 58799549900| 57194229387| 35354747000| 57200797157| 58799340800| 56131232500| 36780200300| 35375901700| 57888342900| 35353542700| 6507241005| 58323199700| 35741445300| 15122879800| 58865053600| 46761435000| 55323268400| 57221545272| 24333249100| 15048513900| 58071887800| 57199237342| 58799368100| 36119091700| 20436954100| 7102698477| 57203081336| 57198058697| 57933616500| 6506423915| 57203053329| 58799550100| 56912268600| 12765090200| 7405639065| 57796361900| 8048773500| 58799427600| 55764250300| 57526401400| 6506725443| 57205417508| 56208851700| 24492599800| 57224945780| 57219242030| 57201985741| 14326449800| 57217332348| 55537473200| 8586593500| 40361488700| 36446872600| 16308434500| 55547129985| 35391056000| 59300332000| 58799519400| 57221544936| 15046143700| 57225966673| 58799368200| 57193909400| 58799485000| 55858911500| 55476303500| 35431694500| 8980819000| 7403881797| 55385641300| 6701475820| 55803046800| 56055885100| 58123331100| 6603093413| 6603002819| 57188535624| 21934921800| 57209446724| 6602880619| 23980415100| 57619638300| 7403719646 | E6: 2024 | F6: 45296 | G6: Nucleic Acids Research | H6: English | I6: 173 | J6: 37.25 | K6: 10.1093/nar/gkad1005 | L6: Article | M6: Gold|Green | N6: Harvard University| European Molecular Biology Laboratory| Massachusetts General Hospital| Medical Research Council| National Institute of Mental Health| Dalhousie University| Great Ormond Street Hospital for Children NHS Foundation Trust| Lawrence Berkeley National Laboratory| University of Colorado Anschutz Medical Campus| Rutgers - The State University of New Jersey, New Brunswick| University College London| University of Michigan, Ann Arbor| University of Pittsburgh| Northeastern University| University of New South Wales| Tohoku University| Technische Universität Dresden| SUNY Upstate Medical University| University of North Carolina at Chapel Hill| Universidad Javeriana| Instituto de Salud Carlos III| Jackson Laboratory| University of Vienna| University of Edinburgh| Charité – Universitätsmedizin Berlin| Université Paris 13| Sorbonne Université| Indiana University Bloomington| King's College London| Queen Mary University of London| Neuroscience Research Australia| McGill University| Northwell Health System| Deakin University| The Children's Hospital of Philadelphia| Radboud University Nijmegen| Hôpital Armand Trousseau| Hospital Universitario La Paz| Institut national de la santé et de la recherche médicale| Bioscientia Institut für Medizinische Diagnostik GmbH| Universidad ICESI| National Institutes of Health| Ludwig Maximilian University of Munich| University of Sydney| Assistance publique – Hôpitaux de Paris| Newcastle University| University of Pennsylvania| Imperial College London| Brigham and Women’s Hospital| Research Organization of Information and Systems| University of Oxford| Joint Support-Center for Data Science Research| Hospital Universitario 12 de Octubre| Max F. Perutz Laboratories| Children's Cancer Research Institute| Johns Hopkins University| Simon Fraser University| Vienna Biocenter| Columbia University| University of Toronto| South London and Maudsley NHS Foundation Trust| Medical University of Vienna| University of California at San Francisco| United States Department of Energy| Mayo Clinic Rochester, MN| University of Groningen| Shriners Hospitals for Children| University of British Columbia| Centers for Disease Control and Prevention| University of Marburg| Barwon Health| Cambridge University Hospitals NHS Foundation Trust| Hospital Universitario Araba| Charles University| Centro de Investigación Biomédica en Red| Tilburg University| Oregon State University| August Pi i Sunyer Biomedical Research Institute| University of Barcelona | O6: 79 | P6: 130829255| 127692143| 125649015| 60010887| 60015543| 60002746| 100465705| 60108590| 60103947| 60025111| 60136288| 60018805| 60021050| 60025778| 60007200| 60033182| 60023691| 60016849| 129882057| 60022036| 116759577| 60027565| 60018491| 60007174| 60013402| 60006183| 60001117| 60005248| 60004024| 60013384| 60021567| 60026124| 60002573| 60102054| 60002289| 60017145| 60023750| 60015913| 60013700| 60001422| 60000905| 60158017| 60009907| 60029929| 60022148| 60028392| 60028421| 60104561| 60001576| 60030315| 60010814| 60017488| 60016390| 60270066| 60022773| 60018207| 60006577| 60017336| 125622602| 60028717| 60000291| 130679822| 60018597| 60025988| 60028628| 60141178| 60030118| 60022109| 60021435| 60003158| 60010365| 60023077| 60002681| 60015765| 60028162| 60006222| 60016782| 112688391| 60016605| 60023469| 60028333| 128317671| 60029502| 60002494| 60021947| 60008435| 124821061| 60104957| 60259858| 60109349| 60015150| 60015879| 60010719| 60002634| 60026851| 60204338| 60025676| 60018353| 60018741| 60028589| 60026245| 130829582| 60005558| 60120069| 60119141| 107343748| 60011520| 100463463| 60006027| 101732084| 60021658| 60027272| 60014873| 60029582| 60212297| 60028884| 60006579| 60088543| 60025709| 60010710| 60033545| 121046122 | Q6: The Jackson Institute for Genomic Medicine| Semanticly| Rare Disease Ghana Initiative| The Jackson Laboratory| University of Pittsburgh| Harvard Medical School| Shriners Children's Northern California| Národní Ústav Duševního Zdraví, Klecany| Renaissance Computing Institute| The University of North Carolina at Chapel Hill| Perth Children's Hospital| Deakin University| Barwon Health| University of Michigan, Ann Arbor| Michigan Medicine| University of Michigan Medical School| University of California, San Francisco| University of Toronto| Nostos Genomics GmbH| Children's Cancer Research Institute, Vienna| Institute for Health Information and Statistics of the Czech Republic| Columbia University Irving Medical Center| Simon Fraser University| Lawrence Berkeley National Laboratory| Oregon State University| Johns Hopkins Bloomberg School of Public Health| Johns Hopkins University School of Medicine| Johns Hopkins University| Hospital Universitario 12 de Octubre| Shriners Hospitals for Children Montreal| AP-HP Assistance Publique - Hopitaux de Paris| EMBL’s European Bioinformatics Institute| Radboud University Medical Center| Donders Institute for Brain, Cognition and Behaviour| TRANZO Scientific Center for Care and Wellbeing| Tilburg University| Dalhousie University, Faculty of Medicine| Dalhousie University| Hôpital Armand-Trousseau| Sorbonne Université| Inserm| Laboratoire d'Informatique Médicale et d'Ingénieurie des Connaissances en e-Santé| Hôpital Saint-Antoine| Massachusetts General Hospital| University College London| University of Colorado Anschutz Medical Campus| University of Colorado School of Medicine| Centro de Investigación Biomédica En Red de Salud Mental| Universitat de Barcelona| Hospital Clínic de Barcelona| Institut d'Investigacions Biomèdiques August Pi i Sunyer - IDIBAPS| Addenbrooke's Hospital| Cambridge University Hospitals NHS Foundation Trust| Northwell Health System| Neuroscience Research Australia| Great Ormond Street Hospital for Children NHS Foundation Trust| National Institutes of Health (NIH)| National Institute of Allergy and Infectious Diseases (NIAID)| SNOMED International| Ludwig-Maximilians-Universität München| Klinikum der Universität München| Chinese HPO Consortium| Max Perutz Labs| Universität Wien| Northeastern University| Khoury College of Computer Sciences| The Children's Hospital of Philadelphia| Queen Mary University of London| Barts and The London School of Medicine and Dentistry| National Institute of Mental Health| The University of British Columbia| University of British Columbia, Faculty of Medicine| Universitätsklinikum Gießen und Marburg, Standort Marburg| Centre for Addiction and Mental Health| Hospital Universitario La Paz| Newcastle University| Brigham and Women's Hospital| Hospital Universitari Parc Taulí| Charles University| Fakultní Nemocnice v Motole| UNSW Sydney| Children's Medical Center| McGill Faculty of Medicine and Health Sciences| Université McGill| Indiana University School of Medicine| Tohoku University| Data Science| Universidad Icesi| Instituto de Investigación Sanitaria Bioaraba| Hospital Universitario Araba| Imperial College London| Medical Research Council| National Heart and Lung Institute| University of Oxford Medical Sciences Division| University of Oxford| Universitätsklinikum Carl Gustav Carus Dresden| Medizinische Fakultät Carl Gustav Carus| Technische Universität Dresden| SUNY Upstate Medical University| Norton College of Medicine | R6: 57205369227 | S6: 7403719646 | T6: 7403719646 | U6: - | V6: Austria| United Kingdom| Spain| Japan| France| Czech Republic| Ghana| China| United States| Germany| Colombia| Australia| Greece| Netherlands| Canada | W6: Genetic Insights and Treatment Strategies in Leukemia | X6: Genetic Screening and Exome Insights in Rare Diseases
A7: Indicators of Global Climate Change 2023: annual update of key indicators of the state of the climate system and human influence | B7: Forster, P.M.| Smith, C.| Walsh, T.| Lamb, W.F.| Lamboll, R.| Hall, B.| Hauser, M.| Ribes, A.| Rosen, D.| Gillett, N.P.| Palmer, M.D.| Rogelj, J.| Von Schuckmann, K.| Trewin, B.| Allen, M.| Andrew, R.| Betts, R.A.| Borger, A.| Boyer, T.| Broersma, J.A.| Buontempo, C.| Burgess, S.| Cagnazzo, C.| Cheng, L.| Friedlingstein, P.| Gettelman, A.| Gütschow, J.| Ishii, M.| Jenkins, S.| Lan, X.| Morice, C.| Mühle, J.| Kadow, C.| Kennedy, J.| Killick, R.E.| Krummel, P.B.| Minx, J.C.| Myhre, G.| Naik, V.| Peters, G.P.| Pirani, A.| Pongratz, J.| Schleussner, C.-F.| Seneviratne, S.I.| Szopa, S.| Thorne, P.| Kovilakam, M.V.M.| Majamäki, E.| Jalkanen, J.-P.| Van Marle, M.| Hoesly, R.M.| Rohde, R.| Schumacher, D.| Van Der Werf, G.| Vose, R.| Zickfeld, K.| Zhang, X.| Masson-Delmotte, V.| Zhai, P. | C7: 59 | D7: 35547807400| 57191980050| 57224086983| 56599171800| 56705370600| 7401720543| 56684259500| 26635870100| 57218420069| 7006130951| 7401916795| 36151443700| 25822837600| 6602484429| 7404105326| 23993876900| 55206018900| 58476226100| 7006188068| 55051868600| 6506634320| 57221765266| 13607567200| 57192370335| 6602135031| 25031430500| 35203289700| 8507223000| 57201352727| 55801282300| 43261917100| 55917306500| 54894523000| 57223813189| 57191592471| 6602579613| 8513127600| 7003777747| 56244473600| 10639594300| 25321144500| 26421368700| 19337864100| 7003499456| 15726660300| 9272538400| 55832509400| 57348373000| 8359737300| 56957126200| 55189762400| 8314032200| 57210598663| 9045036800| 6603344816| 23010937900| 56005684100| 57202733911| 55543826100 | E7: 2024 | F7: 45448 | G7: Earth System Science Data | H7: English | I7: 154 | J7: 33.56 | K7: 10.5194/essd-16-2625-2024 | L7: Article | M7: Gold|Green | N7: Chinese Academy of Meteorological Sciences| University of Bristol| Ludwig Maximilian University of Munich| Bureau of Meteorology Australia| Imperial College London| International Institute for Applied Systems Analysis, Laxenburg| University of Oxford| Centre national d'études spatiales| University of Leeds| Ca' Foscari University of Venice| École polytechnique| Université PSL| Centre for International Climate and Environmental Research| Mercator Research Institute on Global Commons and Climate Change| Simon Fraser University| Institut de recherche pour le développement| CAS - Institute of Atmospheric Physics| Wageningen University & Research| Université Paris Cité| Université Fédérale Toulouse Midi-Pyrénées| Université Paris-Est Créteil| Met Office| Mercator Océan| Japan Meteorological Agency| University of Colorado Boulder| École normale supérieure| University of Oslo| Euro-Mediterranean Center on Climate Change| Institut Polytechnique de Paris| Humboldt University of Berlin| United States Department of Energy| Service hydrographique et océanographique de la marine| École des Ponts ParisTech| Sorbonne Université| University of Exeter| Paris-Est Sup| Potsdam Institute for Climate Impact Research| Helmholtz-Zentrum Hereon| Max Planck Institute for Meteorology| Swiss Federal Institute of Technology Zurich| Maynooth University| Université Paris-Saclay| National Oceanic and Atmospheric Administration| Commissariat à l’énergie atomique et aux énergies alternatives| CNRS| Météo France| Environment and Climate Change Canada| Finnish Meteorological Institute| University of California at San Diego| Chinese Academy of Sciences| NASA Langley Research Center| Université Paul Sabatier Toulouse III| Pacific Northwest National Laboratory | O7: 53 | P7: 60012070| 60019497| 60018258| 60026851| 60159447| 60015150| 60099375| 60025858| 60028770| 60027245| 60008134| 60000673| 60020650| 60116794| 60008506| 60024826| 130831207| 119771982| 60019499| 60016211| 60027716| 60026479| 60000179| 60019908| 60108665| 60105757| 127190910| 60024168| 60025288| 113958672| 60082966| 60013494| 60028717| 60255200| 60000762| 60045588| 60029937| 60106017| 60007816| 60026281| 113737465| 117553207| 60018491| 60027451| 60028564| 60000221| 60008778| 60004156| 60023471| 60000854| 60033178| 131347367| 60023018| 60030612| 129932660 | Q7: University of Leeds| International Institute for Applied Systems Analysis, Laxenburg| Met Office| University of Oxford| Mercator Research Institute on Global Commons and Climate Change| Imperial College London| Institut für Atmosphäre und Klima| ETH Zürich| Météo France| Université de Toulouse| CNRS Centre National de la Recherche Scientifique| Environment and Climate Change Canada| University of Bristol| Mercator Océan| Bureau of Meteorology Australia| CICERO Senter for Klimaforskning| Ecwmf| NOAA's National Centers for Environmental Information (NCEI)| Chinese Academy of Sciences| Institute of Atmospheric Physics Chinese Academy of Sciences| National Oceanic and Atmospheric Administration| University of Exeter| École Normale Supérieure| Institut Pierre-Simon Laplace| Université PSL| Laboratoire de Météorologie Dynamique| Climate Resource| Meteorological Research Institute| Helmholtz-Zentrum Hereon GmbH| Verdun Hospital| Fondazione Centro Euro-Mediterraneo sui Cambiamenti Climatici| Università Ca' Foscari Venezia| Ludwig-Maximilians-Universität München| Climate Analytics| Humboldt-Universität zu Berlin| Laboratoire des Sciences du Climat et de l'Environnement| Université de Versailles Saint-Quentin-en-Yvelines| Université Paris-Saclay| Commissariat a l'Energie Atomique et aux Energies Alternatives| Maynooth University| Berkeley Earth| NOAA/National Centers for Environmental Information| Simon Fraser University| Chinese Academy of Meteorological Sciences| Max Planck Institute for Meteorology| University of Colorado Boulder| Cooperative Institute for Research in Environmental Sciences| Wageningen University & Research| Pacific Northwest National Laboratory| NASA Langley Research Center| Finnish Meteorological Institute| Delteras| Scripps Institution of Oceanography| University of California, San Diego| Data for Action Foundation | R7: 35547807400 | S7: 55543826100 | T7: 35547807400 | U7: - | V7: Austria| United Kingdom| Japan| Finland| Italy| France| Norway| China| Ireland| United States| Germany| Australia| Switzerland| Netherlands| Canada | W7: Climate Variability and Tropical Cyclone Dynamics | X7: Global Ocean Heat and Salinity Dynamics
A8: Unearthing grounded normative theory: practices and commitments of empirical research in political theory | B8: Ackerly, B.| Cabrera, L.| Forman, F.| Johnson, G.F.| Tenove, C.| Wiener, A. | C8: 6 | D8: 8537848200| 59863939300| 55652948500| 55456265300| 57205450261| 7006864011 | E8: 2024 | F8: 45292 | G8: Critical Review of International Social and Political Philosophy | H8: English | I8: 63 | J8: 30.99 | K8: 10.1080/13698230.2021.1894020 | L8: Article | N8: Vanderbilt University| University of Hamburg| Simon Fraser University| Griffith University Queensland| University of British Columbia| University of California at San Diego | O8: 6 | P8: 60003915| 60032987| 60030612| 60018491| 60010365| 60028229 | Q8: Vanderbilt University| Griffith University| University of California, San Diego| Simon Fraser University| The University of British Columbia| Universität Hamburg | R8: 8537848200 | S8: 7006864011 | T8: 8537848200 | U8: - | V8: United States| Germany| Australia| Canada | W8: Justice, Autonomy, and Democracy in Global Contexts | X8: Global Justice and Human Rights Responsibilities
A9: Effect of Risk Mitigation Guidance opioid and stimulant dispensations on mortality and acute care visits during dual public health emergencies: retrospective cohort study | B9: Slaunwhite, A.| Min, J.E.| Palis, H.| Urbanoski, K.| Pauly, B.| Barker, B.| Crabtree, A.| Bach, P.| Krebs, E.| Dale, L.| Meilleur, L.| Nosyk, B. | C9: 12 | D9: 56479230500| 58856686100| 56397157400| 6506201836| 6603498334| 56100493400| 37048663600| 15759134700| 56338995600| 57216415837| 57220055812| 12809172100 | E9: 2024 | F9: 45292 | G9: BMJ | H9: English | I9: 76 | J9: 30.13 | K9: 10.1136/bmj-2023-076336 | L9: Article | M9: Hybrid gold|Green | N9: British Columbia Centre on Substance Use| Simon Fraser University| University of Victoria BC| University of British Columbia| BC Centre for Disease Control| Provincial Health Services Authority | O9: 6 | P9: 60010365| 60012171| 130408287| 60023077| 60003122| 60082761| 114434791| 60018491| 60138516| 60028379 | Q9: The University of British Columbia| BC Centre for Disease Control| Centre for Advancing Health Outcomes| University of British Columbia, Faculty of Medicine| University of Victoria| Canadian Institute for Substance Use Research| First Nations Health Authority (West Vancouver, BC)| Simon Fraser University| British Columbia Centre on Substance Use| British Columbia Cancer Agency | R9: 56479230500 | S9: 12809172100 | T9: 12809172100 | U9: - | V9: Canada | W9: Opioid Use and Management in Healthcare | X9: Heroin Treatment and Safe Supply Strategies
